Workbook

Sheet Config
A1: AE_PE | B1: <-- Select Vehicle Code

Sheet Reference Data 기준데이터
A1: TBL_Vehicle (차종 + 일정 + LeadTime)
A2: VehicleCode | B2: VehicleName | C2: T0_DrawingRelease | D2: ProtoBuild | E2: MasterCar | F2: TestDeadline | G2: LT_PlanDue | H2: LT_PartsReady | I2: LT_TestStart | J2: LT_ReportDue
A3: AE_PE | B3: AE PE (Creta EV) | C3: 46037 | D3: 46127 | E3: 46188 | F3: =E3-30 | G3: 14 | H3: 49 | I3: 63 | J3: 98
A4: SU2i | B4: SU2i (Venue Next) | C4: 46082 | D4: 46174 | E4: 46249 | F4: =E4-30 | G4: 14 | H4: 49 | I4: 63 | J4: 98
A5: EN_SUV | B5: EN SUV | C5: 46054 | D5: 46143 | E5: 46218 | F5: =E5-30 | G5: 14 | H5: 49 | I5: 63 | J5: 98
A7: TBL_TestMaster (시험 마스터)
A8: TestNameKR | B8: TestType | C8: Spec | D8: DurationDays | E8: PartName | F8: PartCategory
A9: VOC 방출 시험 | B9: 단품 Component | C9: MS-300-57 | D9: 14 | E9: Center Console Assy | F9: Console
A10: 내열 시험 | B10: 단품 Component | C10: MS-300-31 | D10: 14 | E10: Center Console Assy | F10: Console
A11: 마모 시험 | B11: 단품 Component | C11: MS-300-35 | D11: 7 | E11: Center Console Assy | F11: Console
A12: 치수 검사 | B12: 단품 Component | C12: ES-90101 | D12: 3 | E12: Center Console Assy | F12: Console
A13: VOC 방출 시험 | B13: 단품 Component | C13: MS-300-57 | D13: 14 | E13: Console Lid Assy | F13: Console
A14: 힌지 내구 시험 | B14: 단품 Component | C14: ES-92030 | D14: 10 | E14: Console Lid Assy | F14: Console
A15: 외관 검사 | B15: 단품 Component | C15: ES-90100 | D15: 3 | E15: Console Lid Assy | F15: Console
A16: VOC 방출 시험 | B16: 단품 Component | C16: MS-300-57 | D16: 14 | E16: Door Trim LH | F16: Trim
A17: 내후성 시험 | B17: 단품 Component | C17: MS-300-34 | D17: 21 | E17: Door Trim LH | F17: Trim
A18: 연소성 시험 | B18: 단품 Component | C18: FMVSS 302 | D18: 3 | E18: Door Trim LH | F18: Trim
A19: 외관 검사 | B19: 단품 Component | C19: ES-90100 | D19: 3 | E19: Door Trim LH | F19: Trim
A20: 내후성 시험 | B20: 단품 Component | C20: MS-300-34 | D20: 21 | E20: Pillar Trim C | F20: Trim
... A30: 외관 검사 | B30: 단품 Component | C30: ES-90100 | D30: 3 | E30: Rear Seat Assy | F30: Seat
A32: TBL_VehicleParts (차종×부품→협력사)
A33: VPKey | B33: SupplierCode
A34: AE_PE_Center Console Assy | B34: SUP_A
A35: AE_PE_Console Lid Assy | B35: SUP_A
A36: AE_PE_Door Trim LH | B36: SUP_B
A37: AE_PE_Pillar Trim C | B37: SUP_C
A38: AE_PE_Front Seat Assy LH | B38: SUP_D
A39: AE_PE_Rear Seat Assy | B39: SUP_D
A40: SU2i_Center Console Assy | B40: SUP_B
A41: SU2i_Console Lid Assy | B41: SUP_B
A42: SU2i_Door Trim LH | B42: SUP_C
A43: SU2i_Pillar Trim C | B43: SUP_A
A44: SU2i_Front Seat Assy LH | B44: SUP_D
... A51: EN_SUV_Rear Seat Assy | B51: SUP_D
A53: Dropdown: PartNames
A54: Center Console Assy
A55: Console Lid Assy
A56: Door Trim LH
A57: Pillar Trim C
A58: Front Seat Assy LH
...

Sheet Master Tracker 마스터추적표
A1: ESIR Master Tracker V3 — Engineering Sample / Initial Run Test
A3: No. | B3: Vehicle Code | C3: Part Name | D3: Part Category | E3: Test Name KR | F3: Test Type | G3: Supplier | H3: T₀ Drawing Release | I3: Plan Due Date | J3: Plan Submitted Date | K3: Review Result | L3: Parts Ready (Plan) | M3: Parts Ready (Actual) | N3: Test Start (Plan) | O3: Test Start (Actual) | P3: Test Complete (Plan) | Q3: Test Complete (Actual) | R3: Report Due Date | S3: Report Submitted Date | T3: Override | U3: Status | V3: Progress % | W3: Days to Deadline | X3: Risk Flag | Y3: Next Action
A4: 번호 | B4: 차종 | C4: 부품명 | D4: 파트구분 | E4: 스펙명 | F4: 시험유형 | G4: 협력사 | H4: T₀ 도면배포 | I4: 계획서기한 | J4: 계획서제출 | K4: 검토결과 | L4: 부품준비(계획) | M4: 부품준비(실적) | N4: 시험시작(계획) | O4: 시험시작(실적) | P4: 시험완료(계획) | Q4: 시험완료(실적) | R4: 성적서기한 | S4: 성적서제출 | T4: 오버라이드 | U4: 상태 | V4: 진행률% | W4: 잔여일 | X4: 리스크 | Y4: 다음조치
A5: 1 | B5: AE_PE | C5: Center Console Assy | D5: =IFERROR(VLOOKUP(C5,'Reference Data 기준데이터'!$E$8:$F$30,2,FALSE),"") | E5: VOC 방출 시험 | F5: =IFERROR(VLOOKUP(E5,'Reference Data 기준데이터'!$A$8:$F$30,2,FALSE),"") | G5: =IFERROR(VLOOKUP(B5&"_"&C5,'Reference Data 기준데이터'!$A$33:$B$51,2,FALSE),"") | H5: =IFERROR(VLOOKUP(B5,'Reference Data 기준데이터'!$A$2:$J$5,3,FALSE),"") | I5: =IFERROR(H5+VLOOKUP(B5,'Reference Data 기준데이터'!$A$2:$J$5,7,FALSE),"") | L5: =IFERROR(H5+VLOOKUP(B5,'Reference Data 기준데이터'!$A$2:$J$5,8,FALSE),"") | N5: =IFERROR(IF(ISNUMBER(SEARCH("Vehicle",F5)),MAX(H5+VLOOKUP(B5,'Reference Data 기준데이터'!$A$2:$J$5,9,FALSE),VLOOKUP(B5,'Reference Data 기준데이터'!$A$2:$J$5,4,FALSE)),H5+VLOOKUP(B5,'Reference Data 기준데이터'!$A$2:$J$5,9,FALSE)),"") | P5: =IFERROR(N5+VLOOKUP(E5,'Reference Data 기준데이터'!$A$8:$F$30,4,FALSE),"") | R5: =IFERROR(MIN(H5+VLOOKUP(B5,'Reference Data 기준데이터'!$A$2:$J$5,10,FALSE),VLOOKUP(B5,'Reference Data 기준데이터'!$A$2:$J$5,6,FALSE)),"") | U5: =IF(T5<>"",T5,IF(AND(S5<>"",Q5<>""),"11-결과등록완료",IF(AND(Q5<>"",S5=""),"10-시험완료",IF(AND(O5<>"",Q5=""),"09-시험준비중",IF(AND(M5<>"",O5=""),"08-단품준비완료",IF(K5="Approved","05-계획서승인",IF(K5="Revision Needed","04-검토중_조건불만족",IF(K5="Under Review","03-검토중_조건충족",IF(AND(J5<>"",K5=""),"02-계획서제출_미검토","01-계획서미제출"))))))))) | V5: =IFS(U5="01-계획서미제출",0,U5="02-계획서제출_미검토",0.05,U5="03-검토중_조건충족",0.1,U5="04-검토중_조건불만족",0.05,U5="05-계획서승인",0.2,U5="06-BIW생산중단",0.15,U5="07-생산완료_미인수",0.3,U5="08-단품준비완료",0.4,U5="09-시험준비중",0.55,U5="10-시험완료",0.85,U5="11-결과등록완료",1,U5="12-조건부승인검토",0.9,TRUE,0) | W5: =IF(S5<>"","-",IF(R5="","N/A",R5-TODAY())) | X5: =IF(U5="11-결과등록완료","DONE",IF(OR(U5="06-BIW생산중단",AND(U5="01-계획서미제출",I5<TODAY())),"CRITICAL",IF(OR(U5="04-검토중_조건불만족",U5="07-생산완료_미인수",U5="12-조건부승인검토"),"ACTION",IF(AND(ISNUMBER(W5),W5<=0),"OVERDUE",IF(AND(ISNUMBER(W5),W5<=14),"WARNING","ON TRACK"))))) | Y5: =IF(U5="11-결과등록완료","— 완료",IF(U5="01-계획서미제출",IF(I5<TODAY(),"계획서 제출 독촉 (OVERDUE)","계획서 제출 대기"),IF(U5="02-계획서제출_미검토","설계자: 계획서 검토 착수",IF(U5="03-검토중_조건충족","설계자: 승인 처리",IF(U5="04-검토중_조건불만족","보완 요청 → 협력사 재제출 독촉",IF(U5="05-계획서승인","시험편 준비 현황 확인",IF(U5="06-BIW생산중단","BIW 생산팀 확인 → 일정 재수립",IF(U5="07-생산완료_미인수","협력사 인수 독촉",IF(U5="08-단품준비완료","시험 일정 확인",IF(U5="09-시험준비중","시험 진행 모니터링",IF(U5="10-시험완료","결과 보고서 전산 등록 독촉",IF(U5="12-조건부승인검토","조건부 승인 여부 판단 → 관련부서 협의","—"))))))))))))
A6: 2 | B6: AE_PE | C6: Center Console Assy | D6: =IFERROR(VLOOKUP(C6,'Reference Data 기준데이터'!$E$8:$F$30,2,FALSE),"") | E6: 내열 시험 | F6: =IFERROR(VLOOKUP(E6,'Reference Data 기준데이터'!$A$8:$F$30,2,FALSE),"") | G6: =IFERROR(VLOOKUP(B6&"_"&C6,'Reference Data 기준데이터'!$A$33:$B$51,2,FALSE),"") | H6: =IFERROR(VLOOKUP(B6,'Reference Data 기준데이터'!$A$2:$J$5,3,FALSE),"") | I6: =IFERROR(H6+VLOOKUP(B6,'Reference Data 기준데이터'!$A$2:$J$5,7,FALSE),"") | J6: 46049 | K6: Approved | L6: =IFERROR(H6+VLOOKUP(B6,'Reference Data 기준데이터'!$A$2:$J$5,8,FALSE),"") | N6: =IFERROR(IF(ISNUMBER(SEARCH("Vehicle",F6)),MAX(H6+VLOOKUP(B6,'Reference Data 기준데이터'!$A$2:$J$5,9,FALSE),VLOOKUP(B6,'Reference Data 기준데이터'!$A$2:$J$5,4,FALSE)),H6+VLOOKUP(B6,'Reference Data 기준데이터'!$A$2:$J$5,9,FALSE)),"") | P6: =IFERROR(N6+VLOOKUP(E6,'Reference Data 기준데이터'!$A$8:$F$30,4,FALSE),"") | R6: =IFERROR(MIN(H6+VLOOKUP(B6,'Reference Data 기준데이터'!$A$2:$J$5,10,FALSE),VLOOKUP(B6,'Reference Data 기준데이터'!$A$2:$J$5,6,FALSE)),"") | U6: =IF(T6<>"",T6,IF(AND(S6<>"",Q6<>""),"11-결과등록완료",IF(AND(Q6<>"",S6=""),"10-시험완료",IF(AND(O6<>"",Q6=""),"09-시험준비중",IF(AND(M6<>"",O6=""),"08-단품준비완료",IF(K6="Approved","05-계획서승인",IF(K6="Revision Needed","04-검토중_조건불만족",IF(K6="Under Review","03-검토중_조건충족",IF(AND(J6<>"",K6=""),"02-계획서제출_미검토","01-계획서미제출"))))))))) | V6: =IFS(U6="01-계획서미제출",0,U6="02-계획서제출_미검토",0.05,U6="03-검토중_조건충족",0.1,U6="04-검토중_조건불만족",0.05,U6="05-계획서승인",0.2,U6="06-BIW생산중단",0.15,U6="07-생산완료_미인수",0.3,U6="08-단품준비완료",0.4,U6="09-시험준비중",0.55,U6="10-시험완료",0.85,U6="11-결과등록완료",1,U6="12-조건부승인검토",0.9,TRUE,0) | W6: =IF(S6<>"","-",IF(R6="","N/A",R6-TODAY())) | X6: =IF(U6="11-결과등록완료","DONE",IF(OR(U6="06-BIW생산중단",AND(U6="01-계획서미제출",I6<TODAY())),"CRITICAL",IF(OR(U6="04-검토중_조건불만족",U6="07-생산완료_미인수",U6="12-조건부승인검토"),"ACTION",IF(AND(ISNUMBER(W6),W6<=0),"OVERDUE",IF(AND(ISNUMBER(W6),W6<=14),"WARNING","ON TRACK"))))) | Y6: =IF(U6="11-결과등록완료","— 완료",IF(U6="01-계획서미제출",IF(I6<TODAY(),"계획서 제출 독촉 (OVERDUE)","계획서 제출 대기"),IF(U6="02-계획서제출_미검토","설계자: 계획서 검토 착수",IF(U6="03-검토중_조건충족","설계자: 승인 처리",IF(U6="04-검토중_조건불만족","보완 요청 → 협력사 재제출 독촉",IF(U6="05-계획서승인","시험편 준비 현황 확인",IF(U6="06-BIW생산중단","BIW 생산팀 확인 → 일정 재수립",IF(U6="07-생산완료_미인수","협력사 인수 독촉",IF(U6="08-단품준비완료","시험 일정 확인",IF(U6="09-시험준비중","시험 진행 모니터링",IF(U6="10-시험완료","결과 보고서 전산 등록 독촉",IF(U6="12-조건부승인검토","조건부 승인 여부 판단 → 관련부서 협의","—"))))))))))))
A7: 3 | B7: AE_PE | C7: Center Console Assy | D7: =IFERROR(VLOOKUP(C7,'Reference Data 기준데이터'!$E$8:$F$30,2,FALSE),"") | E7: 마모 시험 | F7: =IFERROR(VLOOKUP(E7,'Reference Data 기준데이터'!$A$8:$F$30,2,FALSE),"") | G7: =IFERROR(VLOOKUP(B7&"_"&C7,'Reference Data 기준데이터'!$A$33:$B$51,2,FALSE),"") | H7: =IFERROR(VLOOKUP(B7,'Reference Data 기준데이터'!$A$2:$J$5,3,FALSE),"") | I7: =IFERROR(H7+VLOOKUP(B7,'Reference Data 기준데이터'!$A$2:$J$5,7,FALSE),"") | J7: 46050 | K7: Approved | L7: =IFERROR(H7+VLOOKUP(B7,'Reference Data 기준데이터'!$A$2:$J$5,8,FALSE),"") | M7: 46085 | N7: =IFERROR(IF(ISNUMBER(SEARCH("Vehicle",F7)),MAX(H7+VLOOKUP(B7,'Reference Data 기준데이터'!$A$2:$J$5,9,FALSE),VLOOKUP(B7,'Reference Data 기준데이터'!$A$2:$J$5,4,FALSE)),H7+VLOOKUP(B7,'Reference Data 기준데이터'!$A$2:$J$5,9,FALSE)),"") | O7: 46102 | P7: =IFERROR(N7+VLOOKUP(E7,'Reference Data 기준데이터'!$A$8:$F$30,4,FALSE),"") | R7: =IFERROR(MIN(H7+VLOOKUP(B7,'Reference Data 기준데이터'!$A$2:$J$5,10,FALSE),VLOOKUP(B7,'Reference Data 기준데이터'!$A$2:$J$5,6,FALSE)),"") | U7: =IF(T7<>"",T7,IF(AND(S7<>"",Q7<>""),"11-결과등록완료",IF(AND(Q7<>"",S7=""),"10-시험완료",IF(AND(O7<>"",Q7=""),"09-시험준비중",IF(AND(M7<>"",O7=""),"08-단품준비완료",IF(K7="Approved","05-계획서승인",IF(K7="Revision Needed","04-검토중_조건불만족",IF(K7="Under Review","03-검토중_조건충족",IF(AND(J7<>"",K7=""),"02-계획서제출_미검토","01-계획서미제출"))))))))) | V7: =IFS(U7="01-계획서미제출",0,U7="02-계획서제출_미검토",0.05,U7="03-검토중_조건충족",0.1,U7="04-검토중_조건불만족",0.05,U7="05-계획서승인",0.2,U7="06-BIW생산중단",0.15,U7="07-생산완료_미인수",0.3,U7="08-단품준비완료",0.4,U7="09-시험준비중",0.55,U7="10-시험완료",0.85,U7="11-결과등록완료",1,U7="12-조건부승인검토",0.9,TRUE,0) | W7: =IF(S7<>"","-",IF(R7="","N/A",R7-TODAY())) | X7: =IF(U7="11-결과등록완료","DONE",IF(OR(U7="06-BIW생산중단",AND(U7="01-계획서미제출",I7<TODAY())),"CRITICAL",IF(OR(U7="04-검토중_조건불만족",U7="07-생산완료_미인수",U7="12-조건부승인검토"),"ACTION",IF(AND(ISNUMBER(W7),W7<=0),"OVERDUE",IF(AND(ISNUMBER(W7),W7<=14),"WARNING","ON TRACK"))))) | Y7: =IF(U7="11-결과등록완료","— 완료",IF(U7="01-계획서미제출",IF(I7<TODAY(),"계획서 제출 독촉 (OVERDUE)","계획서 제출 대기"),IF(U7="02-계획서제출_미검토","설계자: 계획서 검토 착수",IF(U7="03-검토중_조건충족","설계자: 승인 처리",IF(U7="04-검토중_조건불만족","보완 요청 → 협력사 재제출 독촉",IF(U7="05-계획서승인","시험편 준비 현황 확인",IF(U7="06-BIW생산중단","BIW 생산팀 확인 → 일정 재수립",IF(U7="07-생산완료_미인수","협력사 인수 독촉",IF(U7="08-단품준비완료","시험 일정 확인",IF(U7="09-시험준비중","시험 진행 모니터링",IF(U7="10-시험완료","결과 보고서 전산 등록 독촉",IF(U7="12-조건부승인검토","조건부 승인 여부 판단 → 관련부서 협의","—"))))))))))))
A8: 4 | B8: AE_PE | C8: Center Console Assy | D8: =IFERROR(VLOOKUP(C8,'Reference Data 기준데이터'!$E$8:$F$30,2,FALSE),"") | E8: 치수 검사 | F8: =IFERROR(VLOOKUP(E8,'Reference Data 기준데이터'!$A$8:$F$30,2,FALSE),"") | G8: =IFERROR(VLOOKUP(B8&"_"&C8,'Reference Data 기준데이터'!$A$33:$B$51,2,FALSE),"") | H8: =IFERROR(VLOOKUP(B8,'Reference Data 기준데이터'!$A$2:$J$5,3,FALSE),"") | I8: =IFERROR(H8+VLOOKUP(B8,'Reference Data 기준데이터'!$A$2:$J$5,7,FALSE),"") | J8: 46051 | K8: Approved | L8: =IFERROR(H8+VLOOKUP(B8,'Reference Data 기준데이터'!$A$2:$J$5,8,FALSE),"") | M8: 46086 | N8: =IFERROR(IF(ISNUMBER(SEARCH("Vehicle",F8)),MAX(H8+VLOOKUP(B8,'Reference Data 기준데이터'!$A$2:$J$5,9,FALSE),VLOOKUP(B8,'Reference Data 기준데이터'!$A$2:$J$5,4,FALSE)),H8+VLOOKUP(B8,'Reference Data 기준데이터'!$A$2:$J$5,9,FALSE)),"") | O8: 46103 | P8: =IFERROR(N8+VLOOKUP(E8,'Reference Data 기준데이터'!$A$8:$F$30,4,FALSE),"") | Q8: 46126 | R8: =IFERROR(MIN(H8+VLOOKUP(B8,'Reference Data 기준데이터'!$A$2:$J$5,10,FALSE),VLOOKUP(B8,'Reference Data 기준데이터'!$A$2:$J$5,6,FALSE)),"") | S8: 46130 | U8: =IF(T8<>"",T8,IF(AND(S8<>"",Q8<>""),"11-결과등록완료",IF(AND(Q8<>"",S8=""),"10-시험완료",IF(AND(O8<>"",Q8=""),"09-시험준비중",IF(AND(M8<>"",O8=""),"08-단품준비완료",IF(K8="Approved","05-계획서승인",IF(K8="Revision Needed","04-검토중_조건불만족",IF(K8="Under Review","03-검토중_조건충족",IF(AND(J8<>"",K8=""),"02-계획서제출_미검토","01-계획서미제출"))))))))) | V8: =IFS(U8="01-계획서미제출",0,U8="02-계획서제출_미검토",0.05,U8="03-검토중_조건충족",0.1,U8="04-검토중_조건불만족",0.05,U8="05-계획서승인",0.2,U8="06-BIW생산중단",0.15,U8="07-생산완료_미인수",0.3,U8="08-단품준비완료",0.4,U8="09-시험준비중",0.55,U8="10-시험완료",0.85,U8="11-결과등록완료",1,U8="12-조건부승인검토",0.9,TRUE,0) | W8: =IF(S8<>"","-",IF(R8="","N/A",R8-TODAY())) | X8: =IF(U8="11-결과등록완료","DONE",IF(OR(U8="06-BIW생산중단",AND(U8="01-계획서미제출",I8<TODAY())),"CRITICAL",IF(OR(U8="04-검토중_조건불만족",U8="07-생산완료_미인수",U8="12-조건부승인검토"),"ACTION",IF(AND(ISNUMBER(W8),W8<=0),"OVERDUE",IF(AND(ISNUMBER(W8),W8<=14),"WARNING","ON TRACK"))))) | Y8: =IF(U8="11-결과등록완료","— 완료",IF(U8="01-계획서미제출",IF(I8<TODAY(),"계획서 제출 독촉 (OVERDUE)","계획서 제출 대기"),IF(U8="02-계획서제출_미검토","설계자: 계획서 검토 착수",IF(U8="03-검토중_조건충족","설계자: 승인 처리",IF(U8="04-검토중_조건불만족","보완 요청 → 협력사 재제출 독촉",IF(U8="05-계획서승인","시험편 준비 현황 확인",IF(U8="06-BIW생산중단","BIW 생산팀 확인 → 일정 재수립",IF(U8="07-생산완료_미인수","협력사 인수 독촉",IF(U8="08-단품준비완료","시험 일정 확인",IF(U8="09-시험준비중","시험 진행 모니터링",IF(U8="10-시험완료","결과 보고서 전산 등록 독촉",IF(U8="12-조건부승인검토","조건부 승인 여부 판단 → 관련부서 협의","—"))))))))))))
A9: 5 | B9: AE_PE | C9: Console Lid Assy | D9: =IFERROR(VLOOKUP(C9,'Reference Data 기준데이터'!$E$8:$F$30,2,FALSE),"") | E9: VOC 방출 시험 | F9: =IFERROR(VLOOKUP(E9,'Reference Data 기준데이터'!$A$8:$F$30,2,FALSE),"") | G9: =IFERROR(VLOOKUP(B9&"_"&C9,'Reference Data 기준데이터'!$A$33:$B$51,2,FALSE),"") | H9: =IFERROR(VLOOKUP(B9,'Reference Data 기준데이터'!$A$2:$J$5,3,FALSE),"") | I9: =IFERROR(H9+VLOOKUP(B9,'Reference Data 기준데이터'!$A$2:$J$5,7,FALSE),"") | J9: 46047 | L9: =IFERROR(H9+VLOOKUP(B9,'Reference Data 기준데이터'!$A$2:$J$5,8,FALSE),"") | N9: =IFERROR(IF(ISNUMBER(SEARCH("Vehicle",F9)),MAX(H9+VLOOKUP(B9,'Reference Data 기준데이터'!$A$2:$J$5,9,FALSE),VLOOKUP(B9,'Reference Data 기준데이터'!$A$2:$J$5,4,FALSE)),H9+VLOOKUP(B9,'Reference Data 기준데이터'!$A$2:$J$5,9,FALSE)),"") | P9: =IFERROR(N9+VLOOKUP(E9,'Reference Data 기준데이터'!$A$8:$F$30,4,FALSE),"") | R9: =IFERROR(MIN(H9+VLOOKUP(B9,'Reference Data 기준데이터'!$A$2:$J$5,10,FALSE),VLOOKUP(B9,'Reference Data 기준데이터'!$A$2:$J$5,6,FALSE)),"") | U9: =IF(T9<>"",T9,IF(AND(S9<>"",Q9<>""),"11-결과등록완료",IF(AND(Q9<>"",S9=""),"10-시험완료",IF(AND(O9<>"",Q9=""),"09-시험준비중",IF(AND(M9<>"",O9=""),"08-단품준비완료",IF(K9="Approved","05-계획서승인",IF(K9="Revision Needed","04-검토중_조건불만족",IF(K9="Under Review","03-검토중_조건충족",IF(AND(J9<>"",K9=""),"02-계획서제출_미검토","01-계획서미제출"))))))))) | V9: =IFS(U9="01-계획서미제출",0,U9="02-계획서제출_미검토",0.05,U9="03-검토중_조건충족",0.1,U9="04-검토중_조건불만족",0.05,U9="05-계획서승인",0.2,U9="06-BIW생산중단",0.15,U9="07-생산완료_미인수",0.3,U9="08-단품준비완료",0.4,U9="09-시험준비중",0.55,U9="10-시험완료",0.85,U9="11-결과등록완료",1,U9="12-조건부승인검토",0.9,TRUE,0) | W9: =IF(S9<>"","-",IF(R9="","N/A",R9-TODAY())) | X9: =IF(U9="11-결과등록완료","DONE",IF(OR(U9="06-BIW생산중단",AND(U9="01-계획서미제출",I9<TODAY())),"CRITICAL",IF(OR(U9="04-검토중_조건불만족",U9="07-생산완료_미인수",U9="12-조건부승인검토"),"ACTION",IF(AND(ISNUMBER(W9),W9<=0),"OVERDUE",IF(AND(ISNUMBER(W9),W9<=14),"WARNING","ON TRACK"))))) | Y9: =IF(U9="11-결과등록완료","— 완료",IF(U9="01-계획서미제출",IF(I9<TODAY(),"계획서 제출 독촉 (OVERDUE)","계획서 제출 대기"),IF(U9="02-계획서제출_미검토","설계자: 계획서 검토 착수",IF(U9="03-검토중_조건충족","설계자: 승인 처리",IF(U9="04-검토중_조건불만족","보완 요청 → 협력사 재제출 독촉",IF(U9="05-계획서승인","시험편 준비 현황 확인",IF(U9="06-BIW생산중단","BIW 생산팀 확인 → 일정 재수립",IF(U9="07-생산완료_미인수","협력사 인수 독촉",IF(U9="08-단품준비완료","시험 일정 확인",IF(U9="09-시험준비중","시험 진행 모니터링",IF(U9="10-시험완료","결과 보고서 전산 등록 독촉",IF(U9="12-조건부승인검토","조건부 승인 여부 판단 → 관련부서 협의","—"))))))))))))
A10: 6 | B10: AE_PE | C10: Console Lid Assy | D10: =IFERROR(VLOOKUP(C10,'Reference Data 기준데이터'!$E$8:$F$30,2,FALSE),"") | E10: 힌지 내구 시험 | F10: =IFERROR(VLOOKUP(E10,'Reference Data 기준데이터'!$A$8:$F$30,2,FALSE),"") | G10: =IFERROR(VLOOKUP(B10&"_"&C10,'Reference Data 기준데이터'!$A$33:$B$51,2,FALSE),"") | H10: =IFERROR(VLOOKUP(B10,'Reference Data 기준데이터'!$A$2:$J$5,3,FALSE),"") | I10: =IFERROR(H10+VLOOKUP(B10,'Reference Data 기준데이터'!$A$2:$J$5,7,FALSE),"") | J10: 46048 | K10: Approved | L10: =IFERROR(H10+VLOOKUP(B10,'Reference Data 기준데이터'!$A$2:$J$5,8,FALSE),"") | M10: 46088 | N10: =IFERROR(IF(ISNUMBER(SEARCH("Vehicle",F10)),MAX(H10+VLOOKUP(B10,'Reference Data 기준데이터'!$A$2:$J$5,9,FALSE),VLOOKUP(B10,'Reference Data 기준데이터'!$A$2:$J$5,4,FALSE)),H10+VLOOKUP(B10,'Reference Data 기준데이터'!$A$2:$J$5,9,FALSE)),"") | P10: =IFERROR(N10+VLOOKUP(E10,'Reference Data 기준데이터'!$A$8:$F$30,4,FALSE),"") | R10: =IFERROR(MIN(H10+VLOOKUP(B10,'Reference Data 기준데이터'!$A$2:$J$5,10,FALSE),VLOOKUP(B10,'Reference Data 기준데이터'!$A$2:$J$5,6,FALSE)),"") | U10: =IF(T10<>"",T10,IF(AND(S10<>"",Q10<>""),"11-결과등록완료",IF(AND(Q10<>"",S10=""),"10-시험완료",IF(AND(O10<>"",Q10=""),"09-시험준비중",IF(AND(M10<>"",O10=""),"08-단품준비완료",IF(K10="Approved","05-계획서승인",IF(K10="Revision Needed","04-검토중_조건불만족",IF(K10="Under Review","03-검토중_조건충족",IF(AND(J10<>"",K10=""),"02-계획서제출_미검토","01-계획서미제출"))))))))) | V10: =IFS(U10="01-계획서미제출",0,U10="02-계획서제출_미검토",0.05,U10="03-검토중_조건충족",0.1,U10="04-검토중_조건불만족",0.05,U10="05-계획서승인",0.2,U10="06-BIW생산중단",0.15,U10="07-생산완료_미인수",0.3,U10="08-단품준비완료",0.4,U10="09-시험준비중",0.55,U10="10-시험완료",0.85,U10="11-결과등록완료",1,U10="12-조건부승인검토",0.9,TRUE,0) | W10: =IF(S10<>"","-",IF(R10="","N/A",R10-TODAY())) | X10: =IF(U10="11-결과등록완료","DONE",IF(OR(U10="06-BIW생산중단",AND(U10="01-계획서미제출",I10<TODAY())),"CRITICAL",IF(OR(U10="04-검토중_조건불만족",U10="07-생산완료_미인수",U10="12-조건부승인검토"),"ACTION",IF(AND(ISNUMBER(W10),W10<=0),"OVERDUE",IF(AND(ISNUMBER(W10),W10<=14),"WARNING","ON TRACK"))))) | Y10: =IF(U10="11-결과등록완료","— 완료",IF(U10="01-계획서미제출",IF(I10<TODAY(),"계획서 제출 독촉 (OVERDUE)","계획서 제출 대기"),IF(U10="02-계획서제출_미검토","설계자: 계획서 검토 착수",IF(U10="03-검토중_조건충족","설계자: 승인 처리",IF(U10="04-검토중_조건불만족","보완 요청 → 협력사 재제출 독촉",IF(U10="05-계획서승인","시험편 준비 현황 확인",IF(U10="06-BIW생산중단","BIW 생산팀 확인 → 일정 재수립",IF(U10="07-생산완료_미인수","협력사 인수 독촉",IF(U10="08-단품준비완료","시험 일정 확인",IF(U10="09-시험준비중","시험 진행 모니터링",IF(U10="10-시험완료","결과 보고서 전산 등록 독촉",IF(U10="12-조건부승인검토","조건부 승인 여부 판단 → 관련부서 협의","—"))))))))))))
A11: 7 | B11: AE_PE | C11: Console Lid Assy | D11: =IFERROR(VLOOKUP(C11,'Reference Data 기준데이터'!$E$8:$F$30,2,FALSE),"") | E11: 외관 검사 | F11: =IFERROR(VLOOKUP(E11,'Reference Data 기준데이터'!$A$8:$F$30,2,FALSE),"") | G11: =IFERROR(VLOOKUP(B11&"_"&C11,'Reference Data 기준데이터'!$A$33:$B$51,2,FALSE),"") | H11: =IFERROR(VLOOKUP(B11,'Reference Data 기준데이터'!$A$2:$J$5,3,FALSE),"") | I11: =IFERROR(H11+VLOOKUP(B11,'Reference Data 기준데이터'!$A$2:$J$5,7,FALSE),"") | J11: 46049 | K11: Approved | L11: =IFERROR(H11+VLOOKUP(B11,'Reference Data 기준데이터'!$A$2:$J$5,8,FALSE),"") | M11: 46089 | N11: =IFERROR(IF(ISNUMBER(SEARCH("Vehicle",F11)),MAX(H11+VLOOKUP(B11,'Reference Data 기준데이터'!$A$2:$J$5,9,FALSE),VLOOKUP(B11,'Reference Data 기준데이터'!$A$2:$J$5,4,FALSE)),H11+VLOOKUP(B11,'Reference Data 기준데이터'!$A$2:$J$5,9,FALSE)),"") | O11: 46100 | P11: =IFERROR(N11+VLOOKUP(E11,'Reference Data 기준데이터'!$A$8:$F$30,4,FALSE),"") | Q11: 46122 | R11: =IFERROR(MIN(H11+VLOOKUP(B11,'Reference Data 기준데이터'!$A$2:$J$5,10,FALSE),VLOOKUP(B11,'Reference Data 기준데이터'!$A$2:$J$5,6,FALSE)),"") | S11: 46133 | U11: =IF(T11<>"",T11,IF(AND(S11<>"",Q11<>""),"11-결과등록완료",IF(AND(Q11<>"",S11=""),"10-시험완료",IF(AND(O11<>"",Q11=""),"09-시험준비중",IF(AND(M11<>"",O11=""),"08-단품준비완료",IF(K11="Approved","05-계획서승인",IF(K11="Revision Needed","04-검토중_조건불만족",IF(K11="Under Review","03-검토중_조건충족",IF(AND(J11<>"",K11=""),"02-계획서제출_미검토","01-계획서미제출"))))))))) | V11: =IFS(U11="01-계획서미제출",0,U11="02-계획서제출_미검토",0.05,U11="03-검토중_조건충족",0.1,U11="04-검토중_조건불만족",0.05,U11="05-계획서승인",0.2,U11="06-BIW생산중단",0.15,U11="07-생산완료_미인수",0.3,U11="08-단품준비완료",0.4,U11="09-시험준비중",0.55,U11="10-시험완료",0.85,U11="11-결과등록완료",1,U11="12-조건부승인검토",0.9,TRUE,0) | W11: =IF(S11<>"","-",IF(R11="","N/A",R11-TODAY())) | X11: =IF(U11="11-결과등록완료","DONE",IF(OR(U11="06-BIW생산중단",AND(U11="01-계획서미제출",I11<TODAY())),"CRITICAL",IF(OR(U11="04-검토중_조건불만족",U11="07-생산완료_미인수",U11="12-조건부승인검토"),"ACTION",IF(AND(ISNUMBER(W11),W11<=0),"OVERDUE",IF(AND(ISNUMBER(W11),W11<=14),"WARNING","ON TRACK"))))) | Y11: =IF(U11="11-결과등록완료","— 완료",IF(U11="01-계획서미제출",IF(I11<TODAY(),"계획서 제출 독촉 (OVERDUE)","계획서 제출 대기"),IF(U11="02-계획서제출_미검토","설계자: 계획서 검토 착수",IF(U11="03-검토중_조건충족","설계자: 승인 처리",IF(U11="04-검토중_조건불만족","보완 요청 → 협력사 재제출 독촉",IF(U11="05-계획서승인","시험편 준비 현황 확인",IF(U11="06-BIW생산중단","BIW 생산팀 확인 → 일정 재수립",IF(U11="07-생산완료_미인수","협력사 인수 독촉",IF(U11="08-단품준비완료","시험 일정 확인",IF(U11="09-시험준비중","시험 진행 모니터링",IF(U11="10-시험완료","결과 보고서 전산 등록 독촉",IF(U11="12-조건부승인검토","조건부 승인 여부 판단 → 관련부서 협의","—"))))))))))))
A12: 8 | B12: AE_PE | C12: Door Trim LH | D12: =IFERROR(VLOOKUP(C12,'Reference Data 기준데이터'!$E$8:$F$30,2,FALSE),"") | E12: VOC 방출 시험 | F12: =IFERROR(VLOOKUP(E12,'Reference Data 기준데이터'!$A$8:$F$30,2,FALSE),"") | G12: =IFERROR(VLOOKUP(B12&"_"&C12,'Reference Data 기준데이터'!$A$33:$B$51,2,FALSE),"") | H12: =IFERROR(VLOOKUP(B12,'Reference Data 기준데이터'!$A$2:$J$5,3,FALSE),"") | I12: =IFERROR(H12+VLOOKUP(B12,'Reference Data 기준데이터'!$A$2:$J$5,7,FALSE),"") | J12: 46050 | K12: Under Review | L12: =IFERROR(H12+VLOOKUP(B12,'Reference Data 기준데이터'!$A$2:$J$5,8,FALSE),"") | N12: =IFERROR(IF(ISNUMBER(SEARCH("Vehicle",F12)),MAX(H12+VLOOKUP(B12,'Reference Data 기준데이터'!$A$2:$J$5,9,FALSE),VLOOKUP(B12,'Reference Data 기준데이터'!$A$2:$J$5,4,FALSE)),H12+VLOOKUP(B12,'Reference Data 기준데이터'!$A$2:$J$5,9,FALSE)),"") | P12: =IFERROR(N12+VLOOKUP(E12,'Reference Data 기준데이터'!$A$8:$F$30,4,FALSE),"") | R12: =IFERROR(MIN(H12+VLOOKUP(B12,'Reference Data 기준데이터'!$A$2:$J$5,10,FALSE),VLOOKUP(B12,'Reference Data 기준데이터'!$A$2:$J$5,6,FALSE)),"") | U12: =IF(T12<>"",T12,IF(AND(S12<>"",Q12<>""),"11-결과등록완료",IF(AND(Q12<>"",S12=""),"10-시험완료",IF(AND(O12<>"",Q12=""),"09-시험준비중",IF(AND(M12<>"",O12=""),"08-단품준비완료",IF(K12="Approved","05-계획서승인",IF(K12="Revision Needed","04-검토중_조건불만족",IF(K12="Under Review","03-검토중_조건충족",IF(AND(J12<>"",K12=""),"02-계획서제출_미검토","01-계획서미제출"))))))))) | V12: =IFS(U12="01-계획서미제출",0,U12="02-계획서제출_미검토",0.05,U12="03-검토중_조건충족",0.1,U12="04-검토중_조건불만족",0.05,U12="05-계획서승인",0.2,U12="06-BIW생산중단",0.15,U12="07-생산완료_미인수",0.3,U12="08-단품준비완료",0.4,U12="09-시험준비중",0.55,U12="10-시험완료",0.85,U12="11-결과등록완료",1,U12="12-조건부승인검토",0.9,TRUE,0) | W12: =IF(S12<>"","-",IF(R12="","N/A",R12-TODAY())) | X12: =IF(U12="11-결과등록완료","DONE",IF(OR(U12="06-BIW생산중단",AND(U12="01-계획서미제출",I12<TODAY())),"CRITICAL",IF(OR(U12="04-검토중_조건불만족",U12="07-생산완료_미인수",U12="12-조건부승인검토"),"ACTION",IF(AND(ISNUMBER(W12),W12<=0),"OVERDUE",IF(AND(ISNUMBER(W12),W12<=14),"WARNING","ON TRACK"))))) | Y12: =IF(U12="11-결과등록완료","— 완료",IF(U12="01-계획서미제출",IF(I12<TODAY(),"계획서 제출 독촉 (OVERDUE)","계획서 제출 대기"),IF(U12="02-계획서제출_미검토","설계자: 계획서 검토 착수",IF(U12="03-검토중_조건충족","설계자: 승인 처리",IF(U12="04-검토중_조건불만족","보완 요청 → 협력사 재제출 독촉",IF(U12="05-계획서승인","시험편 준비 현황 확인",IF(U12="06-BIW생산중단","BIW 생산팀 확인 → 일정 재수립",IF(U12="07-생산완료_미인수","협력사 인수 독촉",IF(U12="08-단품준비완료","시험 일정 확인",IF(U12="09-시험준비중","시험 진행 모니터링",IF(U12="10-시험완료","결과 보고서 전산 등록 독촉",IF(U12="12-조건부승인검토","조건부 승인 여부 판단 → 관련부서 협의","—"))))))))))))
A13: 9 | B13: AE_PE | C13: Door Trim LH | D13: =IFERROR(VLOOKUP(C13,'Reference Data 기준데이터'!$E$8:$F$30,2,FALSE),"") | E13: 내후성 시험 | F13: =IFERROR(VLOOKUP(E13,'Reference Data 기준데이터'!$A$8:$F$30,2,FALSE),"") | G13: =IFERROR(VLOOKUP(B13&"_"&C13,'Reference Data 기준데이터'!$A$33:$B$51,2,FALSE),"") | H13: =IFERROR(VLOOKUP(B13,'Reference Data 기준데이터'!$A$2:$J$5,3,FALSE),"") | I13: =IFERROR(H13+VLOOKUP(B13,'Reference Data 기준데이터'!$A$2:$J$5,7,FALSE),"") | J13: 46051 | K13: Approved | L13: =IFERROR(H13+VLOOKUP(B13,'Reference Data 기준데이터'!$A$2:$J$5,8,FALSE),"") | M13: 46083 | N13: =IFERROR(IF(ISNUMBER(SEARCH("Vehicle",F13)),MAX(H13+VLOOKUP(B13,'Reference Data 기준데이터'!$A$2:$J$5,9,FALSE),VLOOKUP(B13,'Reference Data 기준데이터'!$A$2:$J$5,4,FALSE)),H13+VLOOKUP(B13,'Reference Data 기준데이터'!$A$2:$J$5,9,FALSE)),"") | O13: 46102 | P13: =IFERROR(N13+VLOOKUP(E13,'Reference Data 기준데이터'!$A$8:$F$30,4,FALSE),"") | Q13: 46124 | R13: =IFERROR(MIN(H13+VLOOKUP(B13,'Reference Data 기준데이터'!$A$2:$J$5,10,FALSE),VLOOKUP(B13,'Reference Data 기준데이터'!$A$2:$J$5,6,FALSE)),"") | U13: =IF(T13<>"",T13,IF(AND(S13<>"",Q13<>""),"11-결과등록완료",IF(AND(Q13<>"",S13=""),"10-시험완료",IF(AND(O13<>"",Q13=""),"09-시험준비중",IF(AND(M13<>"",O13=""),"08-단품준비완료",IF(K13="Approved","05-계획서승인",IF(K13="Revision Needed","04-검토중_조건불만족",IF(K13="Under Review","03-검토중_조건충족",IF(AND(J13<>"",K13=""),"02-계획서제출_미검토","01-계획서미제출"))))))))) | V13: =IFS(U13="01-계획서미제출",0,U13="02-계획서제출_미검토",0.05,U13="03-검토중_조건충족",0.1,U13="04-검토중_조건불만족",0.05,U13="05-계획서승인",0.2,U13="06-BIW생산중단",0.15,U13="07-생산완료_미인수",0.3,U13="08-단품준비완료",0.4,U13="09-시험준비중",0.55,U13="10-시험완료",0.85,U13="11-결과등록완료",1,U13="12-조건부승인검토",0.9,TRUE,0) | W13: =IF(S13<>"","-",IF(R13="","N/A",R13-TODAY())) | X13: =IF(U13="11-결과등록완료","DONE",IF(OR(U13="06-BIW생산중단",AND(U13="01-계획서미제출",I13<TODAY())),"CRITICAL",IF(OR(U13="04-검토중_조건불만족",U13="07-생산완료_미인수",U13="12-조건부승인검토"),"ACTION",IF(AND(ISNUMBER(W13),W13<=0),"OVERDUE",IF(AND(ISNUMBER(W13),W13<=14),"WARNING","ON TRACK"))))) | Y13: =IF(U13="11-결과등록완료","— 완료",IF(U13="01-계획서미제출",IF(I13<TODAY(),"계획서 제출 독촉 (OVERDUE)","계획서 제출 대기"),IF(U13="02-계획서제출_미검토","설계자: 계획서 검토 착수",IF(U13="03-검토중_조건충족","설계자: 승인 처리",IF(U13="04-검토중_조건불만족","보완 요청 → 협력사 재제출 독촉",IF(U13="05-계획서승인","시험편 준비 현황 확인",IF(U13="06-BIW생산중단","BIW 생산팀 확인 → 일정 재수립",IF(U13="07-생산완료_미인수","협력사 인수 독촉",IF(U13="08-단품준비완료","시험 일정 확인",IF(U13="09-시험준비중","시험 진행 모니터링",IF(U13="10-시험완료","결과 보고서 전산 등록 독촉",IF(U13="12-조건부승인검토","조건부 승인 여부 판단 → 관련부서 협의","—"))))))))))))
A14: 10 | B14: AE_PE | C14: Door Trim LH | D14: =IFERROR(VLOOKUP(C14,'Reference Data 기준데이터'!$E$8:$F$30,2,FALSE),"") | E14: 연소성 시험 | F14: =IFERROR(VLOOKUP(E14,'Reference Data 기준데이터'!$A$8:$F$30,2,FALSE),"") | G14: =IFERROR(VLOOKUP(B14&"_"&C14,'Reference Data 기준데이터'!$A$33:$B$51,2,FALSE),"") | H14: =IFERROR(VLOOKUP(B14,'Reference Data 기준데이터'!$A$2:$J$5,3,FALSE),"") | I14: =IFERROR(H14+VLOOKUP(B14,'Reference Data 기준데이터'!$A$2:$J$5,7,FALSE),"") | J14: 46047 | K14: Approved | L14: =IFERROR(H14+VLOOKUP(B14,'Reference Data 기준데이터'!$A$2:$J$5,8,FALSE),"") | N14: =IFERROR(IF(ISNUMBER(SEARCH("Vehicle",F14)),MAX(H14+VLOOKUP(B14,'Reference Data 기준데이터'!$A$2:$J$5,9,FALSE),VLOOKUP(B14,'Reference Data 기준데이터'!$A$2:$J$5,4,FALSE)),H14+VLOOKUP(B14,'Reference Data 기준데이터'!$A$2:$J$5,9,FALSE)),"") | P14: =IFERROR(N14+VLOOKUP(E14,'Reference Data 기준데이터'!$A$8:$F$30,4,FALSE),"") | R14: =IFERROR(MIN(H14+VLOOKUP(B14,'Reference Data 기준데이터'!$A$2:$J$5,10,FALSE),VLOOKUP(B14,'Reference Data 기준데이터'!$A$2:$J$5,6,FALSE)),"") | T14: 06-BIW생산중단 | U14: =IF(T14<>"",T14,IF(AND(S14<>"",Q14<>""),"11-결과등록완료",IF(AND(Q14<>"",S14=""),"10-시험완료",IF(AND(O14<>"",Q14=""),"09-시험준비중",IF(AND(M14<>"",O14=""),"08-단품준비완료",IF(K14="Approved","05-계획서승인",IF(K14="Revision Needed","04-검토중_조건불만족",IF(K14="Under Review","03-검토중_조건충족",IF(AND(J14<>"",K14=""),"02-계획서제출_미검토","01-계획서미제출"))))))))) | V14: =IFS(U14="01-계획서미제출",0,U14="02-계획서제출_미검토",0.05,U14="03-검토중_조건충족",0.1,U14="04-검토중_조건불만족",0.05,U14="05-계획서승인",0.2,U14="06-BIW생산중단",0.15,U14="07-생산완료_미인수",0.3,U14="08-단품준비완료",0.4,U14="09-시험준비중",0.55,U14="10-시험완료",0.85,U14="11-결과등록완료",1,U14="12-조건부승인검토",0.9,TRUE,0) | W14: =IF(S14<>"","-",IF(R14="","N/A",R14-TODAY())) | X14: =IF(U14="11-결과등록완료","DONE",IF(OR(U14="06-BIW생산중단",AND(U14="01-계획서미제출",I14<TODAY())),"CRITICAL",IF(OR(U14="04-검토중_조건불만족",U14="07-생산완료_미인수",U14="12-조건부승인검토"),"ACTION",IF(AND(ISNUMBER(W14),W14<=0),"OVERDUE",IF(AND(ISNUMBER(W14),W14<=14),"WARNING","ON TRACK"))))) | Y14: =IF(U14="11-결과등록완료","— 완료",IF(U14="01-계획서미제출",IF(I14<TODAY(),"계획서 제출 독촉 (OVERDUE)","계획서 제출 대기"),IF(U14="02-계획서제출_미검토","설계자: 계획서 검토 착수",IF(U14="03-검토중_조건충족","설계자: 승인 처리",IF(U14="04-검토중_조건불만족","보완 요청 → 협력사 재제출 독촉",IF(U14="05-계획서승인","시험편 준비 현황 확인",IF(U14="06-BIW생산중단","BIW 생산팀 확인 → 일정 재수립",IF(U14="07-생산완료_미인수","협력사 인수 독촉",IF(U14="08-단품준비완료","시험 일정 확인",IF(U14="09-시험준비중","시험 진행 모니터링",IF(U14="10-시험완료","결과 보고서 전산 등록 독촉",IF(U14="12-조건부승인검토","조건부 승인 여부 판단 → 관련부서 협의","—"))))))))))))
A15: 11 | B15: AE_PE | C15: Door Trim LH | D15: =IFERROR(VLOOKUP(C15,'Reference Data 기준데이터'!$E$8:$F$30,2,FALSE),"") | E15: 외관 검사 | F15: =IFERROR(VLOOKUP(E15,'Reference Data 기준데이터'!$A$8:$F$30,2,FALSE),"") | G15: =IFERROR(VLOOKUP(B15&"_"&C15,'Reference Data 기준데이터'!$A$33:$B$51,2,FALSE),"") | H15: =IFERROR(VLOOKUP(B15,'Reference Data 기준데이터'!$A$2:$J$5,3,FALSE),"") | I15: =IFERROR(H15+VLOOKUP(B15,'Reference Data 기준데이터'!$A$2:$J$5,7,FALSE),"") | J15: 46048 | K15: Approved | L15: =IFERROR(H15+VLOOKUP(B15,'Reference Data 기준데이터'!$A$2:$J$5,8,FALSE),"") | M15: 46085 | N15: =IFERROR(IF(ISNUMBER(SEARCH("Vehicle",F15)),MAX(H15+VLOOKUP(B15,'Reference Data 기준데이터'!$A$2:$J$5,9,FALSE),VLOOKUP(B15,'Reference Data 기준데이터'!$A$2:$J$5,4,FALSE)),H15+VLOOKUP(B15,'Reference Data 기준데이터'!$A$2:$J$5,9,FALSE)),"") | O15: 46104 | P15: =IFERROR(N15+VLOOKUP(E15,'Reference Data 기준데이터'!$A$8:$F$30,4,FALSE),"") | Q15: 46126 | R15: =IFERROR(MIN(H15+VLOOKUP(B15,'Reference Data 기준데이터'!$A$2:$J$5,10,FALSE),VLOOKUP(B15,'Reference Data 기준데이터'!$A$2:$J$5,6,FALSE)),"") | S15: 46133 | U15: =IF(T15<>"",T15,IF(AND(S15<>"",Q15<>""),"11-결과등록완료",IF(AND(Q15<>"",S15=""),"10-시험완료",IF(AND(O15<>"",Q15=""),"09-시험준비중",IF(AND(M15<>"",O15=""),"08-단품준비완료",IF(K15="Approved","05-계획서승인",IF(K15="Revision Needed","04-검토중_조건불만족",IF(K15="Under Review","03-검토중_조건충족",IF(AND(J15<>"",K15=""),"02-계획서제출_미검토","01-계획서미제출"))))))))) | V15: =IFS(U15="01-계획서미제출",0,U15="02-계획서제출_미검토",0.05,U15="03-검토중_조건충족",0.1,U15="04-검토중_조건불만족",0.05,U15="05-계획서승인",0.2,U15="06-BIW생산중단",0.15,U15="07-생산완료_미인수",0.3,U15="08-단품준비완료",0.4,U15="09-시험준비중",0.55,U15="10-시험완료",0.85,U15="11-결과등록완료",1,U15="12-조건부승인검토",0.9,TRUE,0) | W15: =IF(S15<>"","-",IF(R15="","N/A",R15-TODAY())) | X15: =IF(U15="11-결과등록완료","DONE",IF(OR(U15="06-BIW생산중단",AND(U15="01-계획서미제출",I15<TODAY())),"CRITICAL",IF(OR(U15="04-검토중_조건불만족",U15="07-생산완료_미인수",U15="12-조건부승인검토"),"ACTION",IF(AND(ISNUMBER(W15),W15<=0),"OVERDUE",IF(AND(ISNUMBER(W15),W15<=14),"WARNING","ON TRACK"))))) | Y15: =IF(U15="11-결과등록완료","— 완료",IF(U15="01-계획서미제출",IF(I15<TODAY(),"계획서 제출 독촉 (OVERDUE)","계획서 제출 대기"),IF(U15="02-계획서제출_미검토","설계자: 계획서 검토 착수",IF(U15="03-검토중_조건충족","설계자: 승인 처리",IF(U15="04-검토중_조건불만족","보완 요청 → 협력사 재제출 독촉",IF(U15="05-계획서승인","시험편 준비 현황 확인",IF(U15="06-BIW생산중단","BIW 생산팀 확인 → 일정 재수립",IF(U15="07-생산완료_미인수","협력사 인수 독촉",IF(U15="08-단품준비완료","시험 일정 확인",IF(U15="09-시험준비중","시험 진행 모니터링",IF(U15="10-시험완료","결과 보고서 전산 등록 독촉",IF(U15="12-조건부승인검토","조건부 승인 여부 판단 → 관련부서 협의","—"))))))))))))
A16: 12 | B16: AE_PE | C16: Pillar Trim C | D16: =IFERROR(VLOOKUP(C16,'Reference Data 기준데이터'!$E$8:$F$30,2,FALSE),"") | E16: 내후성 시험 | F16: =IFERROR(VLOOKUP(E16,'Reference Data 기준데이터'!$A$8:$F$30,2,FALSE),"") | G16: =IFERROR(VLOOKUP(B16&"_"&C16,'Reference Data 기준데이터'!$A$33:$B$51,2,FALSE),"") | H16: =IFERROR(VLOOKUP(B16,'Reference Data 기준데이터'!$A$2:$J$5,3,FALSE),"") | I16: =IFERROR(H16+VLOOKUP(B16,'Reference Data 기준데이터'!$A$2:$J$5,7,FALSE),"") | J16: 46049 | K16: Revision Needed | L16: =IFERROR(H16+VLOOKUP(B16,'Reference Data 기준데이터'!$A$2:$J$5,8,FALSE),"") | N16: =IFERROR(IF(ISNUMBER(SEARCH("Vehicle",F16)),MAX(H16+VLOOKUP(B16,'Reference Data 기준데이터'!$A$2:$J$5,9,FALSE),VLOOKUP(B16,'Reference Data 기준데이터'!$A$2:$J$5,4,FALSE)),H16+VLOOKUP(B16,'Reference Data 기준데이터'!$A$2:$J$5,9,FALSE)),"") | P16: =IFERROR(N16+VLOOKUP(E16,'Reference Data 기준데이터'!$A$8:$F$30,4,FALSE),"") | R16: =IFERROR(MIN(H16+VLOOKUP(B16,'Reference Data 기준데이터'!$A$2:$J$5,10,FALSE),VLOOKUP(B16,'Reference Data 기준데이터'!$A$2:$J$5,6,FALSE)),"") | U16: =IF(T16<>"",T16,IF(AND(S16<>"",Q16<>""),"11-결과등록완료",IF(AND(Q16<>"",S16=""),"10-시험완료",IF(AND(O16<>"",Q16=""),"09-시험준비중",IF(AND(M16<>"",O16=""),"08-단품준비완료",IF(K16="Approved","05-계획서승인",IF(K16="Revision Needed","04-검토중_조건불만족",IF(K16="Under Review","03-검토중_조건충족",IF(AND(J16<>"",K16=""),"02-계획서제출_미검토","01-계획서미제출"))))))))) | V16: =IFS(U16="01-계획서미제출",0,U16="02-계획서제출_미검토",0.05,U16="03-검토중_조건충족",0.1,U16="04-검토중_조건불만족",0.05,U16="05-계획서승인",0.2,U16="06-BIW생산중단",0.15,U16="07-생산완료_미인수",0.3,U16="08-단품준비완료",0.4,U16="09-시험준비중",0.55,U16="10-시험완료",0.85,U16="11-결과등록완료",1,U16="12-조건부승인검토",0.9,TRUE,0) | W16: =IF(S16<>"","-",IF(R16="","N/A",R16-TODAY())) | X16: =IF(U16="11-결과등록완료","DONE",IF(OR(U16="06-BIW생산중단",AND(U16="01-계획서미제출",I16<TODAY())),"CRITICAL",IF(OR(U16="04-검토중_조건불만족",U16="07-생산완료_미인수",U16="12-조건부승인검토"),"ACTION",IF(AND(ISNUMBER(W16),W16<=0),"OVERDUE",IF(AND(ISNUMBER(W16),W16<=14),"WARNING","ON TRACK"))))) | Y16: =IF(U16="11-결과등록완료","— 완료",IF(U16="01-계획서미제출",IF(I16<TODAY(),"계획서 제출 독촉 (OVERDUE)","계획서 제출 대기"),IF(U16="02-계획서제출_미검토","설계자: 계획서 검토 착수",IF(U16="03-검토중_조건충족","설계자: 승인 처리",IF(U16="04-검토중_조건불만족","보완 요청 → 협력사 재제출 독촉",IF(U16="05-계획서승인","시험편 준비 현황 확인",IF(U16="06-BIW생산중단","BIW 생산팀 확인 → 일정 재수립",IF(U16="07-생산완료_미인수","협력사 인수 독촉",IF(U16="08-단품준비완료","시험 일정 확인",IF(U16="09-시험준비중","시험 진행 모니터링",IF(U16="10-시험완료","결과 보고서 전산 등록 독촉",IF(U16="12-조건부승인검토","조건부 승인 여부 판단 → 관련부서 협의","—"))))))))))))
A17: 13 | B17: AE_PE | C17: Pillar Trim C | D17: =IFERROR(VLOOKUP(C17,'Reference Data 기준데이터'!$E$8:$F$30,2,FALSE),"") | E17: 연소성 시험 | F17: =IFERROR(VLOOKUP(E17,'Reference Data 기준데이터'!$A$8:$F$30,2,FALSE),"") | G17: =IFERROR(VLOOKUP(B17&"_"&C17,'Reference Data 기준데이터'!$A$33:$B$51,2,FALSE),"") | H17: =IFERROR(VLOOKUP(B17,'Reference Data 기준데이터'!$A$2:$J$5,3,FALSE),"") | I17: =IFERROR(H17+VLOOKUP(B17,'Reference Data 기준데이터'!$A$2:$J$5,7,FALSE),"") | J17: 46050 | K17: Approved | L17: =IFERROR(H17+VLOOKUP(B17,'Reference Data 기준데이터'!$A$2:$J$5,8,FALSE),"") | M17: 46087 | N17: =IFERROR(IF(ISNUMBER(SEARCH("Vehicle",F17)),MAX(H17+VLOOKUP(B17,'Reference Data 기준데이터'!$A$2:$J$5,9,FALSE),VLOOKUP(B17,'Reference Data 기준데이터'!$A$2:$J$5,4,FALSE)),H17+VLOOKUP(B17,'Reference Data 기준데이터'!$A$2:$J$5,9,FALSE)),"") | O17: 46100 | P17: =IFERROR(N17+VLOOKUP(E17,'Reference Data 기준데이터'!$A$8:$F$30,4,FALSE),"") | R17: =IFERROR(MIN(H17+VLOOKUP(B17,'Reference Data 기준데이터'!$A$2:$J$5,10,FALSE),VLOOKUP(B17,'Reference Data 기준데이터'!$A$2:$J$5,6,FALSE)),"") | U17: =IF(T17<>"",T17,IF(AND(S17<>"",Q17<>""),"11-결과등록완료",IF(AND(Q17<>"",S17=""),"10-시험완료",IF(AND(O17<>"",Q17=""),"09-시험준비중",IF(AND(M17<>"",O17=""),"08-단품준비완료",IF(K17="Approved","05-계획서승인",IF(K17="Revision Needed","04-검토중_조건불만족",IF(K17="Under Review","03-검토중_조건충족",IF(AND(J17<>"",K17=""),"02-계획서제출_미검토","01-계획서미제출"))))))))) | V17: =IFS(U17="01-계획서미제출",0,U17="02-계획서제출_미검토",0.05,U17="03-검토중_조건충족",0.1,U17="04-검토중_조건불만족",0.05,U17="05-계획서승인",0.2,U17="06-BIW생산중단",0.15,U17="07-생산완료_미인수",0.3,U17="08-단품준비완료",0.4,U17="09-시험준비중",0.55,U17="10-시험완료",0.85,U17="11-결과등록완료",1,U17="12-조건부승인검토",0.9,TRUE,0) | W17: =IF(S17<>"","-",IF(R17="","N/A",R17-TODAY())) | X17: =IF(U17="11-결과등록완료","DONE",IF(OR(U17="06-BIW생산중단",AND(U17="01-계획서미제출",I17<TODAY())),"CRITICAL",IF(OR(U17="04-검토중_조건불만족",U17="07-생산완료_미인수",U17="12-조건부승인검토"),"ACTION",IF(AND(ISNUMBER(W17),W17<=0),"OVERDUE",IF(AND(ISNUMBER(W17),W17<=14),"WARNING","ON TRACK"))))) | Y17: =IF(U17="11-결과등록완료","— 완료",IF(U17="01-계획서미제출",IF(I17<TODAY(),"계획서 제출 독촉 (OVERDUE)","계획서 제출 대기"),IF(U17="02-계획서제출_미검토","설계자: 계획서 검토 착수",IF(U17="03-검토중_조건충족","설계자: 승인 처리",IF(U17="04-검토중_조건불만족","보완 요청 → 협력사 재제출 독촉",IF(U17="05-계획서승인","시험편 준비 현황 확인",IF(U17="06-BIW생산중단","BIW 생산팀 확인 → 일정 재수립",IF(U17="07-생산완료_미인수","협력사 인수 독촉",IF(U17="08-단품준비완료","시험 일정 확인",IF(U17="09-시험준비중","시험 진행 모니터링",IF(U17="10-시험완료","결과 보고서 전산 등록 독촉",IF(U17="12-조건부승인검토","조건부 승인 여부 판단 → 관련부서 협의","—"))))))))))))
A18: 14 | B18: AE_PE | C18: Pillar Trim C | D18: =IFERROR(VLOOKUP(C18,'Reference Data 기준데이터'!$E$8:$F$30,2,FALSE),"") | E18: 치수 검사 | F18: =IFERROR(VLOOKUP(E18,'Reference Data 기준데이터'!$A$8:$F$30,2,FALSE),"") | G18: =IFERROR(VLOOKUP(B18&"_"&C18,'Reference Data 기준데이터'!$A$33:$B$51,2,FALSE),"") | H18: =IFERROR(VLOOKUP(B18,'Reference Data 기준데이터'!$A$2:$J$5,3,FALSE),"") | I18: =IFERROR(H18+VLOOKUP(B18,'Reference Data 기준데이터'!$A$2:$J$5,7,FALSE),"") | J18: 46051 | K18: Approved | L18: =IFERROR(H18+VLOOKUP(B18,'Reference Data 기준데이터'!$A$2:$J$5,8,FALSE),"") | M18: 46088 | N18: =IFERROR(IF(ISNUMBER(SEARCH("Vehicle",F18)),MAX(H18+VLOOKUP(B18,'Reference Data 기준데이터'!$A$2:$J$5,9,FALSE),VLOOKUP(B18,'Reference Data 기준데이터'!$A$2:$J$5,4,FALSE)),H18+VLOOKUP(B18,'Reference Data 기준데이터'!$A$2:$J$5,9,FALSE)),"") | O18: 46101 | P18: =IFERROR(N18+VLOOKUP(E18,'Reference Data 기준데이터'!$A$8:$F$30,4,FALSE),"") | Q18: 46122 | R18: =IFERROR(MIN(H18+VLOOKUP(B18,'Reference Data 기준데이터'!$A$2:$J$5,10,FALSE),VLOOKUP(B18,'Reference Data 기준데이터'!$A$2:$J$5,6,FALSE)),"") | S18: 46132 | U18: =IF(T18<>"",T18,IF(AND(S18<>"",Q18<>""),"11-결과등록완료",IF(AND(Q18<>"",S18=""),"10-시험완료",IF(AND(O18<>"",Q18=""),"09-시험준비중",IF(AND(M18<>"",O18=""),"08-단품준비완료",IF(K18="Approved","05-계획서승인",IF(K18="Revision Needed","04-검토중_조건불만족",IF(K18="Under Review","03-검토중_조건충족",IF(AND(J18<>"",K18=""),"02-계획서제출_미검토","01-계획서미제출"))))))))) | V18: =IFS(U18="01-계획서미제출",0,U18="02-계획서제출_미검토",0.05,U18="03-검토중_조건충족",0.1,U18="04-검토중_조건불만족",0.05,U18="05-계획서승인",0.2,U18="06-BIW생산중단",0.15,U18="07-생산완료_미인수",0.3,U18="08-단품준비완료",0.4,U18="09-시험준비중",0.55,U18="10-시험완료",0.85,U18="11-결과등록완료",1,U18="12-조건부승인검토",0.9,TRUE,0) | W18: =IF(S18<>"","-",IF(R18="","N/A",R18-TODAY())) | X18: =IF(U18="11-결과등록완료","DONE",IF(OR(U18="06-BIW생산중단",AND(U18="01-계획서미제출",I18<TODAY())),"CRITICAL",IF(OR(U18="04-검토중_조건불만족",U18="07-생산완료_미인수",U18="12-조건부승인검토"),"ACTION",IF(AND(ISNUMBER(W18),W18<=0),"OVERDUE",IF(AND(ISNUMBER(W18),W18<=14),"WARNING","ON TRACK"))))) | Y18: =IF(U18="11-결과등록완료","— 완료",IF(U18="01-계획서미제출",IF(I18<TODAY(),"계획서 제출 독촉 (OVERDUE)","계획서 제출 대기"),IF(U18="02-계획서제출_미검토","설계자: 계획서 검토 착수",IF(U18="03-검토중_조건충족","설계자: 승인 처리",IF(U18="04-검토중_조건불만족","보완 요청 → 협력사 재제출 독촉",IF(U18="05-계획서승인","시험편 준비 현황 확인",IF(U18="06-BIW생산중단","BIW 생산팀 확인 → 일정 재수립",IF(U18="07-생산완료_미인수","협력사 인수 독촉",IF(U18="08-단품준비완료","시험 일정 확인",IF(U18="09-시험준비중","시험 진행 모니터링",IF(U18="10-시험완료","결과 보고서 전산 등록 독촉",IF(U18="12-조건부승인검토","조건부 승인 여부 판단 → 관련부서 협의","—"))))))))))))
A19: 15 | B19: AE_PE | C19: Front Seat Assy LH | D19: =IFERROR(VLOOKUP(C19,'Reference Data 기준데이터'!$E$8:$F$30,2,FALSE),"") | E19: 시트 내구 시험 | F19: =IFERROR(VLOOKUP(E19,'Reference Data 기준데이터'!$A$8:$F$30,2,FALSE),"") | G19: =IFERROR(VLOOKUP(B19&"_"&C19,'Reference Data 기준데이터'!$A$33:$B$51,2,FALSE),"") | H19: =IFERROR(VLOOKUP(B19,'Reference Data 기준데이터'!$A$2:$J$5,3,FALSE),"") | I19: =IFERROR(H19+VLOOKUP(B19,'Reference Data 기준데이터'!$A$2:$J$5,7,FALSE),"") | J19: 46047 | K19: Approved | L19: =IFERROR(H19+VLOOKUP(B19,'Reference Data 기준데이터'!$A$2:$J$5,8,FALSE),"") | M19: 46089 | N19: =IFERROR(IF(ISNUMBER(SEARCH("Vehicle",F19)),MAX(H19+VLOOKUP(B19,'Reference Data 기준데이터'!$A$2:$J$5,9,FALSE),VLOOKUP(B19,'Reference Data 기준데이터'!$A$2:$J$5,4,FALSE)),H19+VLOOKUP(B19,'Reference Data 기준데이터'!$A$2:$J$5,9,FALSE)),"") | P19: =IFERROR(N19+VLOOKUP(E19,'Reference Data 기준데이터'!$A$8:$F$30,4,FALSE),"") | R19: =IFERROR(MIN(H19+VLOOKUP(B19,'Reference Data 기준데이터'!$A$2:$J$5,10,FALSE),VLOOKUP(B19,'Reference Data 기준데이터'!$A$2:$J$5,6,FALSE)),"") | T19: 07-생산완료_미인수 | U19: =IF(T19<>"",T19,IF(AND(S19<>"",Q19<>""),"11-결과등록완료",IF(AND(Q19<>"",S19=""),"10-시험완료",IF(AND(O19<>"",Q19=""),"09-시험준비중",IF(AND(M19<>"",O19=""),"08-단품준비완료",IF(K19="Approved","05-계획서승인",IF(K19="Revision Needed","04-검토중_조건불만족",IF(K19="Under Review","03-검토중_조건충족",IF(AND(J19<>"",K19=""),"02-계획서제출_미검토","01-계획서미제출"))))))))) | V19: =IFS(U19="01-계획서미제출",0,U19="02-계획서제출_미검토",0.05,U19="03-검토중_조건충족",0.1,U19="04-검토중_조건불만족",0.05,U19="05-계획서승인",0.2,U19="06-BIW생산중단",0.15,U19="07-생산완료_미인수",0.3,U19="08-단품준비완료",0.4,U19="09-시험준비중",0.55,U19="10-시험완료",0.85,U19="11-결과등록완료",1,U19="12-조건부승인검토",0.9,TRUE,0) | W19: =IF(S19<>"","-",IF(R19="","N/A",R19-TODAY())) | X19: =IF(U19="11-결과등록완료","DONE",IF(OR(U19="06-BIW생산중단",AND(U19="01-계획서미제출",I19<TODAY())),"CRITICAL",IF(OR(U19="04-검토중_조건불만족",U19="07-생산완료_미인수",U19="12-조건부승인검토"),"ACTION",IF(AND(ISNUMBER(W19),W19<=0),"OVERDUE",IF(AND(ISNUMBER(W19),W19<=14),"WARNING","ON TRACK"))))) | Y19: =IF(U19="11-결과등록완료","— 완료",IF(U19="01-계획서미제출",IF(I19<TODAY(),"계획서 제출 독촉 (OVERDUE)","계획서 제출 대기"),IF(U19="02-계획서제출_미검토","설계자: 계획서 검토 착수",IF(U19="03-검토중_조건충족","설계자: 승인 처리",IF(U19="04-검토중_조건불만족","보완 요청 → 협력사 재제출 독촉",IF(U19="05-계획서승인","시험편 준비 현황 확인",IF(U19="06-BIW생산중단","BIW 생산팀 확인 → 일정 재수립",IF(U19="07-생산완료_미인수","협력사 인수 독촉",IF(U19="08-단품준비완료","시험 일정 확인",IF(U19="09-시험준비중","시험 진행 모니터링",IF(U19="10-시험완료","결과 보고서 전산 등록 독촉",IF(U19="12-조건부승인검토","조건부 승인 여부 판단 → 관련부서 협의","—"))))))))))))
A20: 16 | B20: AE_PE | C20: Front Seat Assy LH | D20: =IFERROR(VLOOKUP(C20,'Reference Data 기준데이터'!$E$8:$F$30,2,FALSE),"") | E20: 안전벨트 앵커리지 | F20: =IFERROR(VLOOKUP(E20,'Reference Data 기준데이터'!$A$8:$F$30,2,FALSE),"") | G20: =IFERROR(VLOOKUP(B20&"_"&C20,'Reference Data 기준데이터'!$A$33:$B$51,2,FALSE),"") | H20: =IFERROR(VLOOKUP(B20,'Reference Data 기준데이터'!$A$2:$J$5,3,FALSE),"") | I20: =IFERROR(H20+VLOOKUP(B20,'Reference Data 기준데이터'!$A$2:$J$5,7,FALSE),"") | J20: 46048 | K20: Approved | L20: =IFERROR(H20+VLOOKUP(B20,'Reference Data 기준데이터'!$A$2:$J$5,8,FALSE),"") | N20: =IFERROR(IF(ISNUMBER(SEARCH("Vehicle",F20)),MAX(H20+VLOOKUP(B20,'Reference Data 기준데이터'!$A$2:$J$5,9,FALSE),VLOOKUP(B20,'Reference Data 기준데이터'!$A$2:$J$5,4,FALSE)),H20+VLOOKUP(B20,'Reference Data 기준데이터'!$A$2:$J$5,9,FALSE)),"") | P20: =IFERROR(N20+VLOOKUP(E20,'Reference Data 기준데이터'!$A$8:$F$30,4,FALSE),"") | R20: =IFERROR(MIN(H20+VLOOKUP(B20,'Reference Data 기준데이터'!$A$2:$J$5,10,FALSE),VLOOKUP(B20,'Reference Data 기준데이터'!$A$2:$J$5,6,FALSE)),"") | U20: =IF(T20<>"",T20,IF(AND(S20<>"",Q20<>""),"11-결과등록완료",IF(AND(Q20<>"",S20=""),"10-시험완료",IF(AND(O20<>"",Q20=""),"09-시험준비중",IF(AND(M20<>"",O20=""),"08-단품준비완료",IF(K20="Approved","05-계획서승인",IF(K20="Revision Needed","04-검토중_조건불만족",IF(K20="Under Review","03-검토중_조건충족",IF(AND(J20<>"",K20=""),"02-계획서제출_미검토","01-계획서미제출"))))))))) | V20: =IFS(U20="01-계획서미제출",0,U20="02-계획서제출_미검토",0.05,U20="03-검토중_조건충족",0.1,U20="04-검토중_조건불만족",0.05,U20="05-계획서승인",0.2,U20="06-BIW생산중단",0.15,U20="07-생산완료_미인수",0.3,U20="08-단품준비완료",0.4,U20="09-시험준비중",0.55,U20="10-시험완료",0.85,U20="11-결과등록완료",1,U20="12-조건부승인검토",0.9,TRUE,0) | W20: =IF(S20<>"","-",IF(R20="","N/A",R20-TODAY())) | X20: =IF(U20="11-결과등록완료","DONE",IF(OR(U20="06-BIW생산중단",AND(U20="01-계획서미제출",I20<TODAY())),"CRITICAL",IF(OR(U20="04-검토중_조건불만족",U20="07-생산완료_미인수",U20="12-조건부승인검토"),"ACTION",IF(AND(ISNUMBER(W20),W20<=0),"OVERDUE",IF(AND(ISNUMBER(W20),W20<=14),"WARNING","ON TRACK"))))) | Y20: =IF(U20="11-결과등록완료","— 완료",IF(U20="01-계획서미제출",IF(I20<TODAY(),"계획서 제출 독촉 (OVERDUE)","계획서 제출 대기"),IF(U20="02-계획서제출_미검토","설계자: 계획서 검토 착수",IF(U20="03-검토중_조건충족","설계자: 승인 처리",IF(U20="04-검토중_조건불만족","보완 요청 → 협력사 재제출 독촉",IF(U20="05-계획서승인","시험편 준비 현황 확인",IF(U20="06-BIW생산중단","BIW 생산팀 확인 → 일정 재수립",IF(U20="07-생산완료_미인수","협력사 인수 독촉",IF(U20="08-단품준비완료","시험 일정 확인",IF(U20="09-시험준비중","시험 진행 모니터링",IF(U20="10-시험완료","결과 보고서 전산 등록 독촉",IF(U20="12-조건부승인검토","조건부 승인 여부 판단 → 관련부서 협의","—"))))))))))))
A21: 17 | B21: AE_PE | C21: Front Seat Assy LH | D21: =IFERROR(VLOOKUP(C21,'Reference Data 기준데이터'!$E$8:$F$30,2,FALSE),"") | E21: H-Point 검증 | F21: =IFERROR(VLOOKUP(E21,'Reference Data 기준데이터'!$A$8:$F$30,2,FALSE),"") | G21: =IFERROR(VLOOKUP(B21&"_"&C21,'Reference Data 기준데이터'!$A$33:$B$51,2,FALSE),"") | H21: =IFERROR(VLOOKUP(B21,'Reference Data 기준데이터'!$A$2:$J$5,3,FALSE),"") | I21: =IFERROR(H21+VLOOKUP(B21,'Reference Data 기준데이터'!$A$2:$J$5,7,FALSE),"") | J21: 46049 | K21: Approved | L21: =IFERROR(H21+VLOOKUP(B21,'Reference Data 기준데이터'!$A$2:$J$5,8,FALSE),"") | M21: 46083 | N21: =IFERROR(IF(ISNUMBER(SEARCH("Vehicle",F21)),MAX(H21+VLOOKUP(B21,'Reference Data 기준데이터'!$A$2:$J$5,9,FALSE),VLOOKUP(B21,'Reference Data 기준데이터'!$A$2:$J$5,4,FALSE)),H21+VLOOKUP(B21,'Reference Data 기준데이터'!$A$2:$J$5,9,FALSE)),"") | O21: 46104 | P21: =IFERROR(N21+VLOOKUP(E21,'Reference Data 기준데이터'!$A$8:$F$30,4,FALSE),"") | R21: =IFERROR(MIN(H21+VLOOKUP(B21,'Reference Data 기준데이터'!$A$2:$J$5,10,FALSE),VLOOKUP(B21,'Reference Data 기준데이터'!$A$2:$J$5,6,FALSE)),"") | U21: =IF(T21<>"",T21,IF(AND(S21<>"",Q21<>""),"11-결과등록완료",IF(AND(Q21<>"",S21=""),"10-시험완료",IF(AND(O21<>"",Q21=""),"09-시험준비중",IF(AND(M21<>"",O21=""),"08-단품준비완료",IF(K21="Approved","05-계획서승인",IF(K21="Revision Needed","04-검토중_조건불만족",IF(K21="Under Review","03-검토중_조건충족",IF(AND(J21<>"",K21=""),"02-계획서제출_미검토","01-계획서미제출"))))))))) | V21: =IFS(U21="01-계획서미제출",0,U21="02-계획서제출_미검토",0.05,U21="03-검토중_조건충족",0.1,U21="04-검토중_조건불만족",0.05,U21="05-계획서승인",0.2,U21="06-BIW생산중단",0.15,U21="07-생산완료_미인수",0.3,U21="08-단품준비완료",0.4,U21="09-시험준비중",0.55,U21="10-시험완료",0.85,U21="11-결과등록완료",1,U21="12-조건부승인검토",0.9,TRUE,0) | W21: =IF(S21<>"","-",IF(R21="","N/A",R21-TODAY())) | X21: =IF(U21="11-결과등록완료","DONE",IF(OR(U21="06-BIW생산중단",AND(U21="01-계획서미제출",I21<TODAY())),"CRITICAL",IF(OR(U21="04-검토중_조건불만족",U21="07-생산완료_미인수",U21="12-조건부승인검토"),"ACTION",IF(AND(ISNUMBER(W21),W21<=0),"OVERDUE",IF(AND(ISNUMBER(W21),W21<=14),"WARNING","ON TRACK"))))) | Y21: =IF(U21="11-결과등록완료","— 완료",IF(U21="01-계획서미제출",IF(I21<TODAY(),"계획서 제출 독촉 (OVERDUE)","계획서 제출 대기"),IF(U21="02-계획서제출_미검토","설계자: 계획서 검토 착수",IF(U21="03-검토중_조건충족","설계자: 승인 처리",IF(U21="04-검토중_조건불만족","보완 요청 → 협력사 재제출 독촉",IF(U21="05-계획서승인","시험편 준비 현황 확인",IF(U21="06-BIW생산중단","BIW 생산팀 확인 → 일정 재수립",IF(U21="07-생산완료_미인수","협력사 인수 독촉",IF(U21="08-단품준비완료","시험 일정 확인",IF(U21="09-시험준비중","시험 진행 모니터링",IF(U21="10-시험완료","결과 보고서 전산 등록 독촉",IF(U21="12-조건부승인검토","조건부 승인 여부 판단 → 관련부서 협의","—"))))))))))))
A22: 18 | B22: AE_PE | C22: Front Seat Assy LH | D22: =IFERROR(VLOOKUP(C22,'Reference Data 기준데이터'!$E$8:$F$30,2,FALSE),"") | E22: BSR 시험 | F22: =IFERROR(VLOOKUP(E22,'Reference Data 기준데이터'!$A$8:$F$30,2,FALSE),"") | G22: =IFERROR(VLOOKUP(B22&"_"&C22,'Reference Data 기준데이터'!$A$33:$B$51,2,FALSE),"") | H22: =IFERROR(VLOOKUP(B22,'Reference Data 기준데이터'!$A$2:$J$5,3,FALSE),"") | I22: =IFERROR(H22+VLOOKUP(B22,'Reference Data 기준데이터'!$A$2:$J$5,7,FALSE),"") | J22: 46050 | K22: Approved | L22: =IFERROR(H22+VLOOKUP(B22,'Reference Data 기준데이터'!$A$2:$J$5,8,FALSE),"") | M22: 46084 | N22: =IFERROR(IF(ISNUMBER(SEARCH("Vehicle",F22)),MAX(H22+VLOOKUP(B22,'Reference Data 기준데이터'!$A$2:$J$5,9,FALSE),VLOOKUP(B22,'Reference Data 기준데이터'!$A$2:$J$5,4,FALSE)),H22+VLOOKUP(B22,'Reference Data 기준데이터'!$A$2:$J$5,9,FALSE)),"") | O22: 46099 | P22: =IFERROR(N22+VLOOKUP(E22,'Reference Data 기준데이터'!$A$8:$F$30,4,FALSE),"") | Q22: 46126 | R22: =IFERROR(MIN(H22+VLOOKUP(B22,'Reference Data 기준데이터'!$A$2:$J$5,10,FALSE),VLOOKUP(B22,'Reference Data 기준데이터'!$A$2:$J$5,6,FALSE)),"") | U22: =IF(T22<>"",T22,IF(AND(S22<>"",Q22<>""),"11-결과등록완료",IF(AND(Q22<>"",S22=""),"10-시험완료",IF(AND(O22<>"",Q22=""),"09-시험준비중",IF(AND(M22<>"",O22=""),"08-단품준비완료",IF(K22="Approved","05-계획서승인",IF(K22="Revision Needed","04-검토중_조건불만족",IF(K22="Under Review","03-검토중_조건충족",IF(AND(J22<>"",K22=""),"02-계획서제출_미검토","01-계획서미제출"))))))))) | V22: =IFS(U22="01-계획서미제출",0,U22="02-계획서제출_미검토",0.05,U22="03-검토중_조건충족",0.1,U22="04-검토중_조건불만족",0.05,U22="05-계획서승인",0.2,U22="06-BIW생산중단",0.15,U22="07-생산완료_미인수",0.3,U22="08-단품준비완료",0.4,U22="09-시험준비중",0.55,U22="10-시험완료",0.85,U22="11-결과등록완료",1,U22="12-조건부승인검토",0.9,TRUE,0) | W22: =IF(S22<>"","-",IF(R22="","N/A",R22-TODAY())) | X22: =IF(U22="11-결과등록완료","DONE",IF(OR(U22="06-BIW생산중단",AND(U22="01-계획서미제출",I22<TODAY())),"CRITICAL",IF(OR(U22="04-검토중_조건불만족",U22="07-생산완료_미인수",U22="12-조건부승인검토"),"ACTION",IF(AND(ISNUMBER(W22),W22<=0),"OVERDUE",IF(AND(ISNUMBER(W22),W22<=14),"WARNING","ON TRACK"))))) | Y22: =IF(U22="11-결과등록완료","— 완료",IF(U22="01-계획서미제출",IF(I22<TODAY(),"계획서 제출 독촉 (OVERDUE)","계획서 제출 대기"),IF(U22="02-계획서제출_미검토","설계자: 계획서 검토 착수",IF(U22="03-검토중_조건충족","설계자: 승인 처리",IF(U22="04-검토중_조건불만족","보완 요청 → 협력사 재제출 독촉",IF(U22="05-계획서승인","시험편 준비 현황 확인",IF(U22="06-BIW생산중단","BIW 생산팀 확인 → 일정 재수립",IF(U22="07-생산완료_미인수","협력사 인수 독촉",IF(U22="08-단품준비완료","시험 일정 확인",IF(U22="09-시험준비중","시험 진행 모니터링",IF(U22="10-시험완료","결과 보고서 전산 등록 독촉",IF(U22="12-조건부승인검토","조건부 승인 여부 판단 → 관련부서 협의","—"))))))))))))
A23: 19 | B23: AE_PE | C23: Rear Seat Assy | D23: =IFERROR(VLOOKUP(C23,'Reference Data 기준데이터'!$E$8:$F$30,2,FALSE),"") | E23: 시트 내구 시험 | F23: =IFERROR(VLOOKUP(E23,'Reference Data 기준데이터'!$A$8:$F$30,2,FALSE),"") | G23: =IFERROR(VLOOKUP(B23&"_"&C23,'Reference Data 기준데이터'!$A$33:$B$51,2,FALSE),"") | H23: =IFERROR(VLOOKUP(B23,'Reference Data 기준데이터'!$A$2:$J$5,3,FALSE),"") | I23: =IFERROR(H23+VLOOKUP(B23,'Reference Data 기준데이터'!$A$2:$J$5,7,FALSE),"") | J23: 46051 | K23: Approved | L23: =IFERROR(H23+VLOOKUP(B23,'Reference Data 기준데이터'!$A$2:$J$5,8,FALSE),"") | M23: 46085 | N23: =IFERROR(IF(ISNUMBER(SEARCH("Vehicle",F23)),MAX(H23+VLOOKUP(B23,'Reference Data 기준데이터'!$A$2:$J$5,9,FALSE),VLOOKUP(B23,'Reference Data 기준데이터'!$A$2:$J$5,4,FALSE)),H23+VLOOKUP(B23,'Reference Data 기준데이터'!$A$2:$J$5,9,FALSE)),"") | P23: =IFERROR(N23+VLOOKUP(E23,'Reference Data 기준데이터'!$A$8:$F$30,4,FALSE),"") | R23: =IFERROR(MIN(H23+VLOOKUP(B23,'Reference Data 기준데이터'!$A$2:$J$5,10,FALSE),VLOOKUP(B23,'Reference Data 기준데이터'!$A$2:$J$5,6,FALSE)),"") | U23: =IF(T23<>"",T23,IF(AND(S23<>"",Q23<>""),"11-결과등록완료",IF(AND(Q23<>"",S23=""),"10-시험완료",IF(AND(O23<>"",Q23=""),"09-시험준비중",IF(AND(M23<>"",O23=""),"08-단품준비완료",IF(K23="Approved","05-계획서승인",IF(K23="Revision Needed","04-검토중_조건불만족",IF(K23="Under Review","03-검토중_조건충족",IF(AND(J23<>"",K23=""),"02-계획서제출_미검토","01-계획서미제출"))))))))) | V23: =IFS(U23="01-계획서미제출",0,U23="02-계획서제출_미검토",0.05,U23="03-검토중_조건충족",0.1,U23="04-검토중_조건불만족",0.05,U23="05-계획서승인",0.2,U23="06-BIW생산중단",0.15,U23="07-생산완료_미인수",0.3,U23="08-단품준비완료",0.4,U23="09-시험준비중",0.55,U23="10-시험완료",0.85,U23="11-결과등록완료",1,U23="12-조건부승인검토",0.9,TRUE,0) | W23: =IF(S23<>"","-",IF(R23="","N/A",R23-TODAY())) | X23: =IF(U23="11-결과등록완료","DONE",IF(OR(U23="06-BIW생산중단",AND(U23="01-계획서미제출",I23<TODAY())),"CRITICAL",IF(OR(U23="04-검토중_조건불만족",U23="07-생산완료_미인수",U23="12-조건부승인검토"),"ACTION",IF(AND(ISNUMBER(W23),W23<=0),"OVERDUE",IF(AND(ISNUMBER(W23),W23<=14),"WARNING","ON TRACK"))))) | Y23: =IF(U23="11-결과등록완료","— 완료",IF(U23="01-계획서미제출",IF(I23<TODAY(),"계획서 제출 독촉 (OVERDUE)","계획서 제출 대기"),IF(U23="02-계획서제출_미검토","설계자: 계획서 검토 착수",IF(U23="03-검토중_조건충족","설계자: 승인 처리",IF(U23="04-검토중_조건불만족","보완 요청 → 협력사 재제출 독촉",IF(U23="05-계획서승인","시험편 준비 현황 확인",IF(U23="06-BIW생산중단","BIW 생산팀 확인 → 일정 재수립",IF(U23="07-생산완료_미인수","협력사 인수 독촉",IF(U23="08-단품준비완료","시험 일정 확인",IF(U23="09-시험준비중","시험 진행 모니터링",IF(U23="10-시험완료","결과 보고서 전산 등록 독촉",IF(U23="12-조건부승인검토","조건부 승인 여부 판단 → 관련부서 협의","—"))))))))))))
A24: 20 | B24: AE_PE | C24: Rear Seat Assy | D24: =IFERROR(VLOOKUP(C24,'Reference Data 기준데이터'!$E$8:$F$30,2,FALSE),"") | E24: ISOFIX 강도 시험 | F24: =IFERROR(VLOOKUP(E24,'Reference Data 기준데이터'!$A$8:$F$30,2,FALSE),"") | G24: =IFERROR(VLOOKUP(B24&"_"&C24,'Reference Data 기준데이터'!$A$33:$B$51,2,FALSE),"") | H24: =IFERROR(VLOOKUP(B24,'Reference Data 기준데이터'!$A$2:$J$5,3,FALSE),"") | I24: =IFERROR(H24+VLOOKUP(B24,'Reference Data 기준데이터'!$A$2:$J$5,7,FALSE),"") | J24: 46047 | K24: Approved | L24: =IFERROR(H24+VLOOKUP(B24,'Reference Data 기준데이터'!$A$2:$J$5,8,FALSE),"") | M24: 46086 | N24: =IFERROR(IF(ISNUMBER(SEARCH("Vehicle",F24)),MAX(H24+VLOOKUP(B24,'Reference Data 기준데이터'!$A$2:$J$5,9,FALSE),VLOOKUP(B24,'Reference Data 기준데이터'!$A$2:$J$5,4,FALSE)),H24+VLOOKUP(B24,'Reference Data 기준데이터'!$A$2:$J$5,9,FALSE)),"") | O24: 46101 | P24: =IFERROR(N24+VLOOKUP(E24,'Reference Data 기준데이터'!$A$8:$F$30,4,FALSE),"") | Q24: 46128 | R24: =IFERROR(MIN(H24+VLOOKUP(B24,'Reference Data 기준데이터'!$A$2:$J$5,10,FALSE),VLOOKUP(B24,'Reference Data 기준데이터'!$A$2:$J$5,6,FALSE)),"") | S24: 46130 | T24: 12-조건부승인검토 | U24: =IF(T24<>"",T24,IF(AND(S24<>"",Q24<>""),"11-결과등록완료",IF(AND(Q24<>"",S24=""),"10-시험완료",IF(AND(O24<>"",Q24=""),"09-시험준비중",IF(AND(M24<>"",O24=""),"08-단품준비완료",IF(K24="Approved","05-계획서승인",IF(K24="Revision Needed","04-검토중_조건불만족",IF(K24="Under Review","03-검토중_조건충족",IF(AND(J24<>"",K24=""),"02-계획서제출_미검토","01-계획서미제출"))))))))) | V24: =IFS(U24="01-계획서미제출",0,U24="02-계획서제출_미검토",0.05,U24="03-검토중_조건충족",0.1,U24="04-검토중_조건불만족",0.05,U24="05-계획서승인",0.2,U24="06-BIW생산중단",0.15,U24="07-생산완료_미인수",0.3,U24="08-단품준비완료",0.4,U24="09-시험준비중",0.55,U24="10-시험완료",0.85,U24="11-결과등록완료",1,U24="12-조건부승인검토",0.9,TRUE,0) | W24: =IF(S24<>"","-",IF(R24="","N/A",R24-TODAY())) | X24: =IF(U24="11-결과등록완료","DONE",IF(OR(U24="06-BIW생산중단",AND(U24="01-계획서미제출",I24<TODAY())),"CRITICAL",IF(OR(U24="04-검토중_조건불만족",U24="07-생산완료_미인수",U24="12-조건부승인검토"),"ACTION",IF(AND(ISNUMBER(W24),W24<=0),"OVERDUE",IF(AND(ISNUMBER(W24),W24<=14),"WARNING","ON TRACK"))))) | Y24: =IF(U24="11-결과등록완료","— 완료",IF(U24="01-계획서미제출",IF(I24<TODAY(),"계획서 제출 독촉 (OVERDUE)","계획서 제출 대기"),IF(U24="02-계획서제출_미검토","설계자: 계획서 검토 착수",IF(U24="03-검토중_조건충족","설계자: 승인 처리",IF(U24="04-검토중_조건불만족","보완 요청 → 협력사 재제출 독촉",IF(U24="05-계획서승인","시험편 준비 현황 확인",IF(U24="06-BIW생산중단","BIW 생산팀 확인 → 일정 재수립",IF(U24="07-생산완료_미인수","협력사 인수 독촉",IF(U24="08-단품준비완료","시험 일정 확인",IF(U24="09-시험준비중","시험 진행 모니터링",IF(U24="10-시험완료","결과 보고서 전산 등록 독촉",IF(U24="12-조건부승인검토","조건부 승인 여부 판단 → 관련부서 협의","—"))))))))))))
A25: 21 | B25: AE_PE | C25: Rear Seat Assy | D25: =IFERROR(VLOOKUP(C25,'Reference Data 기준데이터'!$E$8:$F$30,2,FALSE),"") | E25: 수하물 충격 시험 | F25: =IFERROR(VLOOKUP(E25,'Reference Data 기준데이터'!$A$8:$F$30,2,FALSE),"") | G25: =IFERROR(VLOOKUP(B25&"_"&C25,'Reference Data 기준데이터'!$A$33:$B$51,2,FALSE),"") | H25: =IFERROR(VLOOKUP(B25,'Reference Data 기준데이터'!$A$2:$J$5,3,FALSE),"") | I25: =IFERROR(H25+VLOOKUP(B25,'Reference Data 기준데이터'!$A$2:$J$5,7,FALSE),"") | J25: 46048 | K25: Approved | L25: =IFERROR(H25+VLOOKUP(B25,'Reference Data 기준데이터'!$A$2:$J$5,8,FALSE),"") | M25: 46087 | N25: =IFERROR(IF(ISNUMBER(SEARCH("Vehicle",F25)),MAX(H25+VLOOKUP(B25,'Reference Data 기준데이터'!$A$2:$J$5,9,FALSE),VLOOKUP(B25,'Reference Data 기준데이터'!$A$2:$J$5,4,FALSE)),H25+VLOOKUP(B25,'Reference Data 기준데이터'!$A$2:$J$5,9,FALSE)),"") | O25: 46102 | P25: =IFERROR(N25+VLOOKUP(E25,'Reference Data 기준데이터'!$A$8:$F$30,4,FALSE),"") | Q25: 46122 | R25: =IFERROR(MIN(H25+VLOOKUP(B25,'Reference Data 기준데이터'!$A$2:$J$5,10,FALSE),VLOOKUP(B25,'Reference Data 기준데이터'!$A$2:$J$5,6,FALSE)),"") | S25: 46131 | U25: =IF(T25<>"",T25,IF(AND(S25<>"",Q25<>""),"11-결과등록완료",IF(AND(Q25<>"",S25=""),"10-시험완료",IF(AND(O25<>"",Q25=""),"09-시험준비중",IF(AND(M25<>"",O25=""),"08-단품준비완료",IF(K25="Approved","05-계획서승인",IF(K25="Revision Needed","04-검토중_조건불만족",IF(K25="Under Review","03-검토중_조건충족",IF(AND(J25<>"",K25=""),"02-계획서제출_미검토","01-계획서미제출"))))))))) | V25: =IFS(U25="01-계획서미제출",0,U25="02-계획서제출_미검토",0.05,U25="03-검토중_조건충족",0.1,U25="04-검토중_조건불만족",0.05,U25="05-계획서승인",0.2,U25="06-BIW생산중단",0.15,U25="07-생산완료_미인수",0.3,U25="08-단품준비완료",0.4,U25="09-시험준비중",0.55,U25="10-시험완료",0.85,U25="11-결과등록완료",1,U25="12-조건부승인검토",0.9,TRUE,0) | W25: =IF(S25<>"","-",IF(R25="","N/A",R25-TODAY())) | X25: =IF(U25="11-결과등록완료","DONE",IF(OR(U25="06-BIW생산중단",AND(U25="01-계획서미제출",I25<TODAY())),"CRITICAL",IF(OR(U25="04-검토중_조건불만족",U25="07-생산완료_미인수",U25="12-조건부승인검토"),"ACTION",IF(AND(ISNUMBER(W25),W25<=0),"OVERDUE",IF(AND(ISNUMBER(W25),W25<=14),"WARNING","ON TRACK"))))) | Y25: =IF(U25="11-결과등록완료","— 완료",IF(U25="01-계획서미제출",IF(I25<TODAY(),"계획서 제출 독촉 (OVERDUE)","계획서 제출 대기"),IF(U25="02-계획서제출_미검토","설계자: 계획서 검토 착수",IF(U25="03-검토중_조건충족","설계자: 승인 처리",IF(U25="04-검토중_조건불만족","보완 요청 → 협력사 재제출 독촉",IF(U25="05-계획서승인","시험편 준비 현황 확인",IF(U25="06-BIW생산중단","BIW 생산팀 확인 → 일정 재수립",IF(U25="07-생산완료_미인수","협력사 인수 독촉",IF(U25="08-단품준비완료","시험 일정 확인",IF(U25="09-시험준비중","시험 진행 모니터링",IF(U25="10-시험완료","결과 보고서 전산 등록 독촉",IF(U25="12-조건부승인검토","조건부 승인 여부 판단 → 관련부서 협의","—"))))))))))))
A26: 22 | B26: AE_PE | C26: Rear Seat Assy | D26: =IFERROR(VLOOKUP(C26,'Reference Data 기준데이터'!$E$8:$F$30,2,FALSE),"") | E26: 외관 검사 | F26: =IFERROR(VLOOKUP(E26,'Reference Data 기준데이터'!$A$8:$F$30,2,FALSE),"") | G26: =IFERROR(VLOOKUP(B26&"_"&C26,'Reference Data 기준데이터'!$A$33:$B$51,2,FALSE),"") | H26: =IFERROR(VLOOKUP(B26,'Reference Data 기준데이터'!$A$2:$J$5,3,FALSE),"") | I26: =IFERROR(H26+VLOOKUP(B26,'Reference Data 기준데이터'!$A$2:$J$5,7,FALSE),"") | J26: 46049 | K26: Approved | L26: =IFERROR(H26+VLOOKUP(B26,'Reference Data 기준데이터'!$A$2:$J$5,8,FALSE),"") | M26: 46088 | N26: =IFERROR(IF(ISNUMBER(SEARCH("Vehicle",F26)),MAX(H26+VLOOKUP(B26,'Reference Data 기준데이터'!$A$2:$J$5,9,FALSE),VLOOKUP(B26,'Reference Data 기준데이터'!$A$2:$J$5,4,FALSE)),H26+VLOOKUP(B26,'Reference Data 기준데이터'!$A$2:$J$5,9,FALSE)),"") | O26: 46103 | P26: =IFERROR(N26+VLOOKUP(E26,'Reference Data 기준데이터'!$A$8:$F$30,4,FALSE),"") | Q26: 46123 | R26: =IFERROR(MIN(H26+VLOOKUP(B26,'Reference Data 기준데이터'!$A$2:$J$5,10,FALSE),VLOOKUP(B26,'Reference Data 기준데이터'!$A$2:$J$5,6,FALSE)),"") | S26: 46132 | U26: =IF(T26<>"",T26,IF(AND(S26<>"",Q26<>""),"11-결과등록완료",IF(AND(Q26<>"",S26=""),"10-시험완료",IF(AND(O26<>"",Q26=""),"09-시험준비중",IF(AND(M26<>"",O26=""),"08-단품준비완료",IF(K26="Approved","05-계획서승인",IF(K26="Revision Needed","04-검토중_조건불만족",IF(K26="Under Review","03-검토중_조건충족",IF(AND(J26<>"",K26=""),"02-계획서제출_미검토","01-계획서미제출"))))))))) | V26: =IFS(U26="01-계획서미제출",0,U26="02-계획서제출_미검토",0.05,U26="03-검토중_조건충족",0.1,U26="04-검토중_조건불만족",0.05,U26="05-계획서승인",0.2,U26="06-BIW생산중단",0.15,U26="07-생산완료_미인수",0.3,U26="08-단품준비완료",0.4,U26="09-시험준비중",0.55,U26="10-시험완료",0.85,U26="11-결과등록완료",1,U26="12-조건부승인검토",0.9,TRUE,0) | W26: =IF(S26<>"","-",IF(R26="","N/A",R26-TODAY())) | X26: =IF(U26="11-결과등록완료","DONE",IF(OR(U26="06-BIW생산중단",AND(U26="01-계획서미제출",I26<TODAY())),"CRITICAL",IF(OR(U26="04-검토중_조건불만족",U26="07-생산완료_미인수",U26="12-조건부승인검토"),"ACTION",IF(AND(ISNUMBER(W26),W26<=0),"OVERDUE",IF(AND(ISNUMBER(W26),W26<=14),"WARNING","ON TRACK"))))) | Y26: =IF(U26="11-결과등록완료","— 완료",IF(U26="01-계획서미제출",IF(I26<TODAY(),"계획서 제출 독촉 (OVERDUE)","계획서 제출 대기"),IF(U26="02-계획서제출_미검토","설계자: 계획서 검토 착수",IF(U26="03-검토중_조건충족","설계자: 승인 처리",IF(U26="04-검토중_조건불만족","보완 요청 → 협력사 재제출 독촉",IF(U26="05-계획서승인","시험편 준비 현황 확인",IF(U26="06-BIW생산중단","BIW 생산팀 확인 → 일정 재수립",IF(U26="07-생산완료_미인수","협력사 인수 독촉",IF(U26="08-단품준비완료","시험 일정 확인",IF(U26="09-시험준비중","시험 진행 모니터링",IF(U26="10-시험완료","결과 보고서 전산 등록 독촉",IF(U26="12-조건부승인검토","조건부 승인 여부 판단 → 관련부서 협의","—"))))))))))))
A27: 23 | B27: SU2i | C27: Center Console Assy | D27: =IFERROR(VLOOKUP(C27,'Reference Data 기준데이터'!$E$8:$F$30,2,FALSE),"") | E27: VOC 방출 시험 | F27: =IFERROR(VLOOKUP(E27,'Reference Data 기준데이터'!$A$8:$F$30,2,FALSE),"") | G27: =IFERROR(VLOOKUP(B27&"_"&C27,'Reference Data 기준데이터'!$A$33:$B$51,2,FALSE),"") | H27: =IFERROR(VLOOKUP(B27,'Reference Data 기준데이터'!$A$2:$J$5,3,FALSE),"") | I27: =IFERROR(H27+VLOOKUP(B27,'Reference Data 기준데이터'!$A$2:$J$5,7,FALSE),"") | L27: =IFERROR(H27+VLOOKUP(B27,'Reference Data 기준데이터'!$A$2:$J$5,8,FALSE),"") | N27: =IFERROR(IF(ISNUMBER(SEARCH("Vehicle",F27)),MAX(H27+VLOOKUP(B27,'Reference Data 기준데이터'!$A$2:$J$5,9,FALSE),VLOOKUP(B27,'Reference Data 기준데이터'!$A$2:$J$5,4,FALSE)),H27+VLOOKUP(B27,'Reference Data 기준데이터'!$A$2:$J$5,9,FALSE)),"") | P27: =IFERROR(N27+VLOOKUP(E27,'Reference Data 기준데이터'!$A$8:$F$30,4,FALSE),"") | R27: =IFERROR(MIN(H27+VLOOKUP(B27,'Reference Data 기준데이터'!$A$2:$J$5,10,FALSE),VLOOKUP(B27,'Reference Data 기준데이터'!$A$2:$J$5,6,FALSE)),"") | U27: =IF(T27<>"",T27,IF(AND(S27<>"",Q27<>""),"11-결과등록완료",IF(AND(Q27<>"",S27=""),"10-시험완료",IF(AND(O27<>"",Q27=""),"09-시험준비중",IF(AND(M27<>"",O27=""),"08-단품준비완료",IF(K27="Approved","05-계획서승인",IF(K27="Revision Needed","04-검토중_조건불만족",IF(K27="Under Review","03-검토중_조건충족",IF(AND(J27<>"",K27=""),"02-계획서제출_미검토","01-계획서미제출"))))))))) | V27: =IFS(U27="01-계획서미제출",0,U27="02-계획서제출_미검토",0.05,U27="03-검토중_조건충족",0.1,U27="04-검토중_조건불만족",0.05,U27="05-계획서승인",0.2,U27="06-BIW생산중단",0.15,U27="07-생산완료_미인수",0.3,U27="08-단품준비완료",0.4,U27="09-시험준비중",0.55,U27="10-시험완료",0.85,U27="11-결과등록완료",1,U27="12-조건부승인검토",0.9,TRUE,0) | W27: =IF(S27<>"","-",IF(R27="","N/A",R27-TODAY())) | X27: =IF(U27="11-결과등록완료","DONE",IF(OR(U27="06-BIW생산중단",AND(U27="01-계획서미제출",I27<TODAY())),"CRITICAL",IF(OR(U27="04-검토중_조건불만족",U27="07-생산완료_미인수",U27="12-조건부승인검토"),"ACTION",IF(AND(ISNUMBER(W27),W27<=0),"OVERDUE",IF(AND(ISNUMBER(W27),W27<=14),"WARNING","ON TRACK"))))) | Y27: =IF(U27="11-결과등록완료","— 완료",IF(U27="01-계획서미제출",IF(I27<TODAY(),"계획서 제출 독촉 (OVERDUE)","계획서 제출 대기"),IF(U27="02-계획서제출_미검토","설계자: 계획서 검토 착수",IF(U27="03-검토중_조건충족","설계자: 승인 처리",IF(U27="04-검토중_조건불만족","보완 요청 → 협력사 재제출 독촉",IF(U27="05-계획서승인","시험편 준비 현황 확인",IF(U27="06-BIW생산중단","BIW 생산팀 확인 → 일정 재수립",IF(U27="07-생산완료_미인수","협력사 인수 독촉",IF(U27="08-단품준비완료","시험 일정 확인",IF(U27="09-시험준비중","시험 진행 모니터링",IF(U27="10-시험완료","결과 보고서 전산 등록 독촉",IF(U27="12-조건부승인검토","조건부 승인 여부 판단 → 관련부서 협의","—"))))))))))))
