Workbook

Sheet Ref_PartTest
A1: System | B1: Part Name | C1: ES Spec No. | D1: Spec Title | E1: Cat | F1: Duration (days) | G1: 담당 협력사 | H1: 협력사 담당자 | I1: 주변부품 협력사 | J1: 주변부품 담당자 | K1: BIW 담당자 | L1: 예산처리
A2: Console | B2: 센터콘솔 | C2: ES 95400-05 | D2: EMC 시험 | E2: B | F2: 14 | G2: HS R&A | H2: 박민수 010-1234-0001 | I2: Seoyon | J2: 김태호 010-2345-0001 | K2: 이정우 010-3456-0001 | L2: ✓
A3: Console | B3: 센터콘솔 | C3: MS-300-57 | D3: VOC 방출 시험 | E3: C | F3: 14 | G3: HS R&A | H3: 박민수 010-1234-0001 | L3: ✓
A4: Console | B4: 센터콘솔 | C4: ES-90500 | D4: BSR 시험 | E4: A | F4: 14 | G4: HS R&A | H4: 박민수 010-1234-0001 | I4: Hyundai Mobis | J4: 장현석 010-2345-0002 | K4: 이정우 010-3456-0001 | L4: ✓
A5: Console | B5: 센터콘솔 | C5: ES-90101 | D5: 치수 검사 | E5: C | F5: 3 | G5: HS R&A | H5: 박민수 010-1234-0001 | L5: ✓
A6: Console | B6: 콘솔리드 | C6: FMVSS 302 | D6: 연소성 시험 | E6: C | F6: 3 | G6: HS R&A | H6: 박민수 010-1234-0001 | L6: ✓
A7: Console | B7: 콘솔리드 | C7: ES-92030 | D7: 힌지 내구 시험 | E7: C | F7: 10 | G7: HS R&A | H7: 박민수 010-1234-0001 | L7: 미처리
A8: Console | B8: 콘솔리드 | C8: ES-91300 | D8: 조작력 시험 | E8: C | F8: 5 | G8: HS R&A | H8: 박민수 010-1234-0001 | L8: ✓
A9: Cockpit | B9: 칵핏모듈 | C9: ES 95400-05 | D9: EMC 시험 | E9: A | F9: 14 | G9: Hyundai Mobis | H9: 장현석 010-2345-0002 | I9: HS R&A | J9: 박민수 010-1234-0001 | K9: 이정우 010-3456-0001 | L9: ✓
A10: Cockpit | B10: 칵핏모듈 | C10: ES-90500 | D10: BSR 시험 | E10: A | F10: 14 | G10: Hyundai Mobis | H10: 장현석 010-2345-0002 | I10: Faurecia | J10: David 010-2345-0003 | K10: 이정우 010-3456-0001 | L10: ✓
A11: Trim | B11: 도어트림(앞) | C11: MS-300-57 | D11: VOC 방출 시험 | E11: C | F11: 14 | G11: Faurecia | H11: David 010-2345-0003 | L11: ✓
A12: Trim | B12: 도어트림(앞) | C12: ES-90101 | D12: 치수 검사 | E12: B | F12: 3 | G12: Faurecia | H12: David 010-2345-0003 | I12: Seoyon | J12: 김태호 010-2345-0001 | L12: ✓
A13: Trim | B13: 도어트림(앞) | C13: ES-91300 | D13: 조작력 시험 | E13: B | F13: 5 | G13: Faurecia | H13: David 010-2345-0003 | I13: Seoyon | J13: 김태호 010-2345-0001 | L13: 미처리
A14: Trim | B14: 도어트림(뒤) | C14: MS-300-57 | D14: VOC 방출 시험 | E14: C | F14: 14 | G14: Faurecia | H14: David 010-2345-0003 | L14: ✓
A15: Trim | B15: 도어트림(뒤) | C15: ES-90101 | D15: 치수 검사 | E15: B | F15: 3 | G15: Faurecia | H15: David 010-2345-0003 | I15: Seoyon | J15: 김태호 010-2345-0001 | L15: ✓
A16: Trim | B16: 필러트림 A | C16: MS-300-34 | D16: 내후성 시험 | E16: C | F16: 21 | G16: Seoyon | H16: 김태호 010-2345-0001 | L16: ✓
A17: Trim | B17: 필러트림 B | C17: MS-300-34 | D17: 내후성 시험 | E17: C | F17: 21 | G17: Seoyon | H17: 김태호 010-2345-0001 | L17: ✓
A18: Trim | B18: 필러트림 C | C18: MS-300-34 | D18: 내후성 시험 | E18: C | F18: 21 | G18: Seoyon | H18: 김태호 010-2345-0001 | L18: ✓
A19: Trim | B19: 패키지트레이 | C19: ECE R17 | D19: 수하물 충격 시험 | E19: A | F19: 7 | G19: HS R&A | H19: 박민수 010-1234-0001 | I19: Faurecia | J19: David 010-2345-0003 | K19: 이정우 010-3456-0001 | L19: ✓
A20: Trim | B20: 헤드라이너 | C20: ES 80062 | D20: 포깅 시험 | E20: C | F20: 7 | G20: Seoyon E-Hwa | H20: 유동관 010-2345-0004 | L20: ✓
A21: Seat | B21: 시트(앞) | C21: ES-93100 | D21: 시트 내구 시험 | E21: A | F21: 21 | G21: Hyundai Transys | H21: 최진호 010-2345-0005 | I21: HS R&A | J21: 박민수 010-1234-0001 | K21: 이정우 010-3456-0001 | L21: ✓
A22: Seat | B22: 시트(앞) | C22: ES-93000 | D22: H-Point 검증 | E22: A | F22: 14 | G22: Hyundai Transys | H22: 최진호 010-2345-0005 | I22: Hyundai Mobis | J22: 장현석 010-2345-0002 | K22: 이정우 010-3456-0001 | L22: 미처리
A23: Seat | B23: 시트(앞) | C23: FMVSS 210 | D23: 안전벨트 앵커리지 | E23: A | F23: 14 | G23: Hyundai Transys | H23: 최진호 010-2345-0005 | I23: Hyundai Mobis | J23: 장현석 010-2345-0002 | K23: 이정우 010-3456-0001 | L23: ✓
A24: Seat | B24: 시트(뒤) | C24: ECE R14 | D24: ISOFIX 강도 시험 | E24: A | F24: 10 | G24: Hyundai Transys | H24: 최진호 010-2345-0005 | I24: Hyundai Mobis | J24: 장현석 010-2345-0002 | K24: 이정우 010-3456-0001 | L24: ✓
A25: Seat | B25: 시트(뒤) | C25: MS-300-55 | D25: 냄새 시험 | E25: C | F25: 5 | G25: Hyundai Transys | H25: 최진호 010-2345-0005 | L25: ✓

Sheet Ref_Schedule
A1: Milestone | B1: Date | C1: Note
A2: Vehicle Code | B2: EN_SUV
A3: Vehicle Name | B3: EN SUV
A4: T0 도면배포 | B4: 46054 | C4: 기준일
A5: 계획서 기한 | B5: =B4+14 | C5: T0 + 14일
A6: 부품준비 기한 | B6: =B4+49 | C6: T0 + 49일
A7: 시험시작 기한 | B7: =B4+63 | C7: T0 + 63일
A8: 성적서 기한 | B8: =B4+98 | C8: T0 + 98일
A9: Proto Build | B9: 46143
A10: Master Car | B10: 46218
A11: Test Deadline | B11: =B9-30 | C11: MC - 30일

Sheet Tracker
A1: ESIR Tracker — EN_SUV EN SUV
A3: No | B3: System | C3: Part Name | D3: ES Spec | E3: Spec Title | F3: Cat | G3: Supplier | H3: Budget | I3: Plan Due | J3: Parts Due | K3: Test Start Due | L3: Test End Due | M3: Report Due | N3: Plan ✓ | O3: Review Result | P3: Parts ✓ | Q3: Test Start ✓ | R3: Test End ✓ | S3: Report ✓ | T3: Status | U3: Progress | V3: D-Day | W3: Next Action
A4: 번호 | B4: 시스템 | C4: 파트명 | D4: ES 스펙 | E4: 시험명 | F4: 등급 | G4: 협력사 | H4: 예산 | I4: 계획서 기한 | J4: 부품준비 기한 | K4: 시험시작 기한 | L4: 시험완료 기한 | M4: 성적서 기한 | N4: 계획서 ✓ | O4: 검토 결과 | P4: 부품 ✓ | Q4: 시험시작 ✓ | R4: 시험완료 ✓ | S4: 성적서 ✓ | T4: 상태 | U4: 진행률 | V4: 잔여일 | W4: 다음조치
A5: 1 | B5: =INDEX('Ref_PartTest'!A:A,2) | C5: =INDEX('Ref_PartTest'!B:B,2) | D5: =INDEX('Ref_PartTest'!C:C,2) | E5: =INDEX('Ref_PartTest'!D:D,2) | F5: =INDEX('Ref_PartTest'!E:E,2) | G5: =INDEX('Ref_PartTest'!G:G,2) | H5: =INDEX('Ref_PartTest'!L:L,2) | I5: ='Ref_Schedule'!$B$5 | J5: ='Ref_Schedule'!$B$6 | K5: ='Ref_Schedule'!$B$7 | L5: =K5+INDEX('Ref_PartTest'!F:F,2) | M5: ='Ref_Schedule'!$B$8 | T5: =IF(AND(S5<>"",R5<>""),"11-결과등록완료",IF(AND(R5<>"",S5=""),"10-시험완료",IF(AND(Q5<>"",R5=""),"09-시험준비중",IF(AND(P5<>"",Q5=""),"08-단품준비완료",IF(O5="Approved","05-계획서승인",IF(O5="Revision Needed","04-검토중_보완",IF(O5="Under Review","03-검토중",IF(AND(N5<>"",O5=""),"02-제출_미검토","01-미제출")))))))) | U5: =IF(T5="11-결과등록완료",1,IF(T5="12-조건부승인",0.9,IF(T5="10-시험완료",0.85,IF(T5="09-시험준비중",0.55,IF(T5="08-단품준비완료",0.4,IF(T5="07-미인수",0.3,IF(T5="05-계획서승인",0.2,IF(T5="06-BIW중단",0.15,IF(T5="03-검토중",0.1,IF(T5="02-제출_미검토",0.05,IF(T5="04-검토중_보완",0.05,0))))))))))) | V5: =IF(S5<>"","—",IF(M5="","",M5-TODAY())) | W5: =IF(T5="11-결과등록완료","— 완료",IF(T5="01-미제출",IF(I5<TODAY(),"계획서 제출 독촉 (OVERDUE)","계획서 제출 대기"),IF(T5="02-제출_미검토","검토 착수 필요",IF(T5="03-검토중","승인 처리 대기",IF(T5="04-검토중_보완","보완 → 재제출 독촉",IF(T5="05-계획서승인","부품 준비 현황 확인",IF(T5="06-BIW중단","BIW팀 확인 → 일정 재수립",IF(T5="07-미인수","협력사 인수 독촉",IF(T5="08-단품준비완료","시험 일정 확인",IF(T5="09-시험준비중","시험 모니터링",IF(T5="10-시험완료","성적서 등록 독촉",IF(T5="12-조건부승인","조건부 승인 판단","—"))))))))))))
A6: 2 | B6: =INDEX('Ref_PartTest'!A:A,3) | C6: =INDEX('Ref_PartTest'!B:B,3) | D6: =INDEX('Ref_PartTest'!C:C,3) | E6: =INDEX('Ref_PartTest'!D:D,3) | F6: =INDEX('Ref_PartTest'!E:E,3) | G6: =INDEX('Ref_PartTest'!G:G,3) | H6: =INDEX('Ref_PartTest'!L:L,3) | I6: ='Ref_Schedule'!$B$5 | J6: ='Ref_Schedule'!$B$6 | K6: ='Ref_Schedule'!$B$7 | L6: =K6+INDEX('Ref_PartTest'!F:F,3) | M6: ='Ref_Schedule'!$B$8 | N6: ✓ | T6: =IF(AND(S6<>"",R6<>""),"11-결과등록완료",IF(AND(R6<>"",S6=""),"10-시험완료",IF(AND(Q6<>"",R6=""),"09-시험준비중",IF(AND(P6<>"",Q6=""),"08-단품준비완료",IF(O6="Approved","05-계획서승인",IF(O6="Revision Needed","04-검토중_보완",IF(O6="Under Review","03-검토중",IF(AND(N6<>"",O6=""),"02-제출_미검토","01-미제출")))))))) | U6: =IF(T6="11-결과등록완료",1,IF(T6="12-조건부승인",0.9,IF(T6="10-시험완료",0.85,IF(T6="09-시험준비중",0.55,IF(T6="08-단품준비완료",0.4,IF(T6="07-미인수",0.3,IF(T6="05-계획서승인",0.2,IF(T6="06-BIW중단",0.15,IF(T6="03-검토중",0.1,IF(T6="02-제출_미검토",0.05,IF(T6="04-검토중_보완",0.05,0))))))))))) | V6: =IF(S6<>"","—",IF(M6="","",M6-TODAY())) | W6: =IF(T6="11-결과등록완료","— 완료",IF(T6="01-미제출",IF(I6<TODAY(),"계획서 제출 독촉 (OVERDUE)","계획서 제출 대기"),IF(T6="02-제출_미검토","검토 착수 필요",IF(T6="03-검토중","승인 처리 대기",IF(T6="04-검토중_보완","보완 → 재제출 독촉",IF(T6="05-계획서승인","부품 준비 현황 확인",IF(T6="06-BIW중단","BIW팀 확인 → 일정 재수립",IF(T6="07-미인수","협력사 인수 독촉",IF(T6="08-단품준비완료","시험 일정 확인",IF(T6="09-시험준비중","시험 모니터링",IF(T6="10-시험완료","성적서 등록 독촉",IF(T6="12-조건부승인","조건부 승인 판단","—"))))))))))))
A7: 3 | B7: =INDEX('Ref_PartTest'!A:A,4) | C7: =INDEX('Ref_PartTest'!B:B,4) | D7: =INDEX('Ref_PartTest'!C:C,4) | E7: =INDEX('Ref_PartTest'!D:D,4) | F7: =INDEX('Ref_PartTest'!E:E,4) | G7: =INDEX('Ref_PartTest'!G:G,4) | H7: =INDEX('Ref_PartTest'!L:L,4) | I7: ='Ref_Schedule'!$B$5 | J7: ='Ref_Schedule'!$B$6 | K7: ='Ref_Schedule'!$B$7 | L7: =K7+INDEX('Ref_PartTest'!F:F,4) | M7: ='Ref_Schedule'!$B$8 | N7: ✓ | O7: Under Review | T7: =IF(AND(S7<>"",R7<>""),"11-결과등록완료",IF(AND(R7<>"",S7=""),"10-시험완료",IF(AND(Q7<>"",R7=""),"09-시험준비중",IF(AND(P7<>"",Q7=""),"08-단품준비완료",IF(O7="Approved","05-계획서승인",IF(O7="Revision Needed","04-검토중_보완",IF(O7="Under Review","03-검토중",IF(AND(N7<>"",O7=""),"02-제출_미검토","01-미제출")))))))) | U7: =IF(T7="11-결과등록완료",1,IF(T7="12-조건부승인",0.9,IF(T7="10-시험완료",0.85,IF(T7="09-시험준비중",0.55,IF(T7="08-단품준비완료",0.4,IF(T7="07-미인수",0.3,IF(T7="05-계획서승인",0.2,IF(T7="06-BIW중단",0.15,IF(T7="03-검토중",0.1,IF(T7="02-제출_미검토",0.05,IF(T7="04-검토중_보완",0.05,0))))))))))) | V7: =IF(S7<>"","—",IF(M7="","",M7-TODAY())) | W7: =IF(T7="11-결과등록완료","— 완료",IF(T7="01-미제출",IF(I7<TODAY(),"계획서 제출 독촉 (OVERDUE)","계획서 제출 대기"),IF(T7="02-제출_미검토","검토 착수 필요",IF(T7="03-검토중","승인 처리 대기",IF(T7="04-검토중_보완","보완 → 재제출 독촉",IF(T7="05-계획서승인","부품 준비 현황 확인",IF(T7="06-BIW중단","BIW팀 확인 → 일정 재수립",IF(T7="07-미인수","협력사 인수 독촉",IF(T7="08-단품준비완료","시험 일정 확인",IF(T7="09-시험준비중","시험 모니터링",IF(T7="10-시험완료","성적서 등록 독촉",IF(T7="12-조건부승인","조건부 승인 판단","—"))))))))))))
A8: 4 | B8: =INDEX('Ref_PartTest'!A:A,5) | C8: =INDEX('Ref_PartTest'!B:B,5) | D8: =INDEX('Ref_PartTest'!C:C,5) | E8: =INDEX('Ref_PartTest'!D:D,5) | F8: =INDEX('Ref_PartTest'!E:E,5) | G8: =INDEX('Ref_PartTest'!G:G,5) | H8: =INDEX('Ref_PartTest'!L:L,5) | I8: ='Ref_Schedule'!$B$5 | J8: ='Ref_Schedule'!$B$6 | K8: ='Ref_Schedule'!$B$7 | L8: =K8+INDEX('Ref_PartTest'!F:F,5) | M8: ='Ref_Schedule'!$B$8 | N8: ✓ | O8: Revision Needed | T8: =IF(AND(S8<>"",R8<>""),"11-결과등록완료",IF(AND(R8<>"",S8=""),"10-시험완료",IF(AND(Q8<>"",R8=""),"09-시험준비중",IF(AND(P8<>"",Q8=""),"08-단품준비완료",IF(O8="Approved","05-계획서승인",IF(O8="Revision Needed","04-검토중_보완",IF(O8="Under Review","03-검토중",IF(AND(N8<>"",O8=""),"02-제출_미검토","01-미제출")))))))) | U8: =IF(T8="11-결과등록완료",1,IF(T8="12-조건부승인",0.9,IF(T8="10-시험완료",0.85,IF(T8="09-시험준비중",0.55,IF(T8="08-단품준비완료",0.4,IF(T8="07-미인수",0.3,IF(T8="05-계획서승인",0.2,IF(T8="06-BIW중단",0.15,IF(T8="03-검토중",0.1,IF(T8="02-제출_미검토",0.05,IF(T8="04-검토중_보완",0.05,0))))))))))) | V8: =IF(S8<>"","—",IF(M8="","",M8-TODAY())) | W8: =IF(T8="11-결과등록완료","— 완료",IF(T8="01-미제출",IF(I8<TODAY(),"계획서 제출 독촉 (OVERDUE)","계획서 제출 대기"),IF(T8="02-제출_미검토","검토 착수 필요",IF(T8="03-검토중","승인 처리 대기",IF(T8="04-검토중_보완","보완 → 재제출 독촉",IF(T8="05-계획서승인","부품 준비 현황 확인",IF(T8="06-BIW중단","BIW팀 확인 → 일정 재수립",IF(T8="07-미인수","협력사 인수 독촉",IF(T8="08-단품준비완료","시험 일정 확인",IF(T8="09-시험준비중","시험 모니터링",IF(T8="10-시험완료","성적서 등록 독촉",IF(T8="12-조건부승인","조건부 승인 판단","—"))))))))))))
A9: 5 | B9: =INDEX('Ref_PartTest'!A:A,6) | C9: =INDEX('Ref_PartTest'!B:B,6) | D9: =INDEX('Ref_PartTest'!C:C,6) | E9: =INDEX('Ref_PartTest'!D:D,6) | F9: =INDEX('Ref_PartTest'!E:E,6) | G9: =INDEX('Ref_PartTest'!G:G,6) | H9: =INDEX('Ref_PartTest'!L:L,6) | I9: ='Ref_Schedule'!$B$5 | J9: ='Ref_Schedule'!$B$6 | K9: ='Ref_Schedule'!$B$7 | L9: =K9+INDEX('Ref_PartTest'!F:F,6) | M9: ='Ref_Schedule'!$B$8 | N9: ✓ | O9: Approved | T9: =IF(AND(S9<>"",R9<>""),"11-결과등록완료",IF(AND(R9<>"",S9=""),"10-시험완료",IF(AND(Q9<>"",R9=""),"09-시험준비중",IF(AND(P9<>"",Q9=""),"08-단품준비완료",IF(O9="Approved","05-계획서승인",IF(O9="Revision Needed","04-검토중_보완",IF(O9="Under Review","03-검토중",IF(AND(N9<>"",O9=""),"02-제출_미검토","01-미제출")))))))) | U9: =IF(T9="11-결과등록완료",1,IF(T9="12-조건부승인",0.9,IF(T9="10-시험완료",0.85,IF(T9="09-시험준비중",0.55,IF(T9="08-단품준비완료",0.4,IF(T9="07-미인수",0.3,IF(T9="05-계획서승인",0.2,IF(T9="06-BIW중단",0.15,IF(T9="03-검토중",0.1,IF(T9="02-제출_미검토",0.05,IF(T9="04-검토중_보완",0.05,0))))))))))) | V9: =IF(S9<>"","—",IF(M9="","",M9-TODAY())) | W9: =IF(T9="11-결과등록완료","— 완료",IF(T9="01-미제출",IF(I9<TODAY(),"계획서 제출 독촉 (OVERDUE)","계획서 제출 대기"),IF(T9="02-제출_미검토","검토 착수 필요",IF(T9="03-검토중","승인 처리 대기",IF(T9="04-검토중_보완","보완 → 재제출 독촉",IF(T9="05-계획서승인","부품 준비 현황 확인",IF(T9="06-BIW중단","BIW팀 확인 → 일정 재수립",IF(T9="07-미인수","협력사 인수 독촉",IF(T9="08-단품준비완료","시험 일정 확인",IF(T9="09-시험준비중","시험 모니터링",IF(T9="10-시험완료","성적서 등록 독촉",IF(T9="12-조건부승인","조건부 승인 판단","—"))))))))))))
A10: 6 | B10: =INDEX('Ref_PartTest'!A:A,7) | C10: =INDEX('Ref_PartTest'!B:B,7) | D10: =INDEX('Ref_PartTest'!C:C,7) | E10: =INDEX('Ref_PartTest'!D:D,7) | F10: =INDEX('Ref_PartTest'!E:E,7) | G10: =INDEX('Ref_PartTest'!G:G,7) | H10: =INDEX('Ref_PartTest'!L:L,7) | I10: ='Ref_Schedule'!$B$5 | J10: ='Ref_Schedule'!$B$6 | K10: ='Ref_Schedule'!$B$7 | L10: =K10+INDEX('Ref_PartTest'!F:F,7) | M10: ='Ref_Schedule'!$B$8 | N10: ✓ | O10: Approved | P10: ✓ | T10: =IF(AND(S10<>"",R10<>""),"11-결과등록완료",IF(AND(R10<>"",S10=""),"10-시험완료",IF(AND(Q10<>"",R10=""),"09-시험준비중",IF(AND(P10<>"",Q10=""),"08-단품준비완료",IF(O10="Approved","05-계획서승인",IF(O10="Revision Needed","04-검토중_보완",IF(O10="Under Review","03-검토중",IF(AND(N10<>"",O10=""),"02-제출_미검토","01-미제출")))))))) | U10: =IF(T10="11-결과등록완료",1,IF(T10="12-조건부승인",0.9,IF(T10="10-시험완료",0.85,IF(T10="09-시험준비중",0.55,IF(T10="08-단품준비완료",0.4,IF(T10="07-미인수",0.3,IF(T10="05-계획서승인",0.2,IF(T10="06-BIW중단",0.15,IF(T10="03-검토중",0.1,IF(T10="02-제출_미검토",0.05,IF(T10="04-검토중_보완",0.05,0))))))))))) | V10: =IF(S10<>"","—",IF(M10="","",M10-TODAY())) | W10: =IF(T10="11-결과등록완료","— 완료",IF(T10="01-미제출",IF(I10<TODAY(),"계획서 제출 독촉 (OVERDUE)","계획서 제출 대기"),IF(T10="02-제출_미검토","검토 착수 필요",IF(T10="03-검토중","승인 처리 대기",IF(T10="04-검토중_보완","보완 → 재제출 독촉",IF(T10="05-계획서승인","부품 준비 현황 확인",IF(T10="06-BIW중단","BIW팀 확인 → 일정 재수립",IF(T10="07-미인수","협력사 인수 독촉",IF(T10="08-단품준비완료","시험 일정 확인",IF(T10="09-시험준비중","시험 모니터링",IF(T10="10-시험완료","성적서 등록 독촉",IF(T10="12-조건부승인","조건부 승인 판단","—"))))))))))))
A11: 7 | B11: =INDEX('Ref_PartTest'!A:A,8) | C11: =INDEX('Ref_PartTest'!B:B,8) | D11: =INDEX('Ref_PartTest'!C:C,8) | E11: =INDEX('Ref_PartTest'!D:D,8) | F11: =INDEX('Ref_PartTest'!E:E,8) | G11: =INDEX('Ref_PartTest'!G:G,8) | H11: =INDEX('Ref_PartTest'!L:L,8) | I11: ='Ref_Schedule'!$B$5 | J11: ='Ref_Schedule'!$B$6 | K11: ='Ref_Schedule'!$B$7 | L11: =K11+INDEX('Ref_PartTest'!F:F,8) | M11: ='Ref_Schedule'!$B$8 | N11: ✓ | O11: Approved | P11: ✓ | Q11: ✓ | T11: =IF(AND(S11<>"",R11<>""),"11-결과등록완료",IF(AND(R11<>"",S11=""),"10-시험완료",IF(AND(Q11<>"",R11=""),"09-시험준비중",IF(AND(P11<>"",Q11=""),"08-단품준비완료",IF(O11="Approved","05-계획서승인",IF(O11="Revision Needed","04-검토중_보완",IF(O11="Under Review","03-검토중",IF(AND(N11<>"",O11=""),"02-제출_미검토","01-미제출")))))))) | U11: =IF(T11="11-결과등록완료",1,IF(T11="12-조건부승인",0.9,IF(T11="10-시험완료",0.85,IF(T11="09-시험준비중",0.55,IF(T11="08-단품준비완료",0.4,IF(T11="07-미인수",0.3,IF(T11="05-계획서승인",0.2,IF(T11="06-BIW중단",0.15,IF(T11="03-검토중",0.1,IF(T11="02-제출_미검토",0.05,IF(T11="04-검토중_보완",0.05,0))))))))))) | V11: =IF(S11<>"","—",IF(M11="","",M11-TODAY())) | W11: =IF(T11="11-결과등록완료","— 완료",IF(T11="01-미제출",IF(I11<TODAY(),"계획서 제출 독촉 (OVERDUE)","계획서 제출 대기"),IF(T11="02-제출_미검토","검토 착수 필요",IF(T11="03-검토중","승인 처리 대기",IF(T11="04-검토중_보완","보완 → 재제출 독촉",IF(T11="05-계획서승인","부품 준비 현황 확인",IF(T11="06-BIW중단","BIW팀 확인 → 일정 재수립",IF(T11="07-미인수","협력사 인수 독촉",IF(T11="08-단품준비완료","시험 일정 확인",IF(T11="09-시험준비중","시험 모니터링",IF(T11="10-시험완료","성적서 등록 독촉",IF(T11="12-조건부승인","조건부 승인 판단","—"))))))))))))
A12: 8 | B12: =INDEX('Ref_PartTest'!A:A,9) | C12: =INDEX('Ref_PartTest'!B:B,9) | D12: =INDEX('Ref_PartTest'!C:C,9) | E12: =INDEX('Ref_PartTest'!D:D,9) | F12: =INDEX('Ref_PartTest'!E:E,9) | G12: =INDEX('Ref_PartTest'!G:G,9) | H12: =INDEX('Ref_PartTest'!L:L,9) | I12: ='Ref_Schedule'!$B$5 | J12: ='Ref_Schedule'!$B$6 | K12: ='Ref_Schedule'!$B$7 | L12: =K12+INDEX('Ref_PartTest'!F:F,9) | M12: ='Ref_Schedule'!$B$8 | N12: ✓ | O12: Approved | P12: ✓ | Q12: ✓ | R12: ✓ | T12: =IF(AND(S12<>"",R12<>""),"11-결과등록완료",IF(AND(R12<>"",S12=""),"10-시험완료",IF(AND(Q12<>"",R12=""),"09-시험준비중",IF(AND(P12<>"",Q12=""),"08-단품준비완료",IF(O12="Approved","05-계획서승인",IF(O12="Revision Needed","04-검토중_보완",IF(O12="Under Review","03-검토중",IF(AND(N12<>"",O12=""),"02-제출_미검토","01-미제출")))))))) | U12: =IF(T12="11-결과등록완료",1,IF(T12="12-조건부승인",0.9,IF(T12="10-시험완료",0.85,IF(T12="09-시험준비중",0.55,IF(T12="08-단품준비완료",0.4,IF(T12="07-미인수",0.3,IF(T12="05-계획서승인",0.2,IF(T12="06-BIW중단",0.15,IF(T12="03-검토중",0.1,IF(T12="02-제출_미검토",0.05,IF(T12="04-검토중_보완",0.05,0))))))))))) | V12: =IF(S12<>"","—",IF(M12="","",M12-TODAY())) | W12: =IF(T12="11-결과등록완료","— 완료",IF(T12="01-미제출",IF(I12<TODAY(),"계획서 제출 독촉 (OVERDUE)","계획서 제출 대기"),IF(T12="02-제출_미검토","검토 착수 필요",IF(T12="03-검토중","승인 처리 대기",IF(T12="04-검토중_보완","보완 → 재제출 독촉",IF(T12="05-계획서승인","부품 준비 현황 확인",IF(T12="06-BIW중단","BIW팀 확인 → 일정 재수립",IF(T12="07-미인수","협력사 인수 독촉",IF(T12="08-단품준비완료","시험 일정 확인",IF(T12="09-시험준비중","시험 모니터링",IF(T12="10-시험완료","성적서 등록 독촉",IF(T12="12-조건부승인","조건부 승인 판단","—"))))))))))))
A13: 9 | B13: =INDEX('Ref_PartTest'!A:A,10) | C13: =INDEX('Ref_PartTest'!B:B,10) | D13: =INDEX('Ref_PartTest'!C:C,10) | E13: =INDEX('Ref_PartTest'!D:D,10) | F13: =INDEX('Ref_PartTest'!E:E,10) | G13: =INDEX('Ref_PartTest'!G:G,10) | H13: =INDEX('Ref_PartTest'!L:L,10) | I13: ='Ref_Schedule'!$B$5 | J13: ='Ref_Schedule'!$B$6 | K13: ='Ref_Schedule'!$B$7 | L13: =K13+INDEX('Ref_PartTest'!F:F,10) | M13: ='Ref_Schedule'!$B$8 | N13: ✓ | O13: Approved | P13: ✓ | Q13: ✓ | R13: ✓ | S13: ✓ | T13: =IF(AND(S13<>"",R13<>""),"11-결과등록완료",IF(AND(R13<>"",S13=""),"10-시험완료",IF(AND(Q13<>"",R13=""),"09-시험준비중",IF(AND(P13<>"",Q13=""),"08-단품준비완료",IF(O13="Approved","05-계획서승인",IF(O13="Revision Needed","04-검토중_보완",IF(O13="Under Review","03-검토중",IF(AND(N13<>"",O13=""),"02-제출_미검토","01-미제출")))))))) | U13: =IF(T13="11-결과등록완료",1,IF(T13="12-조건부승인",0.9,IF(T13="10-시험완료",0.85,IF(T13="09-시험준비중",0.55,IF(T13="08-단품준비완료",0.4,IF(T13="07-미인수",0.3,IF(T13="05-계획서승인",0.2,IF(T13="06-BIW중단",0.15,IF(T13="03-검토중",0.1,IF(T13="02-제출_미검토",0.05,IF(T13="04-검토중_보완",0.05,0))))))))))) | V13: =IF(S13<>"","—",IF(M13="","",M13-TODAY())) | W13: =IF(T13="11-결과등록완료","— 완료",IF(T13="01-미제출",IF(I13<TODAY(),"계획서 제출 독촉 (OVERDUE)","계획서 제출 대기"),IF(T13="02-제출_미검토","검토 착수 필요",IF(T13="03-검토중","승인 처리 대기",IF(T13="04-검토중_보완","보완 → 재제출 독촉",IF(T13="05-계획서승인","부품 준비 현황 확인",IF(T13="06-BIW중단","BIW팀 확인 → 일정 재수립",IF(T13="07-미인수","협력사 인수 독촉",IF(T13="08-단품준비완료","시험 일정 확인",IF(T13="09-시험준비중","시험 모니터링",IF(T13="10-시험완료","성적서 등록 독촉",IF(T13="12-조건부승인","조건부 승인 판단","—"))))))))))))
A14: 10 | B14: =INDEX('Ref_PartTest'!A:A,11) | C14: =INDEX('Ref_PartTest'!B:B,11) | D14: =INDEX('Ref_PartTest'!C:C,11) | E14: =INDEX('Ref_PartTest'!D:D,11) | F14: =INDEX('Ref_PartTest'!E:E,11) | G14: =INDEX('Ref_PartTest'!G:G,11) | H14: =INDEX('Ref_PartTest'!L:L,11) | I14: ='Ref_Schedule'!$B$5 | J14: ='Ref_Schedule'!$B$6 | K14: ='Ref_Schedule'!$B$7 | L14: =K14+INDEX('Ref_PartTest'!F:F,11) | M14: ='Ref_Schedule'!$B$8 | N14: ✓ | O14: Approved | P14: ✓ | T14: 06-BIW중단 | U14: =IF(T14="11-결과등록완료",1,IF(T14="12-조건부승인",0.9,IF(T14="10-시험완료",0.85,IF(T14="09-시험준비중",0.55,IF(T14="08-단품준비완료",0.4,IF(T14="07-미인수",0.3,IF(T14="05-계획서승인",0.2,IF(T14="06-BIW중단",0.15,IF(T14="03-검토중",0.1,IF(T14="02-제출_미검토",0.05,IF(T14="04-검토중_보완",0.05,0))))))))))) | V14: =IF(S14<>"","—",IF(M14="","",M14-TODAY())) | W14: =IF(T14="11-결과등록완료","— 완료",IF(T14="01-미제출",IF(I14<TODAY(),"계획서 제출 독촉 (OVERDUE)","계획서 제출 대기"),IF(T14="02-제출_미검토","검토 착수 필요",IF(T14="03-검토중","승인 처리 대기",IF(T14="04-검토중_보완","보완 → 재제출 독촉",IF(T14="05-계획서승인","부품 준비 현황 확인",IF(T14="06-BIW중단","BIW팀 확인 → 일정 재수립",IF(T14="07-미인수","협력사 인수 독촉",IF(T14="08-단품준비완료","시험 일정 확인",IF(T14="09-시험준비중","시험 모니터링",IF(T14="10-시험완료","성적서 등록 독촉",IF(T14="12-조건부승인","조건부 승인 판단","—"))))))))))))
A15: 11 | B15: =INDEX('Ref_PartTest'!A:A,12) | C15: =INDEX('Ref_PartTest'!B:B,12) | D15: =INDEX('Ref_PartTest'!C:C,12) | E15: =INDEX('Ref_PartTest'!D:D,12) | F15: =INDEX('Ref_PartTest'!E:E,12) | G15: =INDEX('Ref_PartTest'!G:G,12) | H15: =INDEX('Ref_PartTest'!L:L,12) | I15: ='Ref_Schedule'!$B$5 | J15: ='Ref_Schedule'!$B$6 | K15: ='Ref_Schedule'!$B$7 | L15: =K15+INDEX('Ref_PartTest'!F:F,12) | M15: ='Ref_Schedule'!$B$8 | N15: ✓ | O15: Approved | P15: ✓ | T15: 07-미인수 | U15: =IF(T15="11-결과등록완료",1,IF(T15="12-조건부승인",0.9,IF(T15="10-시험완료",0.85,IF(T15="09-시험준비중",0.55,IF(T15="08-단품준비완료",0.4,IF(T15="07-미인수",0.3,IF(T15="05-계획서승인",0.2,IF(T15="06-BIW중단",0.15,IF(T15="03-검토중",0.1,IF(T15="02-제출_미검토",0.05,IF(T15="04-검토중_보완",0.05,0))))))))))) | V15: =IF(S15<>"","—",IF(M15="","",M15-TODAY())) | W15: =IF(T15="11-결과등록완료","— 완료",IF(T15="01-미제출",IF(I15<TODAY(),"계획서 제출 독촉 (OVERDUE)","계획서 제출 대기"),IF(T15="02-제출_미검토","검토 착수 필요",IF(T15="03-검토중","승인 처리 대기",IF(T15="04-검토중_보완","보완 → 재제출 독촉",IF(T15="05-계획서승인","부품 준비 현황 확인",IF(T15="06-BIW중단","BIW팀 확인 → 일정 재수립",IF(T15="07-미인수","협력사 인수 독촉",IF(T15="08-단품준비완료","시험 일정 확인",IF(T15="09-시험준비중","시험 모니터링",IF(T15="10-시험완료","성적서 등록 독촉",IF(T15="12-조건부승인","조건부 승인 판단","—"))))))))))))
A16: 12 | B16: =INDEX('Ref_PartTest'!A:A,13) | C16: =INDEX('Ref_PartTest'!B:B,13) | D16: =INDEX('Ref_PartTest'!C:C,13) | E16: =INDEX('Ref_PartTest'!D:D,13) | F16: =INDEX('Ref_PartTest'!E:E,13) | G16: =INDEX('Ref_PartTest'!G:G,13) | H16: =INDEX('Ref_PartTest'!L:L,13) | I16: ='Ref_Schedule'!$B$5 | J16: ='Ref_Schedule'!$B$6 | K16: ='Ref_Schedule'!$B$7 | L16: =K16+INDEX('Ref_PartTest'!F:F,13) | M16: ='Ref_Schedule'!$B$8 | N16: ✓ | O16: Approved | P16: ✓ | Q16: ✓ | R16: ✓ | S16: ✓ | T16: 12-조건부승인 | U16: =IF(T16="11-결과등록완료",1,IF(T16="12-조건부승인",0.9,IF(T16="10-시험완료",0.85,IF(T16="09-시험준비중",0.55,IF(T16="08-단품준비완료",0.4,IF(T16="07-미인수",0.3,IF(T16="05-계획서승인",0.2,IF(T16="06-BIW중단",0.15,IF(T16="03-검토중",0.1,IF(T16="02-제출_미검토",0.05,IF(T16="04-검토중_보완",0.05,0))))))))))) | V16: =IF(S16<>"","—",IF(M16="","",M16-TODAY())) | W16: =IF(T16="11-결과등록완료","— 완료",IF(T16="01-미제출",IF(I16<TODAY(),"계획서 제출 독촉 (OVERDUE)","계획서 제출 대기"),IF(T16="02-제출_미검토","검토 착수 필요",IF(T16="03-검토중","승인 처리 대기",IF(T16="04-검토중_보완","보완 → 재제출 독촉",IF(T16="05-계획서승인","부품 준비 현황 확인",IF(T16="06-BIW중단","BIW팀 확인 → 일정 재수립",IF(T16="07-미인수","협력사 인수 독촉",IF(T16="08-단품준비완료","시험 일정 확인",IF(T16="09-시험준비중","시험 모니터링",IF(T16="10-시험완료","성적서 등록 독촉",IF(T16="12-조건부승인","조건부 승인 판단","—"))))))))))))
A17: 13 | B17: =INDEX('Ref_PartTest'!A:A,14) | C17: =INDEX('Ref_PartTest'!B:B,14) | D17: =INDEX('Ref_PartTest'!C:C,14) | E17: =INDEX('Ref_PartTest'!D:D,14) | F17: =INDEX('Ref_PartTest'!E:E,14) | G17: =INDEX('Ref_PartTest'!G:G,14) | H17: =INDEX('Ref_PartTest'!L:L,14) | I17: ='Ref_Schedule'!$B$5 | J17: ='Ref_Schedule'!$B$6 | K17: ='Ref_Schedule'!$B$7 | L17: =K17+INDEX('Ref_PartTest'!F:F,14) | M17: ='Ref_Schedule'!$B$8 | T17: =IF(AND(S17<>"",R17<>""),"11-결과등록완료",IF(AND(R17<>"",S17=""),"10-시험완료",IF(AND(Q17<>"",R17=""),"09-시험준비중",IF(AND(P17<>"",Q17=""),"08-단품준비완료",IF(O17="Approved","05-계획서승인",IF(O17="Revision Needed","04-검토중_보완",IF(O17="Under Review","03-검토중",IF(AND(N17<>"",O17=""),"02-제출_미검토","01-미제출")))))))) | U17: =IF(T17="11-결과등록완료",1,IF(T17="12-조건부승인",0.9,IF(T17="10-시험완료",0.85,IF(T17="09-시험준비중",0.55,IF(T17="08-단품준비완료",0.4,IF(T17="07-미인수",0.3,IF(T17="05-계획서승인",0.2,IF(T17="06-BIW중단",0.15,IF(T17="03-검토중",0.1,IF(T17="02-제출_미검토",0.05,IF(T17="04-검토중_보완",0.05,0))))))))))) | V17: =IF(S17<>"","—",IF(M17="","",M17-TODAY())) | W17: =IF(T17="11-결과등록완료","— 완료",IF(T17="01-미제출",IF(I17<TODAY(),"계획서 제출 독촉 (OVERDUE)","계획서 제출 대기"),IF(T17="02-제출_미검토","검토 착수 필요",IF(T17="03-검토중","승인 처리 대기",IF(T17="04-검토중_보완","보완 → 재제출 독촉",IF(T17="05-계획서승인","부품 준비 현황 확인",IF(T17="06-BIW중단","BIW팀 확인 → 일정 재수립",IF(T17="07-미인수","협력사 인수 독촉",IF(T17="08-단품준비완료","시험 일정 확인",IF(T17="09-시험준비중","시험 모니터링",IF(T17="10-시험완료","성적서 등록 독촉",IF(T17="12-조건부승인","조건부 승인 판단","—"))))))))))))
A18: 14 | B18: =INDEX('Ref_PartTest'!A:A,15) | C18: =INDEX('Ref_PartTest'!B:B,15) | D18: =INDEX('Ref_PartTest'!C:C,15) | E18: =INDEX('Ref_PartTest'!D:D,15) | F18: =INDEX('Ref_PartTest'!E:E,15) | G18: =INDEX('Ref_PartTest'!G:G,15) | H18: =INDEX('Ref_PartTest'!L:L,15) | I18: ='Ref_Schedule'!$B$5 | J18: ='Ref_Schedule'!$B$6 | K18: ='Ref_Schedule'!$B$7 | L18: =K18+INDEX('Ref_PartTest'!F:F,15) | M18: ='Ref_Schedule'!$B$8 | N18: ✓ | T18: =IF(AND(S18<>"",R18<>""),"11-결과등록완료",IF(AND(R18<>"",S18=""),"10-시험완료",IF(AND(Q18<>"",R18=""),"09-시험준비중",IF(AND(P18<>"",Q18=""),"08-단품준비완료",IF(O18="Approved","05-계획서승인",IF(O18="Revision Needed","04-검토중_보완",IF(O18="Under Review","03-검토중",IF(AND(N18<>"",O18=""),"02-제출_미검토","01-미제출")))))))) | U18: =IF(T18="11-결과등록완료",1,IF(T18="12-조건부승인",0.9,IF(T18="10-시험완료",0.85,IF(T18="09-시험준비중",0.55,IF(T18="08-단품준비완료",0.4,IF(T18="07-미인수",0.3,IF(T18="05-계획서승인",0.2,IF(T18="06-BIW중단",0.15,IF(T18="03-검토중",0.1,IF(T18="02-제출_미검토",0.05,IF(T18="04-검토중_보완",0.05,0))))))))))) | V18: =IF(S18<>"","—",IF(M18="","",M18-TODAY())) | W18: =IF(T18="11-결과등록완료","— 완료",IF(T18="01-미제출",IF(I18<TODAY(),"계획서 제출 독촉 (OVERDUE)","계획서 제출 대기"),IF(T18="02-제출_미검토","검토 착수 필요",IF(T18="03-검토중","승인 처리 대기",IF(T18="04-검토중_보완","보완 → 재제출 독촉",IF(T18="05-계획서승인","부품 준비 현황 확인",IF(T18="06-BIW중단","BIW팀 확인 → 일정 재수립",IF(T18="07-미인수","협력사 인수 독촉",IF(T18="08-단품준비완료","시험 일정 확인",IF(T18="09-시험준비중","시험 모니터링",IF(T18="10-시험완료","성적서 등록 독촉",IF(T18="12-조건부승인","조건부 승인 판단","—"))))))))))))
A19: 15 | B19: =INDEX('Ref_PartTest'!A:A,16) | C19: =INDEX('Ref_PartTest'!B:B,16) | D19: =INDEX('Ref_PartTest'!C:C,16) | E19: =INDEX('Ref_PartTest'!D:D,16) | F19: =INDEX('Ref_PartTest'!E:E,16) | G19: =INDEX('Ref_PartTest'!G:G,16) | H19: =INDEX('Ref_PartTest'!L:L,16) | I19: ='Ref_Schedule'!$B$5 | J19: ='Ref_Schedule'!$B$6 | K19: ='Ref_Schedule'!$B$7 | L19: =K19+INDEX('Ref_PartTest'!F:F,16) | M19: ='Ref_Schedule'!$B$8 | N19: ✓ | O19: Under Review | T19: =IF(AND(S19<>"",R19<>""),"11-결과등록완료",IF(AND(R19<>"",S19=""),"10-시험완료",IF(AND(Q19<>"",R19=""),"09-시험준비중",IF(AND(P19<>"",Q19=""),"08-단품준비완료",IF(O19="Approved","05-계획서승인",IF(O19="Revision Needed","04-검토중_보완",IF(O19="Under Review","03-검토중",IF(AND(N19<>"",O19=""),"02-제출_미검토","01-미제출")))))))) | U19: =IF(T19="11-결과등록완료",1,IF(T19="12-조건부승인",0.9,IF(T19="10-시험완료",0.85,IF(T19="09-시험준비중",0.55,IF(T19="08-단품준비완료",0.4,IF(T19="07-미인수",0.3,IF(T19="05-계획서승인",0.2,IF(T19="06-BIW중단",0.15,IF(T19="03-검토중",0.1,IF(T19="02-제출_미검토",0.05,IF(T19="04-검토중_보완",0.05,0))))))))))) | V19: =IF(S19<>"","—",IF(M19="","",M19-TODAY())) | W19: =IF(T19="11-결과등록완료","— 완료",IF(T19="01-미제출",IF(I19<TODAY(),"계획서 제출 독촉 (OVERDUE)","계획서 제출 대기"),IF(T19="02-제출_미검토","검토 착수 필요",IF(T19="03-검토중","승인 처리 대기",IF(T19="04-검토중_보완","보완 → 재제출 독촉",IF(T19="05-계획서승인","부품 준비 현황 확인",IF(T19="06-BIW중단","BIW팀 확인 → 일정 재수립",IF(T19="07-미인수","협력사 인수 독촉",IF(T19="08-단품준비완료","시험 일정 확인",IF(T19="09-시험준비중","시험 모니터링",IF(T19="10-시험완료","성적서 등록 독촉",IF(T19="12-조건부승인","조건부 승인 판단","—"))))))))))))
A20: 16 | B20: =INDEX('Ref_PartTest'!A:A,17) | C20: =INDEX('Ref_PartTest'!B:B,17) | D20: =INDEX('Ref_PartTest'!C:C,17) | E20: =INDEX('Ref_PartTest'!D:D,17) | F20: =INDEX('Ref_PartTest'!E:E,17) | G20: =INDEX('Ref_PartTest'!G:G,17) | H20: =INDEX('Ref_PartTest'!L:L,17) | I20: ='Ref_Schedule'!$B$5 | J20: ='Ref_Schedule'!$B$6 | K20: ='Ref_Schedule'!$B$7 | L20: =K20+INDEX('Ref_PartTest'!F:F,17) | M20: ='Ref_Schedule'!$B$8 | N20: ✓ | O20: Revision Needed | T20: =IF(AND(S20<>"",R20<>""),"11-결과등록완료",IF(AND(R20<>"",S20=""),"10-시험완료",IF(AND(Q20<>"",R20=""),"09-시험준비중",IF(AND(P20<>"",Q20=""),"08-단품준비완료",IF(O20="Approved","05-계획서승인",IF(O20="Revision Needed","04-검토중_보완",IF(O20="Under Review","03-검토중",IF(AND(N20<>"",O20=""),"02-제출_미검토","01-미제출")))))))) | U20: =IF(T20="11-결과등록완료",1,IF(T20="12-조건부승인",0.9,IF(T20="10-시험완료",0.85,IF(T20="09-시험준비중",0.55,IF(T20="08-단품준비완료",0.4,IF(T20="07-미인수",0.3,IF(T20="05-계획서승인",0.2,IF(T20="06-BIW중단",0.15,IF(T20="03-검토중",0.1,IF(T20="02-제출_미검토",0.05,IF(T20="04-검토중_보완",0.05,0))))))))))) | V20: =IF(S20<>"","—",IF(M20="","",M20-TODAY())) | W20: =IF(T20="11-결과등록완료","— 완료",IF(T20="01-미제출",IF(I20<TODAY(),"계획서 제출 독촉 (OVERDUE)","계획서 제출 대기"),IF(T20="02-제출_미검토","검토 착수 필요",IF(T20="03-검토중","승인 처리 대기",IF(T20="04-검토중_보완","보완 → 재제출 독촉",IF(T20="05-계획서승인","부품 준비 현황 확인",IF(T20="06-BIW중단","BIW팀 확인 → 일정 재수립",IF(T20="07-미인수","협력사 인수 독촉",IF(T20="08-단품준비완료","시험 일정 확인",IF(T20="09-시험준비중","시험 모니터링",IF(T20="10-시험완료","성적서 등록 독촉",IF(T20="12-조건부승인","조건부 승인 판단","—"))))))))))))
A21: 17 | B21: =INDEX('Ref_PartTest'!A:A,18) | C21: =INDEX('Ref_PartTest'!B:B,18) | D21: =INDEX('Ref_PartTest'!C:C,18) | E21: =INDEX('Ref_PartTest'!D:D,18) | F21: =INDEX('Ref_PartTest'!E:E,18) | G21: =INDEX('Ref_PartTest'!G:G,18) | H21: =INDEX('Ref_PartTest'!L:L,18) | I21: ='Ref_Schedule'!$B$5 | J21: ='Ref_Schedule'!$B$6 | K21: ='Ref_Schedule'!$B$7 | L21: =K21+INDEX('Ref_PartTest'!F:F,18) | M21: ='Ref_Schedule'!$B$8 | N21: ✓ | O21: Approved | T21: =IF(AND(S21<>"",R21<>""),"11-결과등록완료",IF(AND(R21<>"",S21=""),"10-시험완료",IF(AND(Q21<>"",R21=""),"09-시험준비중",IF(AND(P21<>"",Q21=""),"08-단품준비완료",IF(O21="Approved","05-계획서승인",IF(O21="Revision Needed","04-검토중_보완",IF(O21="Under Review","03-검토중",IF(AND(N21<>"",O21=""),"02-제출_미검토","01-미제출")))))))) | U21: =IF(T21="11-결과등록완료",1,IF(T21="12-조건부승인",0.9,IF(T21="10-시험완료",0.85,IF(T21="09-시험준비중",0.55,IF(T21="08-단품준비완료",0.4,IF(T21="07-미인수",0.3,IF(T21="05-계획서승인",0.2,IF(T21="06-BIW중단",0.15,IF(T21="03-검토중",0.1,IF(T21="02-제출_미검토",0.05,IF(T21="04-검토중_보완",0.05,0))))))))))) | V21: =IF(S21<>"","—",IF(M21="","",M21-TODAY())) | W21: =IF(T21="11-결과등록완료","— 완료",IF(T21="01-미제출",IF(I21<TODAY(),"계획서 제출 독촉 (OVERDUE)","계획서 제출 대기"),IF(T21="02-제출_미검토","검토 착수 필요",IF(T21="03-검토중","승인 처리 대기",IF(T21="04-검토중_보완","보완 → 재제출 독촉",IF(T21="05-계획서승인","부품 준비 현황 확인",IF(T21="06-BIW중단","BIW팀 확인 → 일정 재수립",IF(T21="07-미인수","협력사 인수 독촉",IF(T21="08-단품준비완료","시험 일정 확인",IF(T21="09-시험준비중","시험 모니터링",IF(T21="10-시험완료","성적서 등록 독촉",IF(T21="12-조건부승인","조건부 승인 판단","—"))))))))))))
A22: 18 | B22: =INDEX('Ref_PartTest'!A:A,19) | C22: =INDEX('Ref_PartTest'!B:B,19) | D22: =INDEX('Ref_PartTest'!C:C,19) | E22: =INDEX('Ref_PartTest'!D:D,19) | F22: =INDEX('Ref_PartTest'!E:E,19) | G22: =INDEX('Ref_PartTest'!G:G,19) | H22: =INDEX('Ref_PartTest'!L:L,19) | I22: ='Ref_Schedule'!$B$5 | J22: ='Ref_Schedule'!$B$6 | K22: ='Ref_Schedule'!$B$7 | L22: =K22+INDEX('Ref_PartTest'!F:F,19) | M22: ='Ref_Schedule'!$B$8 | N22: ✓ | O22: Approved | P22: ✓ | T22: =IF(AND(S22<>"",R22<>""),"11-결과등록완료",IF(AND(R22<>"",S22=""),"10-시험완료",IF(AND(Q22<>"",R22=""),"09-시험준비중",IF(AND(P22<>"",Q22=""),"08-단품준비완료",IF(O22="Approved","05-계획서승인",IF(O22="Revision Needed","04-검토중_보완",IF(O22="Under Review","03-검토중",IF(AND(N22<>"",O22=""),"02-제출_미검토","01-미제출")))))))) | U22: =IF(T22="11-결과등록완료",1,IF(T22="12-조건부승인",0.9,IF(T22="10-시험완료",0.85,IF(T22="09-시험준비중",0.55,IF(T22="08-단품준비완료",0.4,IF(T22="07-미인수",0.3,IF(T22="05-계획서승인",0.2,IF(T22="06-BIW중단",0.15,IF(T22="03-검토중",0.1,IF(T22="02-제출_미검토",0.05,IF(T22="04-검토중_보완",0.05,0))))))))))) | V22: =IF(S22<>"","—",IF(M22="","",M22-TODAY())) | W22: =IF(T22="11-결과등록완료","— 완료",IF(T22="01-미제출",IF(I22<TODAY(),"계획서 제출 독촉 (OVERDUE)","계획서 제출 대기"),IF(T22="02-제출_미검토","검토 착수 필요",IF(T22="03-검토중","승인 처리 대기",IF(T22="04-검토중_보완","보완 → 재제출 독촉",IF(T22="05-계획서승인","부품 준비 현황 확인",IF(T22="06-BIW중단","BIW팀 확인 → 일정 재수립",IF(T22="07-미인수","협력사 인수 독촉",IF(T22="08-단품준비완료","시험 일정 확인",IF(T22="09-시험준비중","시험 모니터링",IF(T22="10-시험완료","성적서 등록 독촉",IF(T22="12-조건부승인","조건부 승인 판단","—"))))))))))))
A23: 19 | B23: =INDEX('Ref_PartTest'!A:A,20) | C23: =INDEX('Ref_PartTest'!B:B,20) | D23: =INDEX('Ref_PartTest'!C:C,20) | E23: =INDEX('Ref_PartTest'!D:D,20) | F23: =INDEX('Ref_PartTest'!E:E,20) | G23: =INDEX('Ref_PartTest'!G:G,20) | H23: =INDEX('Ref_PartTest'!L:L,20) | I23: ='Ref_Schedule'!$B$5 | J23: ='Ref_Schedule'!$B$6 | K23: ='Ref_Schedule'!$B$7 | L23: =K23+INDEX('Ref_PartTest'!F:F,20) | M23: ='Ref_Schedule'!$B$8 | N23: ✓ | O23: Approved | P23: ✓ | Q23: ✓ | T23: =IF(AND(S23<>"",R23<>""),"11-결과등록완료",IF(AND(R23<>"",S23=""),"10-시험완료",IF(AND(Q23<>"",R23=""),"09-시험준비중",IF(AND(P23<>"",Q23=""),"08-단품준비완료",IF(O23="Approved","05-계획서승인",IF(O23="Revision Needed","04-검토중_보완",IF(O23="Under Review","03-검토중",IF(AND(N23<>"",O23=""),"02-제출_미검토","01-미제출")))))))) | U23: =IF(T23="11-결과등록완료",1,IF(T23="12-조건부승인",0.9,IF(T23="10-시험완료",0.85,IF(T23="09-시험준비중",0.55,IF(T23="08-단품준비완료",0.4,IF(T23="07-미인수",0.3,IF(T23="05-계획서승인",0.2,IF(T23="06-BIW중단",0.15,IF(T23="03-검토중",0.1,IF(T23="02-제출_미검토",0.05,IF(T23="04-검토중_보완",0.05,0))))))))))) | V23: =IF(S23<>"","—",IF(M23="","",M23-TODAY())) | W23: =IF(T23="11-결과등록완료","— 완료",IF(T23="01-미제출",IF(I23<TODAY(),"계획서 제출 독촉 (OVERDUE)","계획서 제출 대기"),IF(T23="02-제출_미검토","검토 착수 필요",IF(T23="03-검토중","승인 처리 대기",IF(T23="04-검토중_보완","보완 → 재제출 독촉",IF(T23="05-계획서승인","부품 준비 현황 확인",IF(T23="06-BIW중단","BIW팀 확인 → 일정 재수립",IF(T23="07-미인수","협력사 인수 독촉",IF(T23="08-단품준비완료","시험 일정 확인",IF(T23="09-시험준비중","시험 모니터링",IF(T23="10-시험완료","성적서 등록 독촉",IF(T23="12-조건부승인","조건부 승인 판단","—"))))))))))))
A24: 20 | B24: =INDEX('Ref_PartTest'!A:A,21) | C24: =INDEX('Ref_PartTest'!B:B,21) | D24: =INDEX('Ref_PartTest'!C:C,21) | E24: =INDEX('Ref_PartTest'!D:D,21) | F24: =INDEX('Ref_PartTest'!E:E,21) | G24: =INDEX('Ref_PartTest'!G:G,21) | H24: =INDEX('Ref_PartTest'!L:L,21) | I24: ='Ref_Schedule'!$B$5 | J24: ='Ref_Schedule'!$B$6 | K24: ='Ref_Schedule'!$B$7 | L24: =K24+INDEX('Ref_PartTest'!F:F,21) | M24: ='Ref_Schedule'!$B$8 | N24: ✓ | O24: Approved | P24: ✓ | Q24: ✓ | R24: ✓ | T24: =IF(AND(S24<>"",R24<>""),"11-결과등록완료",IF(AND(R24<>"",S24=""),"10-시험완료",IF(AND(Q24<>"",R24=""),"09-시험준비중",IF(AND(P24<>"",Q24=""),"08-단품준비완료",IF(O24="Approved","05-계획서승인",IF(O24="Revision Needed","04-검토중_보완",IF(O24="Under Review","03-검토중",IF(AND(N24<>"",O24=""),"02-제출_미검토","01-미제출")))))))) | U24: =IF(T24="11-결과등록완료",1,IF(T24="12-조건부승인",0.9,IF(T24="10-시험완료",0.85,IF(T24="09-시험준비중",0.55,IF(T24="08-단품준비완료",0.4,IF(T24="07-미인수",0.3,IF(T24="05-계획서승인",0.2,IF(T24="06-BIW중단",0.15,IF(T24="03-검토중",0.1,IF(T24="02-제출_미검토",0.05,IF(T24="04-검토중_보완",0.05,0))))))))))) | V24: =IF(S24<>"","—",IF(M24="","",M24-TODAY())) | W24: =IF(T24="11-결과등록완료","— 완료",IF(T24="01-미제출",IF(I24<TODAY(),"계획서 제출 독촉 (OVERDUE)","계획서 제출 대기"),IF(T24="02-제출_미검토","검토 착수 필요",IF(T24="03-검토중","승인 처리 대기",IF(T24="04-검토중_보완","보완 → 재제출 독촉",IF(T24="05-계획서승인","부품 준비 현황 확인",IF(T24="06-BIW중단","BIW팀 확인 → 일정 재수립",IF(T24="07-미인수","협력사 인수 독촉",IF(T24="08-단품준비완료","시험 일정 확인",IF(T24="09-시험준비중","시험 모니터링",IF(T24="10-시험완료","성적서 등록 독촉",IF(T24="12-조건부승인","조건부 승인 판단","—"))))))))))))
A25: 21 | B25: =INDEX('Ref_PartTest'!A:A,22) | C25: =INDEX('Ref_PartTest'!B:B,22) | D25: =INDEX('Ref_PartTest'!C:C,22) | E25: =INDEX('Ref_PartTest'!D:D,22) | F25: =INDEX('Ref_PartTest'!E:E,22) | G25: =INDEX('Ref_PartTest'!G:G,22) | H25: =INDEX('Ref_PartTest'!L:L,22) | I25: ='Ref_Schedule'!$B$5 | J25: ='Ref_Schedule'!$B$6 | K25: ='Ref_Schedule'!$B$7 | L25: =K25+INDEX('Ref_PartTest'!F:F,22) | M25: ='Ref_Schedule'!$B$8 | N25: ✓ | O25: Approved | P25: ✓ | Q25: ✓ | R25: ✓ | S25: ✓ | T25: =IF(AND(S25<>"",R25<>""),"11-결과등록완료",IF(AND(R25<>"",S25=""),"10-시험완료",IF(AND(Q25<>"",R25=""),"09-시험준비중",IF(AND(P25<>"",Q25=""),"08-단품준비완료",IF(O25="Approved","05-계획서승인",IF(O25="Revision Needed","04-검토중_보완",IF(O25="Under Review","03-검토중",IF(AND(N25<>"",O25=""),"02-제출_미검토","01-미제출")))))))) | U25: =IF(T25="11-결과등록완료",1,IF(T25="12-조건부승인",0.9,IF(T25="10-시험완료",0.85,IF(T25="09-시험준비중",0.55,IF(T25="08-단품준비완료",0.4,IF(T25="07-미인수",0.3,IF(T25="05-계획서승인",0.2,IF(T25="06-BIW중단",0.15,IF(T25="03-검토중",0.1,IF(T25="02-제출_미검토",0.05,IF(T25="04-검토중_보완",0.05,0))))))))))) | V25: =IF(S25<>"","—",IF(M25="","",M25-TODAY())) | W25: =IF(T25="11-결과등록완료","— 완료",IF(T25="01-미제출",IF(I25<TODAY(),"계획서 제출 독촉 (OVERDUE)","계획서 제출 대기"),IF(T25="02-제출_미검토","검토 착수 필요",IF(T25="03-검토중","승인 처리 대기",IF(T25="04-검토중_보완","보완 → 재제출 독촉",IF(T25="05-계획서승인","부품 준비 현황 확인",IF(T25="06-BIW중단","BIW팀 확인 → 일정 재수립",IF(T25="07-미인수","협력사 인수 독촉",IF(T25="08-단품준비완료","시험 일정 확인",IF(T25="09-시험준비중","시험 모니터링",IF(T25="10-시험완료","성적서 등록 독촉",IF(T25="12-조건부승인","조건부 승인 판단","—"))))))))))))
A26: 22 | B26: =INDEX('Ref_PartTest'!A:A,23) | C26: =INDEX('Ref_PartTest'!B:B,23) | D26: =INDEX('Ref_PartTest'!C:C,23) | E26: =INDEX('Ref_PartTest'!D:D,23) | F26: =INDEX('Ref_PartTest'!E:E,23) | G26: =INDEX('Ref_PartTest'!G:G,23) | H26: =INDEX('Ref_PartTest'!L:L,23) | I26: ='Ref_Schedule'!$B$5 | J26: ='Ref_Schedule'!$B$6 | K26: ='Ref_Schedule'!$B$7 | L26: =K26+INDEX('Ref_PartTest'!F:F,23) | M26: ='Ref_Schedule'!$B$8 | N26: ✓ | O26: Approved | P26: ✓ | T26: 06-BIW중단 | U26: =IF(T26="11-결과등록완료",1,IF(T26="12-조건부승인",0.9,IF(T26="10-시험완료",0.85,IF(T26="09-시험준비중",0.55,IF(T26="08-단품준비완료",0.4,IF(T26="07-미인수",0.3,IF(T26="05-계획서승인",0.2,IF(T26="06-BIW중단",0.15,IF(T26="03-검토중",0.1,IF(T26="02-제출_미검토",0.05,IF(T26="04-검토중_보완",0.05,0))))))))))) | V26: =IF(S26<>"","—",IF(M26="","",M26-TODAY())) | W26: =IF(T26="11-결과등록완료","— 완료",IF(T26="01-미제출",IF(I26<TODAY(),"계획서 제출 독촉 (OVERDUE)","계획서 제출 대기"),IF(T26="02-제출_미검토","검토 착수 필요",IF(T26="03-검토중","승인 처리 대기",IF(T26="04-검토중_보완","보완 → 재제출 독촉",IF(T26="05-계획서승인","부품 준비 현황 확인",IF(T26="06-BIW중단","BIW팀 확인 → 일정 재수립",IF(T26="07-미인수","협력사 인수 독촉",IF(T26="08-단품준비완료","시험 일정 확인",IF(T26="09-시험준비중","시험 모니터링",IF(T26="10-시험완료","성적서 등록 독촉",IF(T26="12-조건부승인","조건부 승인 판단","—"))))))))))))
A27: 23 | B27: =INDEX('Ref_PartTest'!A:A,24) | C27: =INDEX('Ref_PartTest'!B:B,24) | D27: =INDEX('Ref_PartTest'!C:C,24) | E27: =INDEX('Ref_PartTest'!D:D,24) | F27: =INDEX('Ref_PartTest'!E:E,24) | G27: =INDEX('Ref_PartTest'!G:G,24) | H27: =INDEX('Ref_PartTest'!L:L,24) | I27: ='Ref_Schedule'!$B$5 | J27: ='Ref_Schedule'!$B$6 | K27: ='Ref_Schedule'!$B$7 | L27: =K27+INDEX('Ref_PartTest'!F:F,24) | M27: ='Ref_Schedule'!$B$8 | N27: ✓ | O27: Approved | P27: ✓ | T27: 07-미인수 | U27: =IF(T27="11-결과등록완료",1,IF(T27="12-조건부승인",0.9,IF(T27="10-시험완료",0.85,IF(T27="09-시험준비중",0.55,IF(T27="08-단품준비완료",0.4,IF(T27="07-미인수",0.3,IF(T27="05-계획서승인",0.2,IF(T27="06-BIW중단",0.15,IF(T27="03-검토중",0.1,IF(T27="02-제출_미검토",0.05,IF(T27="04-검토중_보완",0.05,0))))))))))) | V27: =IF(S27<>"","—",IF(M27="","",M27-TODAY())) | W27: =IF(T27="11-결과등록완료","— 완료",IF(T27="01-미제출",IF(I27<TODAY(),"계획서 제출 독촉 (OVERDUE)","계획서 제출 대기"),IF(T27="02-제출_미검토","검토 착수 필요",IF(T27="03-검토중","승인 처리 대기",IF(T27="04-검토중_보완","보완 → 재제출 독촉",IF(T27="05-계획서승인","부품 준비 현황 확인",IF(T27="06-BIW중단","BIW팀 확인 → 일정 재수립",IF(T27="07-미인수","협력사 인수 독촉",IF(T27="08-단품준비완료","시험 일정 확인",IF(T27="09-시험준비중","시험 모니터링",IF(T27="10-시험완료","성적서 등록 독촉",IF(T27="12-조건부승인","조건부 승인 판단","—"))))))))))))
A28: 24 | B28: =INDEX('Ref_PartTest'!A:A,25) | C28: =INDEX('Ref_PartTest'!B:B,25) | D28: =INDEX('Ref_PartTest'!C:C,25) | E28: =INDEX('Ref_PartTest'!D:D,25) | F28: =INDEX('Ref_PartTest'!E:E,25) | G28: =INDEX('Ref_PartTest'!G:G,25) | H28: =INDEX('Ref_PartTest'!L:L,25) | I28: ='Ref_Schedule'!$B$5 | J28: ='Ref_Schedule'!$B$6 | K28: ='Ref_Schedule'!$B$7 | L28: =K28+INDEX('Ref_PartTest'!F:F,25) | M28: ='Ref_Schedule'!$B$8 | N28: ✓ | O28: Approved | P28: ✓ | Q28: ✓ | R28: ✓ | S28: ✓ | T28: 12-조건부승인 | U28: =IF(T28="11-결과등록완료",1,IF(T28="12-조건부승인",0.9,IF(T28="10-시험완료",0.85,IF(T28="09-시험준비중",0.55,IF(T28="08-단품준비완료",0.4,IF(T28="07-미인수",0.3,IF(T28="05-계획서승인",0.2,IF(T28="06-BIW중단",0.15,IF(T28="03-검토중",0.1,IF(T28="02-제출_미검토",0.05,IF(T28="04-검토중_보완",0.05,0))))))))))) | V28: =IF(S28<>"","—",IF(M28="","",M28-TODAY())) | W28: =IF(T28="11-결과등록완료","— 완료",IF(T28="01-미제출",IF(I28<TODAY(),"계획서 제출 독촉 (OVERDUE)","계획서 제출 대기"),IF(T28="02-제출_미검토","검토 착수 필요",IF(T28="03-검토중","승인 처리 대기",IF(T28="04-검토중_보완","보완 → 재제출 독촉",IF(T28="05-계획서승인","부품 준비 현황 확인",IF(T28="06-BIW중단","BIW팀 확인 → 일정 재수립",IF(T28="07-미인수","협력사 인수 독촉",IF(T28="08-단품준비완료","시험 일정 확인",IF(T28="09-시험준비중","시험 모니터링",IF(T28="10-시험완료","성적서 등록 독촉",IF(T28="12-조건부승인","조건부 승인 판단","—"))))))))))))
A29: =IF(C29="","",ROW()-4) | I29: =IF(C29="","",'Ref_Schedule'!$B$5) | J29: =IF(C29="","",'Ref_Schedule'!$B$6) | K29: =IF(C29="","",'Ref_Schedule'!$B$7) | L29: =IF(C29="","",K29+14) | M29: =IF(C29="","",'Ref_Schedule'!$B$8) | T29: =IF(C29="","",IF(AND(S29<>"",R29<>""),"11-결과등록완료",IF(AND(R29<>"",S29=""),"10-시험완료",IF(AND(Q29<>"",R29=""),"09-시험준비중",IF(AND(P29<>"",Q29=""),"08-단품준비완료",IF(O29="Approved","05-계획서승인",IF(O29="Revision Needed","04-검토중_보완",IF(O29="Under Review","03-검토중",IF(AND(N29<>"",O29=""),"02-제출_미검토","01-미제출"))))))))) | U29: =IF(C29="","",IF(T29="11-결과등록완료",1,IF(T29="12-조건부승인",0.9,IF(T29="10-시험완료",0.85,IF(T29="09-시험준비중",0.55,IF(T29="08-단품준비완료",0.4,IF(T29="07-미인수",0.3,IF(T29="05-계획서승인",0.2,IF(T29="06-BIW중단",0.15,IF(T29="03-검토중",0.1,IF(T29="02-제출_미검토",0.05,IF(T29="04-검토중_보완",0.05,0)))))))))))) | V29: =IF(C29="","",IF(S29<>"","—",IF(M29="","",M29-TODAY()))) | W29: =IF(C29="","",IF(T29="11-결과등록완료","— 완료",IF(T29="01-미제출",IF(I29<TODAY(),"계획서 제출 독촉","계획서 제출 대기"),IF(T29="02-제출_미검토","검토 착수 필요",IF(T29="03-검토중","승인 처리 대기",IF(T29="04-검토중_보완","보완 → 재제출 독촉",IF(T29="05-계획서승인","부품 준비 현황 확인",IF(T29="06-BIW중단","BIW팀 확인",IF(T29="07-미인수","협력사 인수 독촉",IF(T29="08-단품준비완료","시험 일정 확인",IF(T29="09-시험준비중","시험 모니터링",IF(T29="10-시험완료","성적서 등록 독촉",IF(T29="12-조건부승인","조건부 승인 판단","—")))))))))))))
A30: =IF(C30="","",ROW()-4) | I30: =IF(C30="","",'Ref_Schedule'!$B$5) | J30: =IF(C30="","",'Ref_Schedule'!$B$6) | K30: =IF(C30="","",'Ref_Schedule'!$B$7) | L30: =IF(C30="","",K30+14) | M30: =IF(C30="","",'Ref_Schedule'!$B$8) | T30: =IF(C30="","",IF(AND(S30<>"",R30<>""),"11-결과등록완료",IF(AND(R30<>"",S30=""),"10-시험완료",IF(AND(Q30<>"",R30=""),"09-시험준비중",IF(AND(P30<>"",Q30=""),"08-단품준비완료",IF(O30="Approved","05-계획서승인",IF(O30="Revision Needed","04-검토중_보완",IF(O30="Under Review","03-검토중",IF(AND(N30<>"",O30=""),"02-제출_미검토","01-미제출"))))))))) | U30: =IF(C30="","",IF(T30="11-결과등록완료",1,IF(T30="12-조건부승인",0.9,IF(T30="10-시험완료",0.85,IF(T30="09-시험준비중",0.55,IF(T30="08-단품준비완료",0.4,IF(T30="07-미인수",0.3,IF(T30="05-계획서승인",0.2,IF(T30="06-BIW중단",0.15,IF(T30="03-검토중",0.1,IF(T30="02-제출_미검토",0.05,IF(T30="04-검토중_보완",0.05,0)))))))))))) | V30: =IF(C30="","",IF(S30<>"","—",IF(M30="","",M30-TODAY()))) | W30: =IF(C30="","",IF(T30="11-결과등록완료","— 완료",IF(T30="01-미제출",IF(I30<TODAY(),"계획서 제출 독촉","계획서 제출 대기"),IF(T30="02-제출_미검토","검토 착수 필요",IF(T30="03-검토중","승인 처리 대기",IF(T30="04-검토중_보완","보완 → 재제출 독촉",IF(T30="05-계획서승인","부품 준비 현황 확인",IF(T30="06-BIW중단","BIW팀 확인",IF(T30="07-미인수","협력사 인수 독촉",IF(T30="08-단품준비완료","시험 일정 확인",IF(T30="09-시험준비중","시험 모니터링",IF(T30="10-시험완료","성적서 등록 독촉",IF(T30="12-조건부승인","조건부 승인 판단","—")))))))))))))
A31: =IF(C31="","",ROW()-4) | I31: =IF(C31="","",'Ref_Schedule'!$B$5) | J31: =IF(C31="","",'Ref_Schedule'!$B$6) | K31: =IF(C31="","",'Ref_Schedule'!$B$7) | L31: =IF(C31="","",K31+14) | M31: =IF(C31="","",'Ref_Schedule'!$B$8) | T31: =IF(C31="","",IF(AND(S31<>"",R31<>""),"11-결과등록완료",IF(AND(R31<>"",S31=""),"10-시험완료",IF(AND(Q31<>"",R31=""),"09-시험준비중",IF(AND(P31<>"",Q31=""),"08-단품준비완료",IF(O31="Approved","05-계획서승인",IF(O31="Revision Needed","04-검토중_보완",IF(O31="Under Review","03-검토중",IF(AND(N31<>"",O31=""),"02-제출_미검토","01-미제출"))))))))) | U31: =IF(C31="","",IF(T31="11-결과등록완료",1,IF(T31="12-조건부승인",0.9,IF(T31="10-시험완료",0.85,IF(T31="09-시험준비중",0.55,IF(T31="08-단품준비완료",0.4,IF(T31="07-미인수",0.3,IF(T31="05-계획서승인",0.2,IF(T31="06-BIW중단",0.15,IF(T31="03-검토중",0.1,IF(T31="02-제출_미검토",0.05,IF(T31="04-검토중_보완",0.05,0)))))))))))) | V31: =IF(C31="","",IF(S31<>"","—",IF(M31="","",M31-TODAY()))) | W31: =IF(C31="","",IF(T31="11-결과등록완료","— 완료",IF(T31="01-미제출",IF(I31<TODAY(),"계획서 제출 독촉","계획서 제출 대기"),IF(T31="02-제출_미검토","검토 착수 필요",IF(T31="03-검토중","승인 처리 대기",IF(T31="04-검토중_보완","보완 → 재제출 독촉",IF(T31="05-계획서승인","부품 준비 현황 확인",IF(T31="06-BIW중단","BIW팀 확인",IF(T31="07-미인수","협력사 인수 독촉",IF(T31="08-단품준비완료","시험 일정 확인",IF(T31="09-시험준비중","시험 모니터링",IF(T31="10-시험완료","성적서 등록 독촉",IF(T31="12-조건부승인","조건부 승인 판단","—")))))))))))))
A32: =IF(C32="","",ROW()-4) | I32: =IF(C32="","",'Ref_Schedule'!$B$5) | J32: =IF(C32="","",'Ref_Schedule'!$B$6) | K32: =IF(C32="","",'Ref_Schedule'!$B$7) | L32: =IF(C32="","",K32+14) | M32: =IF(C32="","",'Ref_Schedule'!$B$8) | T32: =IF(C32="","",IF(AND(S32<>"",R32<>""),"11-결과등록완료",IF(AND(R32<>"",S32=""),"10-시험완료",IF(AND(Q32<>"",R32=""),"09-시험준비중",IF(AND(P32<>"",Q32=""),"08-단품준비완료",IF(O32="Approved","05-계획서승인",IF(O32="Revision Needed","04-검토중_보완",IF(O32="Under Review","03-검토중",IF(AND(N32<>"",O32=""),"02-제출_미검토","01-미제출"))))))))) | U32: =IF(C32="","",IF(T32="11-결과등록완료",1,IF(T32="12-조건부승인",0.9,IF(T32="10-시험완료",0.85,IF(T32="09-시험준비중",0.55,IF(T32="08-단품준비완료",0.4,IF(T32="07-미인수",0.3,IF(T32="05-계획서승인",0.2,IF(T32="06-BIW중단",0.15,IF(T32="03-검토중",0.1,IF(T32="02-제출_미검토",0.05,IF(T32="04-검토중_보완",0.05,0)))))))))))) | V32: =IF(C32="","",IF(S32<>"","—",IF(M32="","",M32-TODAY()))) | W32: =IF(C32="","",IF(T32="11-결과등록완료","— 완료",IF(T32="01-미제출",IF(I32<TODAY(),"계획서 제출 독촉","계획서 제출 대기"),IF(T32="02-제출_미검토","검토 착수 필요",IF(T32="03-검토중","승인 처리 대기",IF(T32="04-검토중_보완","보완 → 재제출 독촉",IF(T32="05-계획서승인","부품 준비 현황 확인",IF(T32="06-BIW중단","BIW팀 확인",IF(T32="07-미인수","협력사 인수 독촉",IF(T32="08-단품준비완료","시험 일정 확인",IF(T32="09-시험준비중","시험 모니터링",IF(T32="10-시험완료","성적서 등록 독촉",IF(T32="12-조건부승인","조건부 승인 판단","—")))))))))))))
A33: =IF(C33="","",ROW()-4) | I33: =IF(C33="","",'Ref_Schedule'!$B$5) | J33: =IF(C33="","",'Ref_Schedule'!$B$6) | K33: =IF(C33="","",'Ref_Schedule'!$B$7) | L33: =IF(C33="","",K33+14) | M33: =IF(C33="","",'Ref_Schedule'!$B$8) | T33: =IF(C33="","",IF(AND(S33<>"",R33<>""),"11-결과등록완료",IF(AND(R33<>"",S33=""),"10-시험완료",IF(AND(Q33<>"",R33=""),"09-시험준비중",IF(AND(P33<>"",Q33=""),"08-단품준비완료",IF(O33="Approved","05-계획서승인",IF(O33="Revision Needed","04-검토중_보완",IF(O33="Under Review","03-검토중",IF(AND(N33<>"",O33=""),"02-제출_미검토","01-미제출"))))))))) | U33: =IF(C33="","",IF(T33="11-결과등록완료",1,IF(T33="12-조건부승인",0.9,IF(T33="10-시험완료",0.85,IF(T33="09-시험준비중",0.55,IF(T33="08-단품준비완료",0.4,IF(T33="07-미인수",0.3,IF(T33="05-계획서승인",0.2,IF(T33="06-BIW중단",0.15,IF(T33="03-검토중",0.1,IF(T33="02-제출_미검토",0.05,IF(T33="04-검토중_보완",0.05,0)))))))))))) | V33: =IF(C33="","",IF(S33<>"","—",IF(M33="","",M33-TODAY()))) | W33: =IF(C33="","",IF(T33="11-결과등록완료","— 완료",IF(T33="01-미제출",IF(I33<TODAY(),"계획서 제출 독촉","계획서 제출 대기"),IF(T33="02-제출_미검토","검토 착수 필요",IF(T33="03-검토중","승인 처리 대기",IF(T33="04-검토중_보완","보완 → 재제출 독촉",IF(T33="05-계획서승인","부품 준비 현황 확인",IF(T33="06-BIW중단","BIW팀 확인",IF(T33="07-미인수","협력사 인수 독촉",IF(T33="08-단품준비완료","시험 일정 확인",IF(T33="09-시험준비중","시험 모니터링",IF(T33="10-시험완료","성적서 등록 독촉",IF(T33="12-조건부승인","조건부 승인 판단","—")))))))))))))
A34: =IF(C34="","",ROW()-4) | I34: =IF(C34="","",'Ref_Schedule'!$B$5) | J34: =IF(C34="","",'Ref_Schedule'!$B$6) | K34: =IF(C34="","",'Ref_Schedule'!$B$7) | L34: =IF(C34="","",K34+14) | M34: =IF(C34="","",'Ref_Schedule'!$B$8) | T34: =IF(C34="","",IF(AND(S34<>"",R34<>""),"11-결과등록완료",IF(AND(R34<>"",S34=""),"10-시험완료",IF(AND(Q34<>"",R34=""),"09-시험준비중",IF(AND(P34<>"",Q34=""),"08-단품준비완료",IF(O34="Approved","05-계획서승인",IF(O34="Revision Needed","04-검토중_보완",IF(O34="Under Review","03-검토중",IF(AND(N34<>"",O34=""),"02-제출_미검토","01-미제출"))))))))) | U34: =IF(C34="","",IF(T34="11-결과등록완료",1,IF(T34="12-조건부승인",0.9,IF(T34="10-시험완료",0.85,IF(T34="09-시험준비중",0.55,IF(T34="08-단품준비완료",0.4,IF(T34="07-미인수",0.3,IF(T34="05-계획서승인",0.2,IF(T34="06-BIW중단",0.15,IF(T34="03-검토중",0.1,IF(T34="02-제출_미검토",0.05,IF(T34="04-검토중_보완",0.05,0)))))))))))) | V34: =IF(C34="","",IF(S34<>"","—",IF(M34="","",M34-TODAY()))) | W34: =IF(C34="","",IF(T34="11-결과등록완료","— 완료",IF(T34="01-미제출",IF(I34<TODAY(),"계획서 제출 독촉","계획서 제출 대기"),IF(T34="02-제출_미검토","검토 착수 필요",IF(T34="03-검토중","승인 처리 대기",IF(T34="04-검토중_보완","보완 → 재제출 독촉",IF(T34="05-계획서승인","부품 준비 현황 확인",IF(T34="06-BIW중단","BIW팀 확인",IF(T34="07-미인수","협력사 인수 독촉",IF(T34="08-단품준비완료","시험 일정 확인",IF(T34="09-시험준비중","시험 모니터링",IF(T34="10-시험완료","성적서 등록 독촉",IF(T34="12-조건부승인","조건부 승인 판단","—")))))))))))))
A35: =IF(C35="","",ROW()-4) | I35: =IF(C35="","",'Ref_Schedule'!$B$5) | J35: =IF(C35="","",'Ref_Schedule'!$B$6) | K35: =IF(C35="","",'Ref_Schedule'!$B$7) | L35: =IF(C35="","",K35+14) | M35: =IF(C35="","",'Ref_Schedule'!$B$8) | T35: =IF(C35="","",IF(AND(S35<>"",R35<>""),"11-결과등록완료",IF(AND(R35<>"",S35=""),"10-시험완료",IF(AND(Q35<>"",R35=""),"09-시험준비중",IF(AND(P35<>"",Q35=""),"08-단품준비완료",IF(O35="Approved","05-계획서승인",IF(O35="Revision Needed","04-검토중_보완",IF(O35="Under Review","03-검토중",IF(AND(N35<>"",O35=""),"02-제출_미검토","01-미제출"))))))))) | U35: =IF(C35="","",IF(T35="11-결과등록완료",1,IF(T35="12-조건부승인",0.9,IF(T35="10-시험완료",0.85,IF(T35="09-시험준비중",0.55,IF(T35="08-단품준비완료",0.4,IF(T35="07-미인수",0.3,IF(T35="05-계획서승인",0.2,IF(T35="06-BIW중단",0.15,IF(T35="03-검토중",0.1,IF(T35="02-제출_미검토",0.05,IF(T35="04-검토중_보완",0.05,0)))))))))))) | V35: =IF(C35="","",IF(S35<>"","—",IF(M35="","",M35-TODAY()))) | W35: =IF(C35="","",IF(T35="11-결과등록완료","— 완료",IF(T35="01-미제출",IF(I35<TODAY(),"계획서 제출 독촉","계획서 제출 대기"),IF(T35="02-제출_미검토","검토 착수 필요",IF(T35="03-검토중","승인 처리 대기",IF(T35="04-검토중_보완","보완 → 재제출 독촉",IF(T35="05-계획서승인","부품 준비 현황 확인",IF(T35="06-BIW중단","BIW팀 확인",IF(T35="07-미인수","협력사 인수 독촉",IF(T35="08-단품준비완료","시험 일정 확인",IF(T35="09-시험준비중","시험 모니터링",IF(T35="10-시험완료","성적서 등록 독촉",IF(T35="12-조건부승인","조건부 승인 판단","—")))))))))))))
A36: =IF(C36="","",ROW()-4) | I36: =IF(C36="","",'Ref_Schedule'!$B$5) | J36: =IF(C36="","",'Ref_Schedule'!$B$6) | K36: =IF(C36="","",'Ref_Schedule'!$B$7) | L36: =IF(C36="","",K36+14) | M36: =IF(C36="","",'Ref_Schedule'!$B$8) | T36: =IF(C36="","",IF(AND(S36<>"",R36<>""),"11-결과등록완료",IF(AND(R36<>"",S36=""),"10-시험완료",IF(AND(Q36<>"",R36=""),"09-시험준비중",IF(AND(P36<>"",Q36=""),"08-단품준비완료",IF(O36="Approved","05-계획서승인",IF(O36="Revision Needed","04-검토중_보완",IF(O36="Under Review","03-검토중",IF(AND(N36<>"",O36=""),"02-제출_미검토","01-미제출"))))))))) | U36: =IF(C36="","",IF(T36="11-결과등록완료",1,IF(T36="12-조건부승인",0.9,IF(T36="10-시험완료",0.85,IF(T36="09-시험준비중",0.55,IF(T36="08-단품준비완료",0.4,IF(T36="07-미인수",0.3,IF(T36="05-계획서승인",0.2,IF(T36="06-BIW중단",0.15,IF(T36="03-검토중",0.1,IF(T36="02-제출_미검토",0.05,IF(T36="04-검토중_보완",0.05,0)))))))))))) | V36: =IF(C36="","",IF(S36<>"","—",IF(M36="","",M36-TODAY()))) | W36: =IF(C36="","",IF(T36="11-결과등록완료","— 완료",IF(T36="01-미제출",IF(I36<TODAY(),"계획서 제출 독촉","계획서 제출 대기"),IF(T36="02-제출_미검토","검토 착수 필요",IF(T36="03-검토중","승인 처리 대기",IF(T36="04-검토중_보완","보완 → 재제출 독촉",IF(T36="05-계획서승인","부품 준비 현황 확인",IF(T36="06-BIW중단","BIW팀 확인",IF(T36="07-미인수","협력사 인수 독촉",IF(T36="08-단품준비완료","시험 일정 확인",IF(T36="09-시험준비중","시험 모니터링",IF(T36="10-시험완료","성적서 등록 독촉",IF(T36="12-조건부승인","조건부 승인 판단","—")))))))))))))
A37: =IF(C37="","",ROW()-4) | I37: =IF(C37="","",'Ref_Schedule'!$B$5) | J37: =IF(C37="","",'Ref_Schedule'!$B$6) | K37: =IF(C37="","",'Ref_Schedule'!$B$7) | L37: =IF(C37="","",K37+14) | M37: =IF(C37="","",'Ref_Schedule'!$B$8) | T37: =IF(C37="","",IF(AND(S37<>"",R37<>""),"11-결과등록완료",IF(AND(R37<>"",S37=""),"10-시험완료",IF(AND(Q37<>"",R37=""),"09-시험준비중",IF(AND(P37<>"",Q37=""),"08-단품준비완료",IF(O37="Approved","05-계획서승인",IF(O37="Revision Needed","04-검토중_보완",IF(O37="Under Review","03-검토중",IF(AND(N37<>"",O37=""),"02-제출_미검토","01-미제출"))))))))) | U37: =IF(C37="","",IF(T37="11-결과등록완료",1,IF(T37="12-조건부승인",0.9,IF(T37="10-시험완료",0.85,IF(T37="09-시험준비중",0.55,IF(T37="08-단품준비완료",0.4,IF(T37="07-미인수",0.3,IF(T37="05-계획서승인",0.2,IF(T37="06-BIW중단",0.15,IF(T37="03-검토중",0.1,IF(T37="02-제출_미검토",0.05,IF(T37="04-검토중_보완",0.05,0)))))))))))) | V37: =IF(C37="","",IF(S37<>"","—",IF(M37="","",M37-TODAY()))) | W37: =IF(C37="","",IF(T37="11-결과등록완료","— 완료",IF(T37="01-미제출",IF(I37<TODAY(),"계획서 제출 독촉","계획서 제출 대기"),IF(T37="02-제출_미검토","검토 착수 필요",IF(T37="03-검토중","승인 처리 대기",IF(T37="04-검토중_보완","보완 → 재제출 독촉",IF(T37="05-계획서승인","부품 준비 현황 확인",IF(T37="06-BIW중단","BIW팀 확인",IF(T37="07-미인수","협력사 인수 독촉",IF(T37="08-단품준비완료","시험 일정 확인",IF(T37="09-시험준비중","시험 모니터링",IF(T37="10-시험완료","성적서 등록 독촉",IF(T37="12-조건부승인","조건부 승인 판단","—")))))))))))))
A38: =IF(C38="","",ROW()-4) | I38: =IF(C38="","",'Ref_Schedule'!$B$5) | J38: =IF(C38="","",'Ref_Schedule'!$B$6) | K38: =IF(C38="","",'Ref_Schedule'!$B$7) | L38: =IF(C38="","",K38+14) | M38: =IF(C38="","",'Ref_Schedule'!$B$8) | T38: =IF(C38="","",IF(AND(S38<>"",R38<>""),"11-결과등록완료",IF(AND(R38<>"",S38=""),"10-시험완료",IF(AND(Q38<>"",R38=""),"09-시험준비중",IF(AND(P38<>"",Q38=""),"08-단품준비완료",IF(O38="Approved","05-계획서승인",IF(O38="Revision Needed","04-검토중_보완",IF(O38="Under Review","03-검토중",IF(AND(N38<>"",O38=""),"02-제출_미검토","01-미제출"))))))))) | U38: =IF(C38="","",IF(T38="11-결과등록완료",1,IF(T38="12-조건부승인",0.9,IF(T38="10-시험완료",0.85,IF(T38="09-시험준비중",0.55,IF(T38="08-단품준비완료",0.4,IF(T38="07-미인수",0.3,IF(T38="05-계획서승인",0.2,IF(T38="06-BIW중단",0.15,IF(T38="03-검토중",0.1,IF(T38="02-제출_미검토",0.05,IF(T38="04-검토중_보완",0.05,0)))))))))))) | V38: =IF(C38="","",IF(S38<>"","—",IF(M38="","",M38-TODAY()))) | W38: =IF(C38="","",IF(T38="11-결과등록완료","— 완료",IF(T38="01-미제출",IF(I38<TODAY(),"계획서 제출 독촉","계획서 제출 대기"),IF(T38="02-제출_미검토","검토 착수 필요",IF(T38="03-검토중","승인 처리 대기",IF(T38="04-검토중_보완","보완 → 재제출 독촉",IF(T38="05-계획서승인","부품 준비 현황 확인",IF(T38="06-BIW중단","BIW팀 확인",IF(T38="07-미인수","협력사 인수 독촉",IF(T38="08-단품준비완료","시험 일정 확인",IF(T38="09-시험준비중","시험 모니터링",IF(T38="10-시험완료","성적서 등록 독촉",IF(T38="12-조건부승인","조건부 승인 판단","—")))))))))))))
A39: =IF(C39="","",ROW()-4) | I39: =IF(C39="","",'Ref_Schedule'!$B$5) | J39: =IF(C39="","",'Ref_Schedule'!$B$6) | K39: =IF(C39="","",'Ref_Schedule'!$B$7) | L39: =IF(C39="","",K39+14) | M39: =IF(C39="","",'Ref_Schedule'!$B$8) | T39: =IF(C39="","",IF(AND(S39<>"",R39<>""),"11-결과등록완료",IF(AND(R39<>"",S39=""),"10-시험완료",IF(AND(Q39<>"",R39=""),"09-시험준비중",IF(AND(P39<>"",Q39=""),"08-단품준비완료",IF(O39="Approved","05-계획서승인",IF(O39="Revision Needed","04-검토중_보완",IF(O39="Under Review","03-검토중",IF(AND(N39<>"",O39=""),"02-제출_미검토","01-미제출"))))))))) | U39: =IF(C39="","",IF(T39="11-결과등록완료",1,IF(T39="12-조건부승인",0.9,IF(T39="10-시험완료",0.85,IF(T39="09-시험준비중",0.55,IF(T39="08-단품준비완료",0.4,IF(T39="07-미인수",0.3,IF(T39="05-계획서승인",0.2,IF(T39="06-BIW중단",0.15,IF(T39="03-검토중",0.1,IF(T39="02-제출_미검토",0.05,IF(T39="04-검토중_보완",0.05,0)))))))))))) | V39: =IF(C39="","",IF(S39<>"","—",IF(M39="","",M39-TODAY()))) | W39: =IF(C39="","",IF(T39="11-결과등록완료","— 완료",IF(T39="01-미제출",IF(I39<TODAY(),"계획서 제출 독촉","계획서 제출 대기"),IF(T39="02-제출_미검토","검토 착수 필요",IF(T39="03-검토중","승인 처리 대기",IF(T39="04-검토중_보완","보완 → 재제출 독촉",IF(T39="05-계획서승인","부품 준비 현황 확인",IF(T39="06-BIW중단","BIW팀 확인",IF(T39="07-미인수","협력사 인수 독촉",IF(T39="08-단품준비완료","시험 일정 확인",IF(T39="09-시험준비중","시험 모니터링",IF(T39="10-시험완료","성적서 등록 독촉",IF(T39="12-조건부승인","조건부 승인 판단","—")))))))))))))
A40: =IF(C40="","",ROW()-4) | I40: =IF(C40="","",'Ref_Schedule'!$B$5) | J40: =IF(C40="","",'Ref_Schedule'!$B$6) | K40: =IF(C40="","",'Ref_Schedule'!$B$7) | L40: =IF(C40="","",K40+14) | M40: =IF(C40="","",'Ref_Schedule'!$B$8) | T40: =IF(C40="","",IF(AND(S40<>"",R40<>""),"11-결과등록완료",IF(AND(R40<>"",S40=""),"10-시험완료",IF(AND(Q40<>"",R40=""),"09-시험준비중",IF(AND(P40<>"",Q40=""),"08-단품준비완료",IF(O40="Approved","05-계획서승인",IF(O40="Revision Needed","04-검토중_보완",IF(O40="Under Review","03-검토중",IF(AND(N40<>"",O40=""),"02-제출_미검토","01-미제출"))))))))) | U40: =IF(C40="","",IF(T40="11-결과등록완료",1,IF(T40="12-조건부승인",0.9,IF(T40="10-시험완료",0.85,IF(T40="09-시험준비중",0.55,IF(T40="08-단품준비완료",0.4,IF(T40="07-미인수",0.3,IF(T40="05-계획서승인",0.2,IF(T40="06-BIW중단",0.15,IF(T40="03-검토중",0.1,IF(T40="02-제출_미검토",0.05,IF(T40="04-검토중_보완",0.05,0)))))))))))) | V40: =IF(C40="","",IF(S40<>"","—",IF(M40="","",M40-TODAY()))) | W40: =IF(C40="","",IF(T40="11-결과등록완료","— 완료",IF(T40="01-미제출",IF(I40<TODAY(),"계획서 제출 독촉","계획서 제출 대기"),IF(T40="02-제출_미검토","검토 착수 필요",IF(T40="03-검토중","승인 처리 대기",IF(T40="04-검토중_보완","보완 → 재제출 독촉",IF(T40="05-계획서승인","부품 준비 현황 확인",IF(T40="06-BIW중단","BIW팀 확인",IF(T40="07-미인수","협력사 인수 독촉",IF(T40="08-단품준비완료","시험 일정 확인",IF(T40="09-시험준비중","시험 모니터링",IF(T40="10-시험완료","성적서 등록 독촉",IF(T40="12-조건부승인","조건부 승인 판단","—")))))))))))))
... A80: =IF(C80="","",ROW()-4) | I80: =IF(C80="","",'Ref_Schedule'!$B$5) | J80: =IF(C80="","",'Ref_Schedule'!$B$6) | K80: =IF(C80="","",'Ref_Schedule'!$B$7) | L80: =IF(C80="","",K80+14) | M80: =IF(C80="","",'Ref_Schedule'!$B$8) | T80: =IF(C80="","",IF(AND(S80<>"",R80<>""),"11-결과등록완료",IF(AND(R80<>"",S80=""),"10-시험완료",IF(AND(Q80<>"",R80=""),"09-시험준비중",IF(AND(P80<>"",Q80=""),"08-단품준비완료",IF(O80="Approved","05-계획서승인",IF(O80="Revision Needed","04-검토중_보완",IF(O80="Under Review","03-검토중",IF(AND(N80<>"",O80=""),"02-제출_미검토","01-미제출"))))))))) | U80: =IF(C80="","",IF(T80="11-결과등록완료",1,IF(T80="12-조건부승인",0.9,IF(T80="10-시험완료",0.85,IF(T80="09-시험준비중",0.55,IF(T80="08-단품준비완료",0.4,IF(T80="07-미인수",0.3,IF(T80="05-계획서승인",0.2,IF(T80="06-BIW중단",0.15,IF(T80="03-검토중",0.1,IF(T80="02-제출_미검토",0.05,IF(T80="04-검토중_보완",0.05,0)))))))))))) | V80: =IF(C80="","",IF(S80<>"","—",IF(M80="","",M80-TODAY()))) | W80: =IF(C80="","",IF(T80="11-결과등록완료","— 완료",IF(T80="01-미제출",IF(I80<TODAY(),"계획서 제출 독촉","계획서 제출 대기"),IF(T80="02-제출_미검토","검토 착수 필요",IF(T80="03-검토중","승인 처리 대기",IF(T80="04-검토중_보완","보완 → 재제출 독촉",IF(T80="05-계획서승인","부품 준비 현황 확인",IF(T80="06-BIW중단","BIW팀 확인",IF(T80="07-미인수","협력사 인수 독촉",IF(T80="08-단품준비완료","시험 일정 확인",IF(T80="09-시험준비중","시험 모니터링",IF(T80="10-시험완료","성적서 등록 독촉",IF(T80="12-조건부승인","조건부 승인 판단","—")))))))))))))
...
