Workbook

Sheet Config
A1: AE_PE | B1: <-- Select Vehicle Code

Sheet Reference Data 기준데이터
A1: TBL_Vehicle (차종 + 일정 + LeadTime)
A2: VehicleCode | B2: VehicleName | C2: T0_DrawingRelease | D2: ProtoBuild | E2: MasterCar | F2: TestDeadline | G2: LT_PlanDue | H2: LT_PartsReady | I2: LT_TestStart | J2: LT_ReportDue
A3: AE_PE | B3: AE PE (Creta EV) | C3: 46037 | D3: 46127 | E3: 46188 | F3: =E3-30 | G3: 14 | H3: 49 | I3: 63 | J3: 98
A4: SU2i | B4: SU2i (Venue Next) | C4: 46082 | D4: 46174 | E4: 46249 | F4: =E4-30 | G4: 14 | H4: 49 | I4: 63 | J4: 98
A5: EN_SUV | B5: EN SUV | C5: 46054 | D5: 46143 | E5: 46218 | F5: =E5-30 | G5: 14 | H5: 49 | I5: 63 | J5: 98
A7: TBL_TestCatalog (시험 카탈로그 — 18 tests)
A8: TestNameKR | B8: TestType | C8: Spec | D8: DurationDays | E8: Scope
A9: EMC 시험 | B9: 단품 | C9: ES 95400-05 | D9: 14 | E9: COMMON
A10: VOC 방출 시험 | B10: 단품 | C10: MS-300-57 | D10: 14 | E10: COMMON
A11: 연소성 시험 | B11: 단품 | C11: FMVSS 302 | D11: 3 | E11: COMMON
A12: 포깅 시험 | B12: 단품 | C12: ES 80062 | D12: 7 | E12: COMMON
A13: 냄새 시험 | B13: 단품 | C13: MS-300-55 | D13: 5 | E13: COMMON
A14: 내후성 시험 | B14: 단품 | C14: MS-300-34 | D14: 21 | E14: COMMON
A15: 내열성 시험 | B15: 단품 | C15: MS-300-31 | D15: 14 | E15: COMMON
A16: 내마모성 시험 | B16: 단품 | C16: MS-300-35 | D16: 7 | E16: COMMON
A17: 내변색 시험 | B17: 단품 | C17: MS-300-36 | D17: 10 | E17: COMMON
A18: 힌지 내구 시험 | B18: 단품 | C18: ES-92030 | D18: 10 | E18: ITEM_SPECIFIC
A19: 시트 내구 시험 | B19: 단품 | C19: ES-93100 | D19: 21 | E19: ITEM_SPECIFIC
A20: H-Point 검증 | B20: 차량장착 | C20: ES-93000 | D20: 14 | E20: ITEM_SPECIFIC
... A26: 조작력 시험 | B26: 단품 | C26: ES-91300 | D26: 5 | E26: ITEM_SPECIFIC
A28: TBL_ItemMaster (아이템 → 구분 + 협력사 + 도면번호)
A29: ItemNameKR | B29: PartCategory | C29: Supplier | D29: DrawingNo
A30: 센터콘솔 | B30: Console | C30: HS R&A | D30: DWG-CONSOLE-001
A31: 콘솔리드 | B31: Console | C31: HS R&A | D31: DWG-CONSOLE-002
A32: 칵핏모듈 | B32: Cockpit | C32: Hyundai Mobis | D32: DWG-COCKPIT-001
A33: 도어트림(앞) | B33: Trim | C33: Faurecia | D33: DWG-DOORTRIM-FR
A34: 도어트림(뒤) | B34: Trim | C34: Faurecia | D34: DWG-DOORTRIM-RR
A35: 필러트림 A | B35: Trim | C35: Seoyon | D35: DWG-PILLAR-A
A36: 필러트림 B | B36: Trim | C36: Seoyon | D36: DWG-PILLAR-B
A37: 필러트림 C | B37: Trim | C37: Seoyon | D37: DWG-PILLAR-C
A38: 패키지트레이 | B38: Trim | C38: HS R&A | D38: DWG-PKGTRAY-001
A39: 헤드라이너 | B39: Trim | C39: Seoyon E-Hwa | D39: DWG-HEADLINER-001
A40: 시트(앞) | B40: Seat | C40: Hyundai Transys | D40: DWG-SEAT-FR
A41: 시트(뒤) | B41: Seat | C41: Hyundai Transys | D41: DWG-SEAT-RR
A43: TBL_ItemTests (아이템 × 시험 매핑 + 제외)
A44: ItemNameKR | B44: TestNameKR | C44: Excluded
A45: 센터콘솔 | B45: BSR 시험 | C45: FALSE
A46: 센터콘솔 | B46: 치수 검사 | C46: FALSE
A47: 콘솔리드 | B47: 힌지 내구 시험 | C47: FALSE
A48: 콘솔리드 | B48: 조작력 시험 | C48: FALSE
...

Sheet Master Tracker 마스터추적표
A1: ESIR Master Tracker V4 — Engineering Sample / Initial Run Test (DB Schema v2)
A3: No. | B3: Vehicle Code | C3: Part Category | D3: Item Name | E3: Supplier | F3: Test Name KR | G3: Test Type | H3: Scope | I3: T₀ Drawing Release | J3: Plan Due Date | K3: Plan Submitted Date | L3: Review Result | M3: Parts Ready (Plan) | N3: Parts Ready (Actual) | O3: Test Start (Plan) | P3: Test Start (Actual) | Q3: Test Complete (Plan) | R3: Test Complete (Actual) | S3: Report Due Date | T3: Report Submitted Date | U3: Override | V3: Status | W3: Progress % | X3: Days to Deadline | Y3: Risk Flag | Z3: Days Since Activity | AA3: Next Action | AB3: Note
A4: 번호 | B4: 차종 | C4: 파트구분 | D4: 아이템명 | E4: 협력사 | F4: 시험명 | G4: 시험유형 | H4: 범위 | I4: T₀ 도면배포 | J4: 계획서기한 | K4: 계획서제출 | L4: 검토결과 | M4: 부품준비(계획) | N4: 부품준비(실적) | O4: 시험시작(계획) | P4: 시험시작(실적) | Q4: 시험완료(계획) | R4: 시험완료(실적) | S4: 성적서기한 | T4: 성적서제출 | U4: 오버라이드 | V4: 상태 | W4: 진행률% | X4: 잔여일 | Y4: 리스크 | Z4: 정체일 | AA4: 다음조치 | AB4: 비고
A5: 1 | B5: AE_PE | C5: =IFERROR(VLOOKUP(D5,'Reference Data 기준데이터'!$A$30:$D$41,2,FALSE),"") | D5: 센터콘솔 | E5: =IFERROR(VLOOKUP(D5,'Reference Data 기준데이터'!$A$30:$D$41,3,FALSE),"") | F5: EMC 시험 | G5: =IFERROR(VLOOKUP(F5,'Reference Data 기준데이터'!$A$9:$E$26,2,FALSE),"") | H5: =IFERROR(VLOOKUP(F5,'Reference Data 기준데이터'!$A$9:$E$26,5,FALSE),"") | I5: =IFERROR(VLOOKUP(B5,'Reference Data 기준데이터'!$A$3:$J$5,3,FALSE),"") | J5: =IFERROR(I5+VLOOKUP(B5,'Reference Data 기준데이터'!$A$3:$J$5,7,FALSE),"") | M5: =IFERROR(I5+VLOOKUP(B5,'Reference Data 기준데이터'!$A$3:$J$5,8,FALSE),"") | O5: =IFERROR(IF(G5="차량장착",MAX(I5+VLOOKUP(B5,'Reference Data 기준데이터'!$A$3:$J$5,9,FALSE),VLOOKUP(B5,'Reference Data 기준데이터'!$A$3:$J$5,4,FALSE)),I5+VLOOKUP(B5,'Reference Data 기준데이터'!$A$3:$J$5,9,FALSE)),"") | Q5: =IFERROR(O5+VLOOKUP(F5,'Reference Data 기준데이터'!$A$9:$E$26,4,FALSE),"") | S5: =IFERROR(MIN(I5+VLOOKUP(B5,'Reference Data 기준데이터'!$A$3:$J$5,10,FALSE),VLOOKUP(B5,'Reference Data 기준데이터'!$A$3:$J$5,6,FALSE)),"") | V5: =IF(U5<>"",U5,IF(AND(T5<>"",R5<>""),"11-결과등록완료",IF(AND(R5<>"",T5=""),"10-시험완료",IF(AND(P5<>"",R5=""),"09-시험준비중",IF(AND(N5<>"",P5=""),"08-단품준비완료",IF(L5="Approved","05-계획서승인",IF(L5="Revision Needed","04-검토중_보완",IF(L5="Under Review","03-검토중",IF(AND(K5<>"",L5=""),"02-제출_미검토","01-미제출"))))))))) | W5: =IFS(V5="01-미제출",0,V5="02-제출_미검토",0.05,V5="03-검토중",0.1,V5="04-검토중_보완",0.05,V5="05-계획서승인",0.2,V5="06-BIW중단",0.15,V5="07-미인수",0.3,V5="08-단품준비완료",0.4,V5="09-시험준비중",0.55,V5="10-시험완료",0.85,V5="11-결과등록완료",1,V5="12-조건부승인",0.9,TRUE,0) | X5: =IF(T5<>"","-",IF(S5="","N/A",S5-TODAY())) | Y5: =IF(V5="11-결과등록완료","DONE",IF(U5="06-BIW중단","BLOCKED",IF(AND(K5="",J5<TODAY()),"CRITICAL",IF(AND(ISNUMBER(X5),X5<=0),"OVERDUE",IF(AND(ISNUMBER(X5),X5<=14),"WARNING",IF(U5<>"","ACTION","ON TRACK")))))) | Z5: =IF(OR(T5<>"",R5<>"",P5<>"",N5<>"",K5<>""),TODAY()-MAX(T5,R5,P5,N5,K5),"—") | AA5: =IF(V5="11-결과등록완료","— 완료",IF(V5="01-미제출",IF(J5<TODAY(),"계획서 제출 독촉 (OVERDUE)","계획서 제출 대기"),IF(V5="02-제출_미검토","설계자: 계획서 검토 착수",IF(V5="03-검토중","설계자: 승인 처리",IF(V5="04-검토중_보완","보완 요청 → 협력사 재제출 독촉",IF(V5="05-계획서승인","시험편 준비 현황 확인",IF(V5="06-BIW중단","BIW 생산팀 확인 → 일정 재수립",IF(V5="07-미인수","협력사 인수 독촉",IF(V5="08-단품준비완료","시험 일정 확인",IF(V5="09-시험준비중","시험 진행 모니터링",IF(V5="10-시험완료","결과 보고서 전산 등록 독촉",IF(V5="12-조건부승인","조건부 승인 여부 판단 → 관련부서 협의","—"))))))))))))
A6: 2 | B6: AE_PE | C6: =IFERROR(VLOOKUP(D6,'Reference Data 기준데이터'!$A$30:$D$41,2,FALSE),"") | D6: 센터콘솔 | E6: =IFERROR(VLOOKUP(D6,'Reference Data 기준데이터'!$A$30:$D$41,3,FALSE),"") | F6: VOC 방출 시험 | G6: =IFERROR(VLOOKUP(F6,'Reference Data 기준데이터'!$A$9:$E$26,2,FALSE),"") | H6: =IFERROR(VLOOKUP(F6,'Reference Data 기준데이터'!$A$9:$E$26,5,FALSE),"") | I6: =IFERROR(VLOOKUP(B6,'Reference Data 기준데이터'!$A$3:$J$5,3,FALSE),"") | J6: =IFERROR(I6+VLOOKUP(B6,'Reference Data 기준데이터'!$A$3:$J$5,7,FALSE),"") | K6: 46049 | L6: Approved | M6: =IFERROR(I6+VLOOKUP(B6,'Reference Data 기준데이터'!$A$3:$J$5,8,FALSE),"") | O6: =IFERROR(IF(G6="차량장착",MAX(I6+VLOOKUP(B6,'Reference Data 기준데이터'!$A$3:$J$5,9,FALSE),VLOOKUP(B6,'Reference Data 기준데이터'!$A$3:$J$5,4,FALSE)),I6+VLOOKUP(B6,'Reference Data 기준데이터'!$A$3:$J$5,9,FALSE)),"") | Q6: =IFERROR(O6+VLOOKUP(F6,'Reference Data 기준데이터'!$A$9:$E$26,4,FALSE),"") | S6: =IFERROR(MIN(I6+VLOOKUP(B6,'Reference Data 기준데이터'!$A$3:$J$5,10,FALSE),VLOOKUP(B6,'Reference Data 기준데이터'!$A$3:$J$5,6,FALSE)),"") | V6: =IF(U6<>"",U6,IF(AND(T6<>"",R6<>""),"11-결과등록완료",IF(AND(R6<>"",T6=""),"10-시험완료",IF(AND(P6<>"",R6=""),"09-시험준비중",IF(AND(N6<>"",P6=""),"08-단품준비완료",IF(L6="Approved","05-계획서승인",IF(L6="Revision Needed","04-검토중_보완",IF(L6="Under Review","03-검토중",IF(AND(K6<>"",L6=""),"02-제출_미검토","01-미제출"))))))))) | W6: =IFS(V6="01-미제출",0,V6="02-제출_미검토",0.05,V6="03-검토중",0.1,V6="04-검토중_보완",0.05,V6="05-계획서승인",0.2,V6="06-BIW중단",0.15,V6="07-미인수",0.3,V6="08-단품준비완료",0.4,V6="09-시험준비중",0.55,V6="10-시험완료",0.85,V6="11-결과등록완료",1,V6="12-조건부승인",0.9,TRUE,0) | X6: =IF(T6<>"","-",IF(S6="","N/A",S6-TODAY())) | Y6: =IF(V6="11-결과등록완료","DONE",IF(U6="06-BIW중단","BLOCKED",IF(AND(K6="",J6<TODAY()),"CRITICAL",IF(AND(ISNUMBER(X6),X6<=0),"OVERDUE",IF(AND(ISNUMBER(X6),X6<=14),"WARNING",IF(U6<>"","ACTION","ON TRACK")))))) | Z6: =IF(OR(T6<>"",R6<>"",P6<>"",N6<>"",K6<>""),TODAY()-MAX(T6,R6,P6,N6,K6),"—") | AA6: =IF(V6="11-결과등록완료","— 완료",IF(V6="01-미제출",IF(J6<TODAY(),"계획서 제출 독촉 (OVERDUE)","계획서 제출 대기"),IF(V6="02-제출_미검토","설계자: 계획서 검토 착수",IF(V6="03-검토중","설계자: 승인 처리",IF(V6="04-검토중_보완","보완 요청 → 협력사 재제출 독촉",IF(V6="05-계획서승인","시험편 준비 현황 확인",IF(V6="06-BIW중단","BIW 생산팀 확인 → 일정 재수립",IF(V6="07-미인수","협력사 인수 독촉",IF(V6="08-단품준비완료","시험 일정 확인",IF(V6="09-시험준비중","시험 진행 모니터링",IF(V6="10-시험완료","결과 보고서 전산 등록 독촉",IF(V6="12-조건부승인","조건부 승인 여부 판단 → 관련부서 협의","—"))))))))))))
A7: 3 | B7: AE_PE | C7: =IFERROR(VLOOKUP(D7,'Reference Data 기준데이터'!$A$30:$D$41,2,FALSE),"") | D7: 센터콘솔 | E7: =IFERROR(VLOOKUP(D7,'Reference Data 기준데이터'!$A$30:$D$41,3,FALSE),"") | F7: 연소성 시험 | G7: =IFERROR(VLOOKUP(F7,'Reference Data 기준데이터'!$A$9:$E$26,2,FALSE),"") | H7: =IFERROR(VLOOKUP(F7,'Reference Data 기준데이터'!$A$9:$E$26,5,FALSE),"") | I7: =IFERROR(VLOOKUP(B7,'Reference Data 기준데이터'!$A$3:$J$5,3,FALSE),"") | J7: =IFERROR(I7+VLOOKUP(B7,'Reference Data 기준데이터'!$A$3:$J$5,7,FALSE),"") | K7: 46050 | L7: Approved | M7: =IFERROR(I7+VLOOKUP(B7,'Reference Data 기준데이터'!$A$3:$J$5,8,FALSE),"") | N7: 46085 | O7: =IFERROR(IF(G7="차량장착",MAX(I7+VLOOKUP(B7,'Reference Data 기준데이터'!$A$3:$J$5,9,FALSE),VLOOKUP(B7,'Reference Data 기준데이터'!$A$3:$J$5,4,FALSE)),I7+VLOOKUP(B7,'Reference Data 기준데이터'!$A$3:$J$5,9,FALSE)),"") | P7: 46102 | Q7: =IFERROR(O7+VLOOKUP(F7,'Reference Data 기준데이터'!$A$9:$E$26,4,FALSE),"") | S7: =IFERROR(MIN(I7+VLOOKUP(B7,'Reference Data 기준데이터'!$A$3:$J$5,10,FALSE),VLOOKUP(B7,'Reference Data 기준데이터'!$A$3:$J$5,6,FALSE)),"") | V7: =IF(U7<>"",U7,IF(AND(T7<>"",R7<>""),"11-결과등록완료",IF(AND(R7<>"",T7=""),"10-시험완료",IF(AND(P7<>"",R7=""),"09-시험준비중",IF(AND(N7<>"",P7=""),"08-단품준비완료",IF(L7="Approved","05-계획서승인",IF(L7="Revision Needed","04-검토중_보완",IF(L7="Under Review","03-검토중",IF(AND(K7<>"",L7=""),"02-제출_미검토","01-미제출"))))))))) | W7: =IFS(V7="01-미제출",0,V7="02-제출_미검토",0.05,V7="03-검토중",0.1,V7="04-검토중_보완",0.05,V7="05-계획서승인",0.2,V7="06-BIW중단",0.15,V7="07-미인수",0.3,V7="08-단품준비완료",0.4,V7="09-시험준비중",0.55,V7="10-시험완료",0.85,V7="11-결과등록완료",1,V7="12-조건부승인",0.9,TRUE,0) | X7: =IF(T7<>"","-",IF(S7="","N/A",S7-TODAY())) | Y7: =IF(V7="11-결과등록완료","DONE",IF(U7="06-BIW중단","BLOCKED",IF(AND(K7="",J7<TODAY()),"CRITICAL",IF(AND(ISNUMBER(X7),X7<=0),"OVERDUE",IF(AND(ISNUMBER(X7),X7<=14),"WARNING",IF(U7<>"","ACTION","ON TRACK")))))) | Z7: =IF(OR(T7<>"",R7<>"",P7<>"",N7<>"",K7<>""),TODAY()-MAX(T7,R7,P7,N7,K7),"—") | AA7: =IF(V7="11-결과등록완료","— 완료",IF(V7="01-미제출",IF(J7<TODAY(),"계획서 제출 독촉 (OVERDUE)","계획서 제출 대기"),IF(V7="02-제출_미검토","설계자: 계획서 검토 착수",IF(V7="03-검토중","설계자: 승인 처리",IF(V7="04-검토중_보완","보완 요청 → 협력사 재제출 독촉",IF(V7="05-계획서승인","시험편 준비 현황 확인",IF(V7="06-BIW중단","BIW 생산팀 확인 → 일정 재수립",IF(V7="07-미인수","협력사 인수 독촉",IF(V7="08-단품준비완료","시험 일정 확인",IF(V7="09-시험준비중","시험 진행 모니터링",IF(V7="10-시험완료","결과 보고서 전산 등록 독촉",IF(V7="12-조건부승인","조건부 승인 여부 판단 → 관련부서 협의","—"))))))))))))
A8: 4 | B8: AE_PE | C8: =IFERROR(VLOOKUP(D8,'Reference Data 기준데이터'!$A$30:$D$41,2,FALSE),"") | D8: 센터콘솔 | E8: =IFERROR(VLOOKUP(D8,'Reference Data 기준데이터'!$A$30:$D$41,3,FALSE),"") | F8: BSR 시험 | G8: =IFERROR(VLOOKUP(F8,'Reference Data 기준데이터'!$A$9:$E$26,2,FALSE),"") | H8: =IFERROR(VLOOKUP(F8,'Reference Data 기준데이터'!$A$9:$E$26,5,FALSE),"") | I8: =IFERROR(VLOOKUP(B8,'Reference Data 기준데이터'!$A$3:$J$5,3,FALSE),"") | J8: =IFERROR(I8+VLOOKUP(B8,'Reference Data 기준데이터'!$A$3:$J$5,7,FALSE),"") | K8: 46051 | L8: Approved | M8: =IFERROR(I8+VLOOKUP(B8,'Reference Data 기준데이터'!$A$3:$J$5,8,FALSE),"") | N8: 46086 | O8: =IFERROR(IF(G8="차량장착",MAX(I8+VLOOKUP(B8,'Reference Data 기준데이터'!$A$3:$J$5,9,FALSE),VLOOKUP(B8,'Reference Data 기준데이터'!$A$3:$J$5,4,FALSE)),I8+VLOOKUP(B8,'Reference Data 기준데이터'!$A$3:$J$5,9,FALSE)),"") | P8: 46103 | Q8: =IFERROR(O8+VLOOKUP(F8,'Reference Data 기준데이터'!$A$9:$E$26,4,FALSE),"") | R8: 46126 | S8: =IFERROR(MIN(I8+VLOOKUP(B8,'Reference Data 기준데이터'!$A$3:$J$5,10,FALSE),VLOOKUP(B8,'Reference Data 기준데이터'!$A$3:$J$5,6,FALSE)),"") | T8: 46130 | V8: =IF(U8<>"",U8,IF(AND(T8<>"",R8<>""),"11-결과등록완료",IF(AND(R8<>"",T8=""),"10-시험완료",IF(AND(P8<>"",R8=""),"09-시험준비중",IF(AND(N8<>"",P8=""),"08-단품준비완료",IF(L8="Approved","05-계획서승인",IF(L8="Revision Needed","04-검토중_보완",IF(L8="Under Review","03-검토중",IF(AND(K8<>"",L8=""),"02-제출_미검토","01-미제출"))))))))) | W8: =IFS(V8="01-미제출",0,V8="02-제출_미검토",0.05,V8="03-검토중",0.1,V8="04-검토중_보완",0.05,V8="05-계획서승인",0.2,V8="06-BIW중단",0.15,V8="07-미인수",0.3,V8="08-단품준비완료",0.4,V8="09-시험준비중",0.55,V8="10-시험완료",0.85,V8="11-결과등록완료",1,V8="12-조건부승인",0.9,TRUE,0) | X8: =IF(T8<>"","-",IF(S8="","N/A",S8-TODAY())) | Y8: =IF(V8="11-결과등록완료","DONE",IF(U8="06-BIW중단","BLOCKED",IF(AND(K8="",J8<TODAY()),"CRITICAL",IF(AND(ISNUMBER(X8),X8<=0),"OVERDUE",IF(AND(ISNUMBER(X8),X8<=14),"WARNING",IF(U8<>"","ACTION","ON TRACK")))))) | Z8: =IF(OR(T8<>"",R8<>"",P8<>"",N8<>"",K8<>""),TODAY()-MAX(T8,R8,P8,N8,K8),"—") | AA8: =IF(V8="11-결과등록완료","— 완료",IF(V8="01-미제출",IF(J8<TODAY(),"계획서 제출 독촉 (OVERDUE)","계획서 제출 대기"),IF(V8="02-제출_미검토","설계자: 계획서 검토 착수",IF(V8="03-검토중","설계자: 승인 처리",IF(V8="04-검토중_보완","보완 요청 → 협력사 재제출 독촉",IF(V8="05-계획서승인","시험편 준비 현황 확인",IF(V8="06-BIW중단","BIW 생산팀 확인 → 일정 재수립",IF(V8="07-미인수","협력사 인수 독촉",IF(V8="08-단품준비완료","시험 일정 확인",IF(V8="09-시험준비중","시험 진행 모니터링",IF(V8="10-시험완료","결과 보고서 전산 등록 독촉",IF(V8="12-조건부승인","조건부 승인 여부 판단 → 관련부서 협의","—"))))))))))))
A9: 5 | B9: AE_PE | C9: =IFERROR(VLOOKUP(D9,'Reference Data 기준데이터'!$A$30:$D$41,2,FALSE),"") | D9: 센터콘솔 | E9: =IFERROR(VLOOKUP(D9,'Reference Data 기준데이터'!$A$30:$D$41,3,FALSE),"") | F9: 치수 검사 | G9: =IFERROR(VLOOKUP(F9,'Reference Data 기준데이터'!$A$9:$E$26,2,FALSE),"") | H9: =IFERROR(VLOOKUP(F9,'Reference Data 기준데이터'!$A$9:$E$26,5,FALSE),"") | I9: =IFERROR(VLOOKUP(B9,'Reference Data 기준데이터'!$A$3:$J$5,3,FALSE),"") | J9: =IFERROR(I9+VLOOKUP(B9,'Reference Data 기준데이터'!$A$3:$J$5,7,FALSE),"") | K9: 46047 | L9: Under Review | M9: =IFERROR(I9+VLOOKUP(B9,'Reference Data 기준데이터'!$A$3:$J$5,8,FALSE),"") | O9: =IFERROR(IF(G9="차량장착",MAX(I9+VLOOKUP(B9,'Reference Data 기준데이터'!$A$3:$J$5,9,FALSE),VLOOKUP(B9,'Reference Data 기준데이터'!$A$3:$J$5,4,FALSE)),I9+VLOOKUP(B9,'Reference Data 기준데이터'!$A$3:$J$5,9,FALSE)),"") | Q9: =IFERROR(O9+VLOOKUP(F9,'Reference Data 기준데이터'!$A$9:$E$26,4,FALSE),"") | S9: =IFERROR(MIN(I9+VLOOKUP(B9,'Reference Data 기준데이터'!$A$3:$J$5,10,FALSE),VLOOKUP(B9,'Reference Data 기준데이터'!$A$3:$J$5,6,FALSE)),"") | V9: =IF(U9<>"",U9,IF(AND(T9<>"",R9<>""),"11-결과등록완료",IF(AND(R9<>"",T9=""),"10-시험완료",IF(AND(P9<>"",R9=""),"09-시험준비중",IF(AND(N9<>"",P9=""),"08-단품준비완료",IF(L9="Approved","05-계획서승인",IF(L9="Revision Needed","04-검토중_보완",IF(L9="Under Review","03-검토중",IF(AND(K9<>"",L9=""),"02-제출_미검토","01-미제출"))))))))) | W9: =IFS(V9="01-미제출",0,V9="02-제출_미검토",0.05,V9="03-검토중",0.1,V9="04-검토중_보완",0.05,V9="05-계획서승인",0.2,V9="06-BIW중단",0.15,V9="07-미인수",0.3,V9="08-단품준비완료",0.4,V9="09-시험준비중",0.55,V9="10-시험완료",0.85,V9="11-결과등록완료",1,V9="12-조건부승인",0.9,TRUE,0) | X9: =IF(T9<>"","-",IF(S9="","N/A",S9-TODAY())) | Y9: =IF(V9="11-결과등록완료","DONE",IF(U9="06-BIW중단","BLOCKED",IF(AND(K9="",J9<TODAY()),"CRITICAL",IF(AND(ISNUMBER(X9),X9<=0),"OVERDUE",IF(AND(ISNUMBER(X9),X9<=14),"WARNING",IF(U9<>"","ACTION","ON TRACK")))))) | Z9: =IF(OR(T9<>"",R9<>"",P9<>"",N9<>"",K9<>""),TODAY()-MAX(T9,R9,P9,N9,K9),"—") | AA9: =IF(V9="11-결과등록완료","— 완료",IF(V9="01-미제출",IF(J9<TODAY(),"계획서 제출 독촉 (OVERDUE)","계획서 제출 대기"),IF(V9="02-제출_미검토","설계자: 계획서 검토 착수",IF(V9="03-검토중","설계자: 승인 처리",IF(V9="04-검토중_보완","보완 요청 → 협력사 재제출 독촉",IF(V9="05-계획서승인","시험편 준비 현황 확인",IF(V9="06-BIW중단","BIW 생산팀 확인 → 일정 재수립",IF(V9="07-미인수","협력사 인수 독촉",IF(V9="08-단품준비완료","시험 일정 확인",IF(V9="09-시험준비중","시험 진행 모니터링",IF(V9="10-시험완료","결과 보고서 전산 등록 독촉",IF(V9="12-조건부승인","조건부 승인 여부 판단 → 관련부서 협의","—"))))))))))))
A10: 6 | B10: AE_PE | C10: =IFERROR(VLOOKUP(D10,'Reference Data 기준데이터'!$A$30:$D$41,2,FALSE),"") | D10: 콘솔리드 | E10: =IFERROR(VLOOKUP(D10,'Reference Data 기준데이터'!$A$30:$D$41,3,FALSE),"") | F10: EMC 시험 | G10: =IFERROR(VLOOKUP(F10,'Reference Data 기준데이터'!$A$9:$E$26,2,FALSE),"") | H10: =IFERROR(VLOOKUP(F10,'Reference Data 기준데이터'!$A$9:$E$26,5,FALSE),"") | I10: =IFERROR(VLOOKUP(B10,'Reference Data 기준데이터'!$A$3:$J$5,3,FALSE),"") | J10: =IFERROR(I10+VLOOKUP(B10,'Reference Data 기준데이터'!$A$3:$J$5,7,FALSE),"") | K10: 46048 | M10: =IFERROR(I10+VLOOKUP(B10,'Reference Data 기준데이터'!$A$3:$J$5,8,FALSE),"") | O10: =IFERROR(IF(G10="차량장착",MAX(I10+VLOOKUP(B10,'Reference Data 기준데이터'!$A$3:$J$5,9,FALSE),VLOOKUP(B10,'Reference Data 기준데이터'!$A$3:$J$5,4,FALSE)),I10+VLOOKUP(B10,'Reference Data 기준데이터'!$A$3:$J$5,9,FALSE)),"") | Q10: =IFERROR(O10+VLOOKUP(F10,'Reference Data 기준데이터'!$A$9:$E$26,4,FALSE),"") | S10: =IFERROR(MIN(I10+VLOOKUP(B10,'Reference Data 기준데이터'!$A$3:$J$5,10,FALSE),VLOOKUP(B10,'Reference Data 기준데이터'!$A$3:$J$5,6,FALSE)),"") | V10: =IF(U10<>"",U10,IF(AND(T10<>"",R10<>""),"11-결과등록완료",IF(AND(R10<>"",T10=""),"10-시험완료",IF(AND(P10<>"",R10=""),"09-시험준비중",IF(AND(N10<>"",P10=""),"08-단품준비완료",IF(L10="Approved","05-계획서승인",IF(L10="Revision Needed","04-검토중_보완",IF(L10="Under Review","03-검토중",IF(AND(K10<>"",L10=""),"02-제출_미검토","01-미제출"))))))))) | W10: =IFS(V10="01-미제출",0,V10="02-제출_미검토",0.05,V10="03-검토중",0.1,V10="04-검토중_보완",0.05,V10="05-계획서승인",0.2,V10="06-BIW중단",0.15,V10="07-미인수",0.3,V10="08-단품준비완료",0.4,V10="09-시험준비중",0.55,V10="10-시험완료",0.85,V10="11-결과등록완료",1,V10="12-조건부승인",0.9,TRUE,0) | X10: =IF(T10<>"","-",IF(S10="","N/A",S10-TODAY())) | Y10: =IF(V10="11-결과등록완료","DONE",IF(U10="06-BIW중단","BLOCKED",IF(AND(K10="",J10<TODAY()),"CRITICAL",IF(AND(ISNUMBER(X10),X10<=0),"OVERDUE",IF(AND(ISNUMBER(X10),X10<=14),"WARNING",IF(U10<>"","ACTION","ON TRACK")))))) | Z10: =IF(OR(T10<>"",R10<>"",P10<>"",N10<>"",K10<>""),TODAY()-MAX(T10,R10,P10,N10,K10),"—") | AA10: =IF(V10="11-결과등록완료","— 완료",IF(V10="01-미제출",IF(J10<TODAY(),"계획서 제출 독촉 (OVERDUE)","계획서 제출 대기"),IF(V10="02-제출_미검토","설계자: 계획서 검토 착수",IF(V10="03-검토중","설계자: 승인 처리",IF(V10="04-검토중_보완","보완 요청 → 협력사 재제출 독촉",IF(V10="05-계획서승인","시험편 준비 현황 확인",IF(V10="06-BIW중단","BIW 생산팀 확인 → 일정 재수립",IF(V10="07-미인수","협력사 인수 독촉",IF(V10="08-단품준비완료","시험 일정 확인",IF(V10="09-시험준비중","시험 진행 모니터링",IF(V10="10-시험완료","결과 보고서 전산 등록 독촉",IF(V10="12-조건부승인","조건부 승인 여부 판단 → 관련부서 협의","—"))))))))))))
A11: 7 | B11: AE_PE | C11: =IFERROR(VLOOKUP(D11,'Reference Data 기준데이터'!$A$30:$D$41,2,FALSE),"") | D11: 콘솔리드 | E11: =IFERROR(VLOOKUP(D11,'Reference Data 기준데이터'!$A$30:$D$41,3,FALSE),"") | F11: VOC 방출 시험 | G11: =IFERROR(VLOOKUP(F11,'Reference Data 기준데이터'!$A$9:$E$26,2,FALSE),"") | H11: =IFERROR(VLOOKUP(F11,'Reference Data 기준데이터'!$A$9:$E$26,5,FALSE),"") | I11: =IFERROR(VLOOKUP(B11,'Reference Data 기준데이터'!$A$3:$J$5,3,FALSE),"") | J11: =IFERROR(I11+VLOOKUP(B11,'Reference Data 기준데이터'!$A$3:$J$5,7,FALSE),"") | K11: 46049 | L11: Approved | M11: =IFERROR(I11+VLOOKUP(B11,'Reference Data 기준데이터'!$A$3:$J$5,8,FALSE),"") | N11: 46089 | O11: =IFERROR(IF(G11="차량장착",MAX(I11+VLOOKUP(B11,'Reference Data 기준데이터'!$A$3:$J$5,9,FALSE),VLOOKUP(B11,'Reference Data 기준데이터'!$A$3:$J$5,4,FALSE)),I11+VLOOKUP(B11,'Reference Data 기준데이터'!$A$3:$J$5,9,FALSE)),"") | Q11: =IFERROR(O11+VLOOKUP(F11,'Reference Data 기준데이터'!$A$9:$E$26,4,FALSE),"") | S11: =IFERROR(MIN(I11+VLOOKUP(B11,'Reference Data 기준데이터'!$A$3:$J$5,10,FALSE),VLOOKUP(B11,'Reference Data 기준데이터'!$A$3:$J$5,6,FALSE)),"") | V11: =IF(U11<>"",U11,IF(AND(T11<>"",R11<>""),"11-결과등록완료",IF(AND(R11<>"",T11=""),"10-시험완료",IF(AND(P11<>"",R11=""),"09-시험준비중",IF(AND(N11<>"",P11=""),"08-단품준비완료",IF(L11="Approved","05-계획서승인",IF(L11="Revision Needed","04-검토중_보완",IF(L11="Under Review","03-검토중",IF(AND(K11<>"",L11=""),"02-제출_미검토","01-미제출"))))))))) | W11: =IFS(V11="01-미제출",0,V11="02-제출_미검토",0.05,V11="03-검토중",0.1,V11="04-검토중_보완",0.05,V11="05-계획서승인",0.2,V11="06-BIW중단",0.15,V11="07-미인수",0.3,V11="08-단품준비완료",0.4,V11="09-시험준비중",0.55,V11="10-시험완료",0.85,V11="11-결과등록완료",1,V11="12-조건부승인",0.9,TRUE,0) | X11: =IF(T11<>"","-",IF(S11="","N/A",S11-TODAY())) | Y11: =IF(V11="11-결과등록완료","DONE",IF(U11="06-BIW중단","BLOCKED",IF(AND(K11="",J11<TODAY()),"CRITICAL",IF(AND(ISNUMBER(X11),X11<=0),"OVERDUE",IF(AND(ISNUMBER(X11),X11<=14),"WARNING",IF(U11<>"","ACTION","ON TRACK")))))) | Z11: =IF(OR(T11<>"",R11<>"",P11<>"",N11<>"",K11<>""),TODAY()-MAX(T11,R11,P11,N11,K11),"—") | AA11: =IF(V11="11-결과등록완료","— 완료",IF(V11="01-미제출",IF(J11<TODAY(),"계획서 제출 독촉 (OVERDUE)","계획서 제출 대기"),IF(V11="02-제출_미검토","설계자: 계획서 검토 착수",IF(V11="03-검토중","설계자: 승인 처리",IF(V11="04-검토중_보완","보완 요청 → 협력사 재제출 독촉",IF(V11="05-계획서승인","시험편 준비 현황 확인",IF(V11="06-BIW중단","BIW 생산팀 확인 → 일정 재수립",IF(V11="07-미인수","협력사 인수 독촉",IF(V11="08-단품준비완료","시험 일정 확인",IF(V11="09-시험준비중","시험 진행 모니터링",IF(V11="10-시험완료","결과 보고서 전산 등록 독촉",IF(V11="12-조건부승인","조건부 승인 여부 판단 → 관련부서 협의","—"))))))))))))
A12: 8 | B12: AE_PE | C12: =IFERROR(VLOOKUP(D12,'Reference Data 기준데이터'!$A$30:$D$41,2,FALSE),"") | D12: 콘솔리드 | E12: =IFERROR(VLOOKUP(D12,'Reference Data 기준데이터'!$A$30:$D$41,3,FALSE),"") | F12: 연소성 시험 | G12: =IFERROR(VLOOKUP(F12,'Reference Data 기준데이터'!$A$9:$E$26,2,FALSE),"") | H12: =IFERROR(VLOOKUP(F12,'Reference Data 기준데이터'!$A$9:$E$26,5,FALSE),"") | I12: =IFERROR(VLOOKUP(B12,'Reference Data 기준데이터'!$A$3:$J$5,3,FALSE),"") | J12: =IFERROR(I12+VLOOKUP(B12,'Reference Data 기준데이터'!$A$3:$J$5,7,FALSE),"") | K12: 46050 | L12: Approved | M12: =IFERROR(I12+VLOOKUP(B12,'Reference Data 기준데이터'!$A$3:$J$5,8,FALSE),"") | N12: 46082 | O12: =IFERROR(IF(G12="차량장착",MAX(I12+VLOOKUP(B12,'Reference Data 기준데이터'!$A$3:$J$5,9,FALSE),VLOOKUP(B12,'Reference Data 기준데이터'!$A$3:$J$5,4,FALSE)),I12+VLOOKUP(B12,'Reference Data 기준데이터'!$A$3:$J$5,9,FALSE)),"") | P12: 46101 | Q12: =IFERROR(O12+VLOOKUP(F12,'Reference Data 기준데이터'!$A$9:$E$26,4,FALSE),"") | R12: 46123 | S12: =IFERROR(MIN(I12+VLOOKUP(B12,'Reference Data 기준데이터'!$A$3:$J$5,10,FALSE),VLOOKUP(B12,'Reference Data 기준데이터'!$A$3:$J$5,6,FALSE)),"") | V12: =IF(U12<>"",U12,IF(AND(T12<>"",R12<>""),"11-결과등록완료",IF(AND(R12<>"",T12=""),"10-시험완료",IF(AND(P12<>"",R12=""),"09-시험준비중",IF(AND(N12<>"",P12=""),"08-단품준비완료",IF(L12="Approved","05-계획서승인",IF(L12="Revision Needed","04-검토중_보완",IF(L12="Under Review","03-검토중",IF(AND(K12<>"",L12=""),"02-제출_미검토","01-미제출"))))))))) | W12: =IFS(V12="01-미제출",0,V12="02-제출_미검토",0.05,V12="03-검토중",0.1,V12="04-검토중_보완",0.05,V12="05-계획서승인",0.2,V12="06-BIW중단",0.15,V12="07-미인수",0.3,V12="08-단품준비완료",0.4,V12="09-시험준비중",0.55,V12="10-시험완료",0.85,V12="11-결과등록완료",1,V12="12-조건부승인",0.9,TRUE,0) | X12: =IF(T12<>"","-",IF(S12="","N/A",S12-TODAY())) | Y12: =IF(V12="11-결과등록완료","DONE",IF(U12="06-BIW중단","BLOCKED",IF(AND(K12="",J12<TODAY()),"CRITICAL",IF(AND(ISNUMBER(X12),X12<=0),"OVERDUE",IF(AND(ISNUMBER(X12),X12<=14),"WARNING",IF(U12<>"","ACTION","ON TRACK")))))) | Z12: =IF(OR(T12<>"",R12<>"",P12<>"",N12<>"",K12<>""),TODAY()-MAX(T12,R12,P12,N12,K12),"—") | AA12: =IF(V12="11-결과등록완료","— 완료",IF(V12="01-미제출",IF(J12<TODAY(),"계획서 제출 독촉 (OVERDUE)","계획서 제출 대기"),IF(V12="02-제출_미검토","설계자: 계획서 검토 착수",IF(V12="03-검토중","설계자: 승인 처리",IF(V12="04-검토중_보완","보완 요청 → 협력사 재제출 독촉",IF(V12="05-계획서승인","시험편 준비 현황 확인",IF(V12="06-BIW중단","BIW 생산팀 확인 → 일정 재수립",IF(V12="07-미인수","협력사 인수 독촉",IF(V12="08-단품준비완료","시험 일정 확인",IF(V12="09-시험준비중","시험 진행 모니터링",IF(V12="10-시험완료","결과 보고서 전산 등록 독촉",IF(V12="12-조건부승인","조건부 승인 여부 판단 → 관련부서 협의","—"))))))))))))
A13: 9 | B13: AE_PE | C13: =IFERROR(VLOOKUP(D13,'Reference Data 기준데이터'!$A$30:$D$41,2,FALSE),"") | D13: 콘솔리드 | E13: =IFERROR(VLOOKUP(D13,'Reference Data 기준데이터'!$A$30:$D$41,3,FALSE),"") | F13: 힌지 내구 시험 | G13: =IFERROR(VLOOKUP(F13,'Reference Data 기준데이터'!$A$9:$E$26,2,FALSE),"") | H13: =IFERROR(VLOOKUP(F13,'Reference Data 기준데이터'!$A$9:$E$26,5,FALSE),"") | I13: =IFERROR(VLOOKUP(B13,'Reference Data 기준데이터'!$A$3:$J$5,3,FALSE),"") | J13: =IFERROR(I13+VLOOKUP(B13,'Reference Data 기준데이터'!$A$3:$J$5,7,FALSE),"") | K13: 46051 | L13: Approved | M13: =IFERROR(I13+VLOOKUP(B13,'Reference Data 기준데이터'!$A$3:$J$5,8,FALSE),"") | O13: =IFERROR(IF(G13="차량장착",MAX(I13+VLOOKUP(B13,'Reference Data 기준데이터'!$A$3:$J$5,9,FALSE),VLOOKUP(B13,'Reference Data 기준데이터'!$A$3:$J$5,4,FALSE)),I13+VLOOKUP(B13,'Reference Data 기준데이터'!$A$3:$J$5,9,FALSE)),"") | Q13: =IFERROR(O13+VLOOKUP(F13,'Reference Data 기준데이터'!$A$9:$E$26,4,FALSE),"") | S13: =IFERROR(MIN(I13+VLOOKUP(B13,'Reference Data 기준데이터'!$A$3:$J$5,10,FALSE),VLOOKUP(B13,'Reference Data 기준데이터'!$A$3:$J$5,6,FALSE)),"") | U13: 06-BIW중단 | V13: =IF(U13<>"",U13,IF(AND(T13<>"",R13<>""),"11-결과등록완료",IF(AND(R13<>"",T13=""),"10-시험완료",IF(AND(P13<>"",R13=""),"09-시험준비중",IF(AND(N13<>"",P13=""),"08-단품준비완료",IF(L13="Approved","05-계획서승인",IF(L13="Revision Needed","04-검토중_보완",IF(L13="Under Review","03-검토중",IF(AND(K13<>"",L13=""),"02-제출_미검토","01-미제출"))))))))) | W13: =IFS(V13="01-미제출",0,V13="02-제출_미검토",0.05,V13="03-검토중",0.1,V13="04-검토중_보완",0.05,V13="05-계획서승인",0.2,V13="06-BIW중단",0.15,V13="07-미인수",0.3,V13="08-단품준비완료",0.4,V13="09-시험준비중",0.55,V13="10-시험완료",0.85,V13="11-결과등록완료",1,V13="12-조건부승인",0.9,TRUE,0) | X13: =IF(T13<>"","-",IF(S13="","N/A",S13-TODAY())) | Y13: =IF(V13="11-결과등록완료","DONE",IF(U13="06-BIW중단","BLOCKED",IF(AND(K13="",J13<TODAY()),"CRITICAL",IF(AND(ISNUMBER(X13),X13<=0),"OVERDUE",IF(AND(ISNUMBER(X13),X13<=14),"WARNING",IF(U13<>"","ACTION","ON TRACK")))))) | Z13: =IF(OR(T13<>"",R13<>"",P13<>"",N13<>"",K13<>""),TODAY()-MAX(T13,R13,P13,N13,K13),"—") | AA13: =IF(V13="11-결과등록완료","— 완료",IF(V13="01-미제출",IF(J13<TODAY(),"계획서 제출 독촉 (OVERDUE)","계획서 제출 대기"),IF(V13="02-제출_미검토","설계자: 계획서 검토 착수",IF(V13="03-검토중","설계자: 승인 처리",IF(V13="04-검토중_보완","보완 요청 → 협력사 재제출 독촉",IF(V13="05-계획서승인","시험편 준비 현황 확인",IF(V13="06-BIW중단","BIW 생산팀 확인 → 일정 재수립",IF(V13="07-미인수","협력사 인수 독촉",IF(V13="08-단품준비완료","시험 일정 확인",IF(V13="09-시험준비중","시험 진행 모니터링",IF(V13="10-시험완료","결과 보고서 전산 등록 독촉",IF(V13="12-조건부승인","조건부 승인 여부 판단 → 관련부서 협의","—"))))))))))))
A14: 10 | B14: AE_PE | C14: =IFERROR(VLOOKUP(D14,'Reference Data 기준데이터'!$A$30:$D$41,2,FALSE),"") | D14: 콘솔리드 | E14: =IFERROR(VLOOKUP(D14,'Reference Data 기준데이터'!$A$30:$D$41,3,FALSE),"") | F14: 조작력 시험 | G14: =IFERROR(VLOOKUP(F14,'Reference Data 기준데이터'!$A$9:$E$26,2,FALSE),"") | H14: =IFERROR(VLOOKUP(F14,'Reference Data 기준데이터'!$A$9:$E$26,5,FALSE),"") | I14: =IFERROR(VLOOKUP(B14,'Reference Data 기준데이터'!$A$3:$J$5,3,FALSE),"") | J14: =IFERROR(I14+VLOOKUP(B14,'Reference Data 기준데이터'!$A$3:$J$5,7,FALSE),"") | K14: 46047 | L14: Approved | M14: =IFERROR(I14+VLOOKUP(B14,'Reference Data 기준데이터'!$A$3:$J$5,8,FALSE),"") | N14: 46084 | O14: =IFERROR(IF(G14="차량장착",MAX(I14+VLOOKUP(B14,'Reference Data 기준데이터'!$A$3:$J$5,9,FALSE),VLOOKUP(B14,'Reference Data 기준데이터'!$A$3:$J$5,4,FALSE)),I14+VLOOKUP(B14,'Reference Data 기준데이터'!$A$3:$J$5,9,FALSE)),"") | P14: 46103 | Q14: =IFERROR(O14+VLOOKUP(F14,'Reference Data 기준데이터'!$A$9:$E$26,4,FALSE),"") | R14: 46125 | S14: =IFERROR(MIN(I14+VLOOKUP(B14,'Reference Data 기준데이터'!$A$3:$J$5,10,FALSE),VLOOKUP(B14,'Reference Data 기준데이터'!$A$3:$J$5,6,FALSE)),"") | T14: 46132 | V14: =IF(U14<>"",U14,IF(AND(T14<>"",R14<>""),"11-결과등록완료",IF(AND(R14<>"",T14=""),"10-시험완료",IF(AND(P14<>"",R14=""),"09-시험준비중",IF(AND(N14<>"",P14=""),"08-단품준비완료",IF(L14="Approved","05-계획서승인",IF(L14="Revision Needed","04-검토중_보완",IF(L14="Under Review","03-검토중",IF(AND(K14<>"",L14=""),"02-제출_미검토","01-미제출"))))))))) | W14: =IFS(V14="01-미제출",0,V14="02-제출_미검토",0.05,V14="03-검토중",0.1,V14="04-검토중_보완",0.05,V14="05-계획서승인",0.2,V14="06-BIW중단",0.15,V14="07-미인수",0.3,V14="08-단품준비완료",0.4,V14="09-시험준비중",0.55,V14="10-시험완료",0.85,V14="11-결과등록완료",1,V14="12-조건부승인",0.9,TRUE,0) | X14: =IF(T14<>"","-",IF(S14="","N/A",S14-TODAY())) | Y14: =IF(V14="11-결과등록완료","DONE",IF(U14="06-BIW중단","BLOCKED",IF(AND(K14="",J14<TODAY()),"CRITICAL",IF(AND(ISNUMBER(X14),X14<=0),"OVERDUE",IF(AND(ISNUMBER(X14),X14<=14),"WARNING",IF(U14<>"","ACTION","ON TRACK")))))) | Z14: =IF(OR(T14<>"",R14<>"",P14<>"",N14<>"",K14<>""),TODAY()-MAX(T14,R14,P14,N14,K14),"—") | AA14: =IF(V14="11-결과등록완료","— 완료",IF(V14="01-미제출",IF(J14<TODAY(),"계획서 제출 독촉 (OVERDUE)","계획서 제출 대기"),IF(V14="02-제출_미검토","설계자: 계획서 검토 착수",IF(V14="03-검토중","설계자: 승인 처리",IF(V14="04-검토중_보완","보완 요청 → 협력사 재제출 독촉",IF(V14="05-계획서승인","시험편 준비 현황 확인",IF(V14="06-BIW중단","BIW 생산팀 확인 → 일정 재수립",IF(V14="07-미인수","협력사 인수 독촉",IF(V14="08-단품준비완료","시험 일정 확인",IF(V14="09-시험준비중","시험 진행 모니터링",IF(V14="10-시험완료","결과 보고서 전산 등록 독촉",IF(V14="12-조건부승인","조건부 승인 여부 판단 → 관련부서 협의","—"))))))))))))
A15: 11 | B15: AE_PE | C15: =IFERROR(VLOOKUP(D15,'Reference Data 기준데이터'!$A$30:$D$41,2,FALSE),"") | D15: 시트(앞) | E15: =IFERROR(VLOOKUP(D15,'Reference Data 기준데이터'!$A$30:$D$41,3,FALSE),"") | F15: EMC 시험 | G15: =IFERROR(VLOOKUP(F15,'Reference Data 기준데이터'!$A$9:$E$26,2,FALSE),"") | H15: =IFERROR(VLOOKUP(F15,'Reference Data 기준데이터'!$A$9:$E$26,5,FALSE),"") | I15: =IFERROR(VLOOKUP(B15,'Reference Data 기준데이터'!$A$3:$J$5,3,FALSE),"") | J15: =IFERROR(I15+VLOOKUP(B15,'Reference Data 기준데이터'!$A$3:$J$5,7,FALSE),"") | K15: 46048 | L15: Revision Needed | M15: =IFERROR(I15+VLOOKUP(B15,'Reference Data 기준데이터'!$A$3:$J$5,8,FALSE),"") | O15: =IFERROR(IF(G15="차량장착",MAX(I15+VLOOKUP(B15,'Reference Data 기준데이터'!$A$3:$J$5,9,FALSE),VLOOKUP(B15,'Reference Data 기준데이터'!$A$3:$J$5,4,FALSE)),I15+VLOOKUP(B15,'Reference Data 기준데이터'!$A$3:$J$5,9,FALSE)),"") | Q15: =IFERROR(O15+VLOOKUP(F15,'Reference Data 기준데이터'!$A$9:$E$26,4,FALSE),"") | S15: =IFERROR(MIN(I15+VLOOKUP(B15,'Reference Data 기준데이터'!$A$3:$J$5,10,FALSE),VLOOKUP(B15,'Reference Data 기준데이터'!$A$3:$J$5,6,FALSE)),"") | V15: =IF(U15<>"",U15,IF(AND(T15<>"",R15<>""),"11-결과등록완료",IF(AND(R15<>"",T15=""),"10-시험완료",IF(AND(P15<>"",R15=""),"09-시험준비중",IF(AND(N15<>"",P15=""),"08-단품준비완료",IF(L15="Approved","05-계획서승인",IF(L15="Revision Needed","04-검토중_보완",IF(L15="Under Review","03-검토중",IF(AND(K15<>"",L15=""),"02-제출_미검토","01-미제출"))))))))) | W15: =IFS(V15="01-미제출",0,V15="02-제출_미검토",0.05,V15="03-검토중",0.1,V15="04-검토중_보완",0.05,V15="05-계획서승인",0.2,V15="06-BIW중단",0.15,V15="07-미인수",0.3,V15="08-단품준비완료",0.4,V15="09-시험준비중",0.55,V15="10-시험완료",0.85,V15="11-결과등록완료",1,V15="12-조건부승인",0.9,TRUE,0) | X15: =IF(T15<>"","-",IF(S15="","N/A",S15-TODAY())) | Y15: =IF(V15="11-결과등록완료","DONE",IF(U15="06-BIW중단","BLOCKED",IF(AND(K15="",J15<TODAY()),"CRITICAL",IF(AND(ISNUMBER(X15),X15<=0),"OVERDUE",IF(AND(ISNUMBER(X15),X15<=14),"WARNING",IF(U15<>"","ACTION","ON TRACK")))))) | Z15: =IF(OR(T15<>"",R15<>"",P15<>"",N15<>"",K15<>""),TODAY()-MAX(T15,R15,P15,N15,K15),"—") | AA15: =IF(V15="11-결과등록완료","— 완료",IF(V15="01-미제출",IF(J15<TODAY(),"계획서 제출 독촉 (OVERDUE)","계획서 제출 대기"),IF(V15="02-제출_미검토","설계자: 계획서 검토 착수",IF(V15="03-검토중","설계자: 승인 처리",IF(V15="04-검토중_보완","보완 요청 → 협력사 재제출 독촉",IF(V15="05-계획서승인","시험편 준비 현황 확인",IF(V15="06-BIW중단","BIW 생산팀 확인 → 일정 재수립",IF(V15="07-미인수","협력사 인수 독촉",IF(V15="08-단품준비완료","시험 일정 확인",IF(V15="09-시험준비중","시험 진행 모니터링",IF(V15="10-시험완료","결과 보고서 전산 등록 독촉",IF(V15="12-조건부승인","조건부 승인 여부 판단 → 관련부서 협의","—"))))))))))))
A16: 12 | B16: AE_PE | C16: =IFERROR(VLOOKUP(D16,'Reference Data 기준데이터'!$A$30:$D$41,2,FALSE),"") | D16: 시트(앞) | E16: =IFERROR(VLOOKUP(D16,'Reference Data 기준데이터'!$A$30:$D$41,3,FALSE),"") | F16: VOC 방출 시험 | G16: =IFERROR(VLOOKUP(F16,'Reference Data 기준데이터'!$A$9:$E$26,2,FALSE),"") | H16: =IFERROR(VLOOKUP(F16,'Reference Data 기준데이터'!$A$9:$E$26,5,FALSE),"") | I16: =IFERROR(VLOOKUP(B16,'Reference Data 기준데이터'!$A$3:$J$5,3,FALSE),"") | J16: =IFERROR(I16+VLOOKUP(B16,'Reference Data 기준데이터'!$A$3:$J$5,7,FALSE),"") | K16: 46049 | L16: Approved | M16: =IFERROR(I16+VLOOKUP(B16,'Reference Data 기준데이터'!$A$3:$J$5,8,FALSE),"") | N16: 46086 | O16: =IFERROR(IF(G16="차량장착",MAX(I16+VLOOKUP(B16,'Reference Data 기준데이터'!$A$3:$J$5,9,FALSE),VLOOKUP(B16,'Reference Data 기준데이터'!$A$3:$J$5,4,FALSE)),I16+VLOOKUP(B16,'Reference Data 기준데이터'!$A$3:$J$5,9,FALSE)),"") | P16: 46099 | Q16: =IFERROR(O16+VLOOKUP(F16,'Reference Data 기준데이터'!$A$9:$E$26,4,FALSE),"") | S16: =IFERROR(MIN(I16+VLOOKUP(B16,'Reference Data 기준데이터'!$A$3:$J$5,10,FALSE),VLOOKUP(B16,'Reference Data 기준데이터'!$A$3:$J$5,6,FALSE)),"") | V16: =IF(U16<>"",U16,IF(AND(T16<>"",R16<>""),"11-결과등록완료",IF(AND(R16<>"",T16=""),"10-시험완료",IF(AND(P16<>"",R16=""),"09-시험준비중",IF(AND(N16<>"",P16=""),"08-단품준비완료",IF(L16="Approved","05-계획서승인",IF(L16="Revision Needed","04-검토중_보완",IF(L16="Under Review","03-검토중",IF(AND(K16<>"",L16=""),"02-제출_미검토","01-미제출"))))))))) | W16: =IFS(V16="01-미제출",0,V16="02-제출_미검토",0.05,V16="03-검토중",0.1,V16="04-검토중_보완",0.05,V16="05-계획서승인",0.2,V16="06-BIW중단",0.15,V16="07-미인수",0.3,V16="08-단품준비완료",0.4,V16="09-시험준비중",0.55,V16="10-시험완료",0.85,V16="11-결과등록완료",1,V16="12-조건부승인",0.9,TRUE,0) | X16: =IF(T16<>"","-",IF(S16="","N/A",S16-TODAY())) | Y16: =IF(V16="11-결과등록완료","DONE",IF(U16="06-BIW중단","BLOCKED",IF(AND(K16="",J16<TODAY()),"CRITICAL",IF(AND(ISNUMBER(X16),X16<=0),"OVERDUE",IF(AND(ISNUMBER(X16),X16<=14),"WARNING",IF(U16<>"","ACTION","ON TRACK")))))) | Z16: =IF(OR(T16<>"",R16<>"",P16<>"",N16<>"",K16<>""),TODAY()-MAX(T16,R16,P16,N16,K16),"—") | AA16: =IF(V16="11-결과등록완료","— 완료",IF(V16="01-미제출",IF(J16<TODAY(),"계획서 제출 독촉 (OVERDUE)","계획서 제출 대기"),IF(V16="02-제출_미검토","설계자: 계획서 검토 착수",IF(V16="03-검토중","설계자: 승인 처리",IF(V16="04-검토중_보완","보완 요청 → 협력사 재제출 독촉",IF(V16="05-계획서승인","시험편 준비 현황 확인",IF(V16="06-BIW중단","BIW 생산팀 확인 → 일정 재수립",IF(V16="07-미인수","협력사 인수 독촉",IF(V16="08-단품준비완료","시험 일정 확인",IF(V16="09-시험준비중","시험 진행 모니터링",IF(V16="10-시험완료","결과 보고서 전산 등록 독촉",IF(V16="12-조건부승인","조건부 승인 여부 판단 → 관련부서 협의","—"))))))))))))
A17: 13 | B17: AE_PE | C17: =IFERROR(VLOOKUP(D17,'Reference Data 기준데이터'!$A$30:$D$41,2,FALSE),"") | D17: 시트(앞) | E17: =IFERROR(VLOOKUP(D17,'Reference Data 기준데이터'!$A$30:$D$41,3,FALSE),"") | F17: 연소성 시험 | G17: =IFERROR(VLOOKUP(F17,'Reference Data 기준데이터'!$A$9:$E$26,2,FALSE),"") | H17: =IFERROR(VLOOKUP(F17,'Reference Data 기준데이터'!$A$9:$E$26,5,FALSE),"") | I17: =IFERROR(VLOOKUP(B17,'Reference Data 기준데이터'!$A$3:$J$5,3,FALSE),"") | J17: =IFERROR(I17+VLOOKUP(B17,'Reference Data 기준데이터'!$A$3:$J$5,7,FALSE),"") | K17: 46050 | L17: Approved | M17: =IFERROR(I17+VLOOKUP(B17,'Reference Data 기준데이터'!$A$3:$J$5,8,FALSE),"") | N17: 46087 | O17: =IFERROR(IF(G17="차량장착",MAX(I17+VLOOKUP(B17,'Reference Data 기준데이터'!$A$3:$J$5,9,FALSE),VLOOKUP(B17,'Reference Data 기준데이터'!$A$3:$J$5,4,FALSE)),I17+VLOOKUP(B17,'Reference Data 기준데이터'!$A$3:$J$5,9,FALSE)),"") | P17: 46100 | Q17: =IFERROR(O17+VLOOKUP(F17,'Reference Data 기준데이터'!$A$9:$E$26,4,FALSE),"") | R17: 46128 | S17: =IFERROR(MIN(I17+VLOOKUP(B17,'Reference Data 기준데이터'!$A$3:$J$5,10,FALSE),VLOOKUP(B17,'Reference Data 기준데이터'!$A$3:$J$5,6,FALSE)),"") | T17: 46131 | V17: =IF(U17<>"",U17,IF(AND(T17<>"",R17<>""),"11-결과등록완료",IF(AND(R17<>"",T17=""),"10-시험완료",IF(AND(P17<>"",R17=""),"09-시험준비중",IF(AND(N17<>"",P17=""),"08-단품준비완료",IF(L17="Approved","05-계획서승인",IF(L17="Revision Needed","04-검토중_보완",IF(L17="Under Review","03-검토중",IF(AND(K17<>"",L17=""),"02-제출_미검토","01-미제출"))))))))) | W17: =IFS(V17="01-미제출",0,V17="02-제출_미검토",0.05,V17="03-검토중",0.1,V17="04-검토중_보완",0.05,V17="05-계획서승인",0.2,V17="06-BIW중단",0.15,V17="07-미인수",0.3,V17="08-단품준비완료",0.4,V17="09-시험준비중",0.55,V17="10-시험완료",0.85,V17="11-결과등록완료",1,V17="12-조건부승인",0.9,TRUE,0) | X17: =IF(T17<>"","-",IF(S17="","N/A",S17-TODAY())) | Y17: =IF(V17="11-결과등록완료","DONE",IF(U17="06-BIW중단","BLOCKED",IF(AND(K17="",J17<TODAY()),"CRITICAL",IF(AND(ISNUMBER(X17),X17<=0),"OVERDUE",IF(AND(ISNUMBER(X17),X17<=14),"WARNING",IF(U17<>"","ACTION","ON TRACK")))))) | Z17: =IF(OR(T17<>"",R17<>"",P17<>"",N17<>"",K17<>""),TODAY()-MAX(T17,R17,P17,N17,K17),"—") | AA17: =IF(V17="11-결과등록완료","— 완료",IF(V17="01-미제출",IF(J17<TODAY(),"계획서 제출 독촉 (OVERDUE)","계획서 제출 대기"),IF(V17="02-제출_미검토","설계자: 계획서 검토 착수",IF(V17="03-검토중","설계자: 승인 처리",IF(V17="04-검토중_보완","보완 요청 → 협력사 재제출 독촉",IF(V17="05-계획서승인","시험편 준비 현황 확인",IF(V17="06-BIW중단","BIW 생산팀 확인 → 일정 재수립",IF(V17="07-미인수","협력사 인수 독촉",IF(V17="08-단품준비완료","시험 일정 확인",IF(V17="09-시험준비중","시험 진행 모니터링",IF(V17="10-시험완료","결과 보고서 전산 등록 독촉",IF(V17="12-조건부승인","조건부 승인 여부 판단 → 관련부서 협의","—"))))))))))))
A18: 14 | B18: AE_PE | C18: =IFERROR(VLOOKUP(D18,'Reference Data 기준데이터'!$A$30:$D$41,2,FALSE),"") | D18: 시트(앞) | E18: =IFERROR(VLOOKUP(D18,'Reference Data 기준데이터'!$A$30:$D$41,3,FALSE),"") | F18: 시트 내구 시험 | G18: =IFERROR(VLOOKUP(F18,'Reference Data 기준데이터'!$A$9:$E$26,2,FALSE),"") | H18: =IFERROR(VLOOKUP(F18,'Reference Data 기준데이터'!$A$9:$E$26,5,FALSE),"") | I18: =IFERROR(VLOOKUP(B18,'Reference Data 기준데이터'!$A$3:$J$5,3,FALSE),"") | J18: =IFERROR(I18+VLOOKUP(B18,'Reference Data 기준데이터'!$A$3:$J$5,7,FALSE),"") | K18: 46051 | L18: Approved | M18: =IFERROR(I18+VLOOKUP(B18,'Reference Data 기준데이터'!$A$3:$J$5,8,FALSE),"") | O18: =IFERROR(IF(G18="차량장착",MAX(I18+VLOOKUP(B18,'Reference Data 기준데이터'!$A$3:$J$5,9,FALSE),VLOOKUP(B18,'Reference Data 기준데이터'!$A$3:$J$5,4,FALSE)),I18+VLOOKUP(B18,'Reference Data 기준데이터'!$A$3:$J$5,9,FALSE)),"") | Q18: =IFERROR(O18+VLOOKUP(F18,'Reference Data 기준데이터'!$A$9:$E$26,4,FALSE),"") | S18: =IFERROR(MIN(I18+VLOOKUP(B18,'Reference Data 기준데이터'!$A$3:$J$5,10,FALSE),VLOOKUP(B18,'Reference Data 기준데이터'!$A$3:$J$5,6,FALSE)),"") | V18: =IF(U18<>"",U18,IF(AND(T18<>"",R18<>""),"11-결과등록완료",IF(AND(R18<>"",T18=""),"10-시험완료",IF(AND(P18<>"",R18=""),"09-시험준비중",IF(AND(N18<>"",P18=""),"08-단품준비완료",IF(L18="Approved","05-계획서승인",IF(L18="Revision Needed","04-검토중_보완",IF(L18="Under Review","03-검토중",IF(AND(K18<>"",L18=""),"02-제출_미검토","01-미제출"))))))))) | W18: =IFS(V18="01-미제출",0,V18="02-제출_미검토",0.05,V18="03-검토중",0.1,V18="04-검토중_보완",0.05,V18="05-계획서승인",0.2,V18="06-BIW중단",0.15,V18="07-미인수",0.3,V18="08-단품준비완료",0.4,V18="09-시험준비중",0.55,V18="10-시험완료",0.85,V18="11-결과등록완료",1,V18="12-조건부승인",0.9,TRUE,0) | X18: =IF(T18<>"","-",IF(S18="","N/A",S18-TODAY())) | Y18: =IF(V18="11-결과등록완료","DONE",IF(U18="06-BIW중단","BLOCKED",IF(AND(K18="",J18<TODAY()),"CRITICAL",IF(AND(ISNUMBER(X18),X18<=0),"OVERDUE",IF(AND(ISNUMBER(X18),X18<=14),"WARNING",IF(U18<>"","ACTION","ON TRACK")))))) | Z18: =IF(OR(T18<>"",R18<>"",P18<>"",N18<>"",K18<>""),TODAY()-MAX(T18,R18,P18,N18,K18),"—") | AA18: =IF(V18="11-결과등록완료","— 완료",IF(V18="01-미제출",IF(J18<TODAY(),"계획서 제출 독촉 (OVERDUE)","계획서 제출 대기"),IF(V18="02-제출_미검토","설계자: 계획서 검토 착수",IF(V18="03-검토중","설계자: 승인 처리",IF(V18="04-검토중_보완","보완 요청 → 협력사 재제출 독촉",IF(V18="05-계획서승인","시험편 준비 현황 확인",IF(V18="06-BIW중단","BIW 생산팀 확인 → 일정 재수립",IF(V18="07-미인수","협력사 인수 독촉",IF(V18="08-단품준비완료","시험 일정 확인",IF(V18="09-시험준비중","시험 진행 모니터링",IF(V18="10-시험완료","결과 보고서 전산 등록 독촉",IF(V18="12-조건부승인","조건부 승인 여부 판단 → 관련부서 협의","—"))))))))))))
A19: 15 | B19: AE_PE | C19: =IFERROR(VLOOKUP(D19,'Reference Data 기준데이터'!$A$30:$D$41,2,FALSE),"") | D19: 시트(앞) | E19: =IFERROR(VLOOKUP(D19,'Reference Data 기준데이터'!$A$30:$D$41,3,FALSE),"") | F19: H-Point 검증 | G19: =IFERROR(VLOOKUP(F19,'Reference Data 기준데이터'!$A$9:$E$26,2,FALSE),"") | H19: =IFERROR(VLOOKUP(F19,'Reference Data 기준데이터'!$A$9:$E$26,5,FALSE),"") | I19: =IFERROR(VLOOKUP(B19,'Reference Data 기준데이터'!$A$3:$J$5,3,FALSE),"") | J19: =IFERROR(I19+VLOOKUP(B19,'Reference Data 기준데이터'!$A$3:$J$5,7,FALSE),"") | K19: 46047 | L19: Approved | M19: =IFERROR(I19+VLOOKUP(B19,'Reference Data 기준데이터'!$A$3:$J$5,8,FALSE),"") | N19: 46089 | O19: =IFERROR(IF(G19="차량장착",MAX(I19+VLOOKUP(B19,'Reference Data 기준데이터'!$A$3:$J$5,9,FALSE),VLOOKUP(B19,'Reference Data 기준데이터'!$A$3:$J$5,4,FALSE)),I19+VLOOKUP(B19,'Reference Data 기준데이터'!$A$3:$J$5,9,FALSE)),"") | Q19: =IFERROR(O19+VLOOKUP(F19,'Reference Data 기준데이터'!$A$9:$E$26,4,FALSE),"") | S19: =IFERROR(MIN(I19+VLOOKUP(B19,'Reference Data 기준데이터'!$A$3:$J$5,10,FALSE),VLOOKUP(B19,'Reference Data 기준데이터'!$A$3:$J$5,6,FALSE)),"") | U19: 07-미인수 | V19: =IF(U19<>"",U19,IF(AND(T19<>"",R19<>""),"11-결과등록완료",IF(AND(R19<>"",T19=""),"10-시험완료",IF(AND(P19<>"",R19=""),"09-시험준비중",IF(AND(N19<>"",P19=""),"08-단품준비완료",IF(L19="Approved","05-계획서승인",IF(L19="Revision Needed","04-검토중_보완",IF(L19="Under Review","03-검토중",IF(AND(K19<>"",L19=""),"02-제출_미검토","01-미제출"))))))))) | W19: =IFS(V19="01-미제출",0,V19="02-제출_미검토",0.05,V19="03-검토중",0.1,V19="04-검토중_보완",0.05,V19="05-계획서승인",0.2,V19="06-BIW중단",0.15,V19="07-미인수",0.3,V19="08-단품준비완료",0.4,V19="09-시험준비중",0.55,V19="10-시험완료",0.85,V19="11-결과등록완료",1,V19="12-조건부승인",0.9,TRUE,0) | X19: =IF(T19<>"","-",IF(S19="","N/A",S19-TODAY())) | Y19: =IF(V19="11-결과등록완료","DONE",IF(U19="06-BIW중단","BLOCKED",IF(AND(K19="",J19<TODAY()),"CRITICAL",IF(AND(ISNUMBER(X19),X19<=0),"OVERDUE",IF(AND(ISNUMBER(X19),X19<=14),"WARNING",IF(U19<>"","ACTION","ON TRACK")))))) | Z19: =IF(OR(T19<>"",R19<>"",P19<>"",N19<>"",K19<>""),TODAY()-MAX(T19,R19,P19,N19,K19),"—") | AA19: =IF(V19="11-결과등록완료","— 완료",IF(V19="01-미제출",IF(J19<TODAY(),"계획서 제출 독촉 (OVERDUE)","계획서 제출 대기"),IF(V19="02-제출_미검토","설계자: 계획서 검토 착수",IF(V19="03-검토중","설계자: 승인 처리",IF(V19="04-검토중_보완","보완 요청 → 협력사 재제출 독촉",IF(V19="05-계획서승인","시험편 준비 현황 확인",IF(V19="06-BIW중단","BIW 생산팀 확인 → 일정 재수립",IF(V19="07-미인수","협력사 인수 독촉",IF(V19="08-단품준비완료","시험 일정 확인",IF(V19="09-시험준비중","시험 진행 모니터링",IF(V19="10-시험완료","결과 보고서 전산 등록 독촉",IF(V19="12-조건부승인","조건부 승인 여부 판단 → 관련부서 협의","—"))))))))))))
A20: 16 | B20: AE_PE | C20: =IFERROR(VLOOKUP(D20,'Reference Data 기준데이터'!$A$30:$D$41,2,FALSE),"") | D20: 시트(앞) | E20: =IFERROR(VLOOKUP(D20,'Reference Data 기준데이터'!$A$30:$D$41,3,FALSE),"") | F20: 안전벨트 앵커리지 | G20: =IFERROR(VLOOKUP(F20,'Reference Data 기준데이터'!$A$9:$E$26,2,FALSE),"") | H20: =IFERROR(VLOOKUP(F20,'Reference Data 기준데이터'!$A$9:$E$26,5,FALSE),"") | I20: =IFERROR(VLOOKUP(B20,'Reference Data 기준데이터'!$A$3:$J$5,3,FALSE),"") | J20: =IFERROR(I20+VLOOKUP(B20,'Reference Data 기준데이터'!$A$3:$J$5,7,FALSE),"") | K20: 46048 | L20: Under Review | M20: =IFERROR(I20+VLOOKUP(B20,'Reference Data 기준데이터'!$A$3:$J$5,8,FALSE),"") | O20: =IFERROR(IF(G20="차량장착",MAX(I20+VLOOKUP(B20,'Reference Data 기준데이터'!$A$3:$J$5,9,FALSE),VLOOKUP(B20,'Reference Data 기준데이터'!$A$3:$J$5,4,FALSE)),I20+VLOOKUP(B20,'Reference Data 기준데이터'!$A$3:$J$5,9,FALSE)),"") | Q20: =IFERROR(O20+VLOOKUP(F20,'Reference Data 기준데이터'!$A$9:$E$26,4,FALSE),"") | S20: =IFERROR(MIN(I20+VLOOKUP(B20,'Reference Data 기준데이터'!$A$3:$J$5,10,FALSE),VLOOKUP(B20,'Reference Data 기준데이터'!$A$3:$J$5,6,FALSE)),"") | V20: =IF(U20<>"",U20,IF(AND(T20<>"",R20<>""),"11-결과등록완료",IF(AND(R20<>"",T20=""),"10-시험완료",IF(AND(P20<>"",R20=""),"09-시험준비중",IF(AND(N20<>"",P20=""),"08-단품준비완료",IF(L20="Approved","05-계획서승인",IF(L20="Revision Needed","04-검토중_보완",IF(L20="Under Review","03-검토중",IF(AND(K20<>"",L20=""),"02-제출_미검토","01-미제출"))))))))) | W20: =IFS(V20="01-미제출",0,V20="02-제출_미검토",0.05,V20="03-검토중",0.1,V20="04-검토중_보완",0.05,V20="05-계획서승인",0.2,V20="06-BIW중단",0.15,V20="07-미인수",0.3,V20="08-단품준비완료",0.4,V20="09-시험준비중",0.55,V20="10-시험완료",0.85,V20="11-결과등록완료",1,V20="12-조건부승인",0.9,TRUE,0) | X20: =IF(T20<>"","-",IF(S20="","N/A",S20-TODAY())) | Y20: =IF(V20="11-결과등록완료","DONE",IF(U20="06-BIW중단","BLOCKED",IF(AND(K20="",J20<TODAY()),"CRITICAL",IF(AND(ISNUMBER(X20),X20<=0),"OVERDUE",IF(AND(ISNUMBER(X20),X20<=14),"WARNING",IF(U20<>"","ACTION","ON TRACK")))))) | Z20: =IF(OR(T20<>"",R20<>"",P20<>"",N20<>"",K20<>""),TODAY()-MAX(T20,R20,P20,N20,K20),"—") | AA20: =IF(V20="11-결과등록완료","— 완료",IF(V20="01-미제출",IF(J20<TODAY(),"계획서 제출 독촉 (OVERDUE)","계획서 제출 대기"),IF(V20="02-제출_미검토","설계자: 계획서 검토 착수",IF(V20="03-검토중","설계자: 승인 처리",IF(V20="04-검토중_보완","보완 요청 → 협력사 재제출 독촉",IF(V20="05-계획서승인","시험편 준비 현황 확인",IF(V20="06-BIW중단","BIW 생산팀 확인 → 일정 재수립",IF(V20="07-미인수","협력사 인수 독촉",IF(V20="08-단품준비완료","시험 일정 확인",IF(V20="09-시험준비중","시험 진행 모니터링",IF(V20="10-시험완료","결과 보고서 전산 등록 독촉",IF(V20="12-조건부승인","조건부 승인 여부 판단 → 관련부서 협의","—"))))))))))))
A21: 17 | B21: AE_PE | C21: =IFERROR(VLOOKUP(D21,'Reference Data 기준데이터'!$A$30:$D$41,2,FALSE),"") | D21: 시트(뒤) | E21: =IFERROR(VLOOKUP(D21,'Reference Data 기준데이터'!$A$30:$D$41,3,FALSE),"") | F21: EMC 시험 | G21: =IFERROR(VLOOKUP(F21,'Reference Data 기준데이터'!$A$9:$E$26,2,FALSE),"") | H21: =IFERROR(VLOOKUP(F21,'Reference Data 기준데이터'!$A$9:$E$26,5,FALSE),"") | I21: =IFERROR(VLOOKUP(B21,'Reference Data 기준데이터'!$A$3:$J$5,3,FALSE),"") | J21: =IFERROR(I21+VLOOKUP(B21,'Reference Data 기준데이터'!$A$3:$J$5,7,FALSE),"") | K21: 46049 | L21: Approved | M21: =IFERROR(I21+VLOOKUP(B21,'Reference Data 기준데이터'!$A$3:$J$5,8,FALSE),"") | N21: 46083 | O21: =IFERROR(IF(G21="차량장착",MAX(I21+VLOOKUP(B21,'Reference Data 기준데이터'!$A$3:$J$5,9,FALSE),VLOOKUP(B21,'Reference Data 기준데이터'!$A$3:$J$5,4,FALSE)),I21+VLOOKUP(B21,'Reference Data 기준데이터'!$A$3:$J$5,9,FALSE)),"") | Q21: =IFERROR(O21+VLOOKUP(F21,'Reference Data 기준데이터'!$A$9:$E$26,4,FALSE),"") | S21: =IFERROR(MIN(I21+VLOOKUP(B21,'Reference Data 기준데이터'!$A$3:$J$5,10,FALSE),VLOOKUP(B21,'Reference Data 기준데이터'!$A$3:$J$5,6,FALSE)),"") | V21: =IF(U21<>"",U21,IF(AND(T21<>"",R21<>""),"11-결과등록완료",IF(AND(R21<>"",T21=""),"10-시험완료",IF(AND(P21<>"",R21=""),"09-시험준비중",IF(AND(N21<>"",P21=""),"08-단품준비완료",IF(L21="Approved","05-계획서승인",IF(L21="Revision Needed","04-검토중_보완",IF(L21="Under Review","03-검토중",IF(AND(K21<>"",L21=""),"02-제출_미검토","01-미제출"))))))))) | W21: =IFS(V21="01-미제출",0,V21="02-제출_미검토",0.05,V21="03-검토중",0.1,V21="04-검토중_보완",0.05,V21="05-계획서승인",0.2,V21="06-BIW중단",0.15,V21="07-미인수",0.3,V21="08-단품준비완료",0.4,V21="09-시험준비중",0.55,V21="10-시험완료",0.85,V21="11-결과등록완료",1,V21="12-조건부승인",0.9,TRUE,0) | X21: =IF(T21<>"","-",IF(S21="","N/A",S21-TODAY())) | Y21: =IF(V21="11-결과등록완료","DONE",IF(U21="06-BIW중단","BLOCKED",IF(AND(K21="",J21<TODAY()),"CRITICAL",IF(AND(ISNUMBER(X21),X21<=0),"OVERDUE",IF(AND(ISNUMBER(X21),X21<=14),"WARNING",IF(U21<>"","ACTION","ON TRACK")))))) | Z21: =IF(OR(T21<>"",R21<>"",P21<>"",N21<>"",K21<>""),TODAY()-MAX(T21,R21,P21,N21,K21),"—") | AA21: =IF(V21="11-결과등록완료","— 완료",IF(V21="01-미제출",IF(J21<TODAY(),"계획서 제출 독촉 (OVERDUE)","계획서 제출 대기"),IF(V21="02-제출_미검토","설계자: 계획서 검토 착수",IF(V21="03-검토중","설계자: 승인 처리",IF(V21="04-검토중_보완","보완 요청 → 협력사 재제출 독촉",IF(V21="05-계획서승인","시험편 준비 현황 확인",IF(V21="06-BIW중단","BIW 생산팀 확인 → 일정 재수립",IF(V21="07-미인수","협력사 인수 독촉",IF(V21="08-단품준비완료","시험 일정 확인",IF(V21="09-시험준비중","시험 진행 모니터링",IF(V21="10-시험완료","결과 보고서 전산 등록 독촉",IF(V21="12-조건부승인","조건부 승인 여부 판단 → 관련부서 협의","—"))))))))))))
A22: 18 | B22: AE_PE | C22: =IFERROR(VLOOKUP(D22,'Reference Data 기준데이터'!$A$30:$D$41,2,FALSE),"") | D22: 시트(뒤) | E22: =IFERROR(VLOOKUP(D22,'Reference Data 기준데이터'!$A$30:$D$41,3,FALSE),"") | F22: VOC 방출 시험 | G22: =IFERROR(VLOOKUP(F22,'Reference Data 기준데이터'!$A$9:$E$26,2,FALSE),"") | H22: =IFERROR(VLOOKUP(F22,'Reference Data 기준데이터'!$A$9:$E$26,5,FALSE),"") | I22: =IFERROR(VLOOKUP(B22,'Reference Data 기준데이터'!$A$3:$J$5,3,FALSE),"") | J22: =IFERROR(I22+VLOOKUP(B22,'Reference Data 기준데이터'!$A$3:$J$5,7,FALSE),"") | K22: 46050 | L22: Approved | M22: =IFERROR(I22+VLOOKUP(B22,'Reference Data 기준데이터'!$A$3:$J$5,8,FALSE),"") | N22: 46084 | O22: =IFERROR(IF(G22="차량장착",MAX(I22+VLOOKUP(B22,'Reference Data 기준데이터'!$A$3:$J$5,9,FALSE),VLOOKUP(B22,'Reference Data 기준데이터'!$A$3:$J$5,4,FALSE)),I22+VLOOKUP(B22,'Reference Data 기준데이터'!$A$3:$J$5,9,FALSE)),"") | P22: 46099 | Q22: =IFERROR(O22+VLOOKUP(F22,'Reference Data 기준데이터'!$A$9:$E$26,4,FALSE),"") | R22: 46126 | S22: =IFERROR(MIN(I22+VLOOKUP(B22,'Reference Data 기준데이터'!$A$3:$J$5,10,FALSE),VLOOKUP(B22,'Reference Data 기준데이터'!$A$3:$J$5,6,FALSE)),"") | T22: 46132 | U22: 12-조건부승인 | V22: =IF(U22<>"",U22,IF(AND(T22<>"",R22<>""),"11-결과등록완료",IF(AND(R22<>"",T22=""),"10-시험완료",IF(AND(P22<>"",R22=""),"09-시험준비중",IF(AND(N22<>"",P22=""),"08-단품준비완료",IF(L22="Approved","05-계획서승인",IF(L22="Revision Needed","04-검토중_보완",IF(L22="Under Review","03-검토중",IF(AND(K22<>"",L22=""),"02-제출_미검토","01-미제출"))))))))) | W22: =IFS(V22="01-미제출",0,V22="02-제출_미검토",0.05,V22="03-검토중",0.1,V22="04-검토중_보완",0.05,V22="05-계획서승인",0.2,V22="06-BIW중단",0.15,V22="07-미인수",0.3,V22="08-단품준비완료",0.4,V22="09-시험준비중",0.55,V22="10-시험완료",0.85,V22="11-결과등록완료",1,V22="12-조건부승인",0.9,TRUE,0) | X22: =IF(T22<>"","-",IF(S22="","N/A",S22-TODAY())) | Y22: =IF(V22="11-결과등록완료","DONE",IF(U22="06-BIW중단","BLOCKED",IF(AND(K22="",J22<TODAY()),"CRITICAL",IF(AND(ISNUMBER(X22),X22<=0),"OVERDUE",IF(AND(ISNUMBER(X22),X22<=14),"WARNING",IF(U22<>"","ACTION","ON TRACK")))))) | Z22: =IF(OR(T22<>"",R22<>"",P22<>"",N22<>"",K22<>""),TODAY()-MAX(T22,R22,P22,N22,K22),"—") | AA22: =IF(V22="11-결과등록완료","— 완료",IF(V22="01-미제출",IF(J22<TODAY(),"계획서 제출 독촉 (OVERDUE)","계획서 제출 대기"),IF(V22="02-제출_미검토","설계자: 계획서 검토 착수",IF(V22="03-검토중","설계자: 승인 처리",IF(V22="04-검토중_보완","보완 요청 → 협력사 재제출 독촉",IF(V22="05-계획서승인","시험편 준비 현황 확인",IF(V22="06-BIW중단","BIW 생산팀 확인 → 일정 재수립",IF(V22="07-미인수","협력사 인수 독촉",IF(V22="08-단품준비완료","시험 일정 확인",IF(V22="09-시험준비중","시험 진행 모니터링",IF(V22="10-시험완료","결과 보고서 전산 등록 독촉",IF(V22="12-조건부승인","조건부 승인 여부 판단 → 관련부서 협의","—"))))))))))))
A23: 19 | B23: AE_PE | C23: =IFERROR(VLOOKUP(D23,'Reference Data 기준데이터'!$A$30:$D$41,2,FALSE),"") | D23: 시트(뒤) | E23: =IFERROR(VLOOKUP(D23,'Reference Data 기준데이터'!$A$30:$D$41,3,FALSE),"") | F23: 연소성 시험 | G23: =IFERROR(VLOOKUP(F23,'Reference Data 기준데이터'!$A$9:$E$26,2,FALSE),"") | H23: =IFERROR(VLOOKUP(F23,'Reference Data 기준데이터'!$A$9:$E$26,5,FALSE),"") | I23: =IFERROR(VLOOKUP(B23,'Reference Data 기준데이터'!$A$3:$J$5,3,FALSE),"") | J23: =IFERROR(I23+VLOOKUP(B23,'Reference Data 기준데이터'!$A$3:$J$5,7,FALSE),"") | M23: =IFERROR(I23+VLOOKUP(B23,'Reference Data 기준데이터'!$A$3:$J$5,8,FALSE),"") | O23: =IFERROR(IF(G23="차량장착",MAX(I23+VLOOKUP(B23,'Reference Data 기준데이터'!$A$3:$J$5,9,FALSE),VLOOKUP(B23,'Reference Data 기준데이터'!$A$3:$J$5,4,FALSE)),I23+VLOOKUP(B23,'Reference Data 기준데이터'!$A$3:$J$5,9,FALSE)),"") | Q23: =IFERROR(O23+VLOOKUP(F23,'Reference Data 기준데이터'!$A$9:$E$26,4,FALSE),"") | S23: =IFERROR(MIN(I23+VLOOKUP(B23,'Reference Data 기준데이터'!$A$3:$J$5,10,FALSE),VLOOKUP(B23,'Reference Data 기준데이터'!$A$3:$J$5,6,FALSE)),"") | V23: =IF(U23<>"",U23,IF(AND(T23<>"",R23<>""),"11-결과등록완료",IF(AND(R23<>"",T23=""),"10-시험완료",IF(AND(P23<>"",R23=""),"09-시험준비중",IF(AND(N23<>"",P23=""),"08-단품준비완료",IF(L23="Approved","05-계획서승인",IF(L23="Revision Needed","04-검토중_보완",IF(L23="Under Review","03-검토중",IF(AND(K23<>"",L23=""),"02-제출_미검토","01-미제출"))))))))) | W23: =IFS(V23="01-미제출",0,V23="02-제출_미검토",0.05,V23="03-검토중",0.1,V23="04-검토중_보완",0.05,V23="05-계획서승인",0.2,V23="06-BIW중단",0.15,V23="07-미인수",0.3,V23="08-단품준비완료",0.4,V23="09-시험준비중",0.55,V23="10-시험완료",0.85,V23="11-결과등록완료",1,V23="12-조건부승인",0.9,TRUE,0) | X23: =IF(T23<>"","-",IF(S23="","N/A",S23-TODAY())) | Y23: =IF(V23="11-결과등록완료","DONE",IF(U23="06-BIW중단","BLOCKED",IF(AND(K23="",J23<TODAY()),"CRITICAL",IF(AND(ISNUMBER(X23),X23<=0),"OVERDUE",IF(AND(ISNUMBER(X23),X23<=14),"WARNING",IF(U23<>"","ACTION","ON TRACK")))))) | Z23: =IF(OR(T23<>"",R23<>"",P23<>"",N23<>"",K23<>""),TODAY()-MAX(T23,R23,P23,N23,K23),"—") | AA23: =IF(V23="11-결과등록완료","— 완료",IF(V23="01-미제출",IF(J23<TODAY(),"계획서 제출 독촉 (OVERDUE)","계획서 제출 대기"),IF(V23="02-제출_미검토","설계자: 계획서 검토 착수",IF(V23="03-검토중","설계자: 승인 처리",IF(V23="04-검토중_보완","보완 요청 → 협력사 재제출 독촉",IF(V23="05-계획서승인","시험편 준비 현황 확인",IF(V23="06-BIW중단","BIW 생산팀 확인 → 일정 재수립",IF(V23="07-미인수","협력사 인수 독촉",IF(V23="08-단품준비완료","시험 일정 확인",IF(V23="09-시험준비중","시험 진행 모니터링",IF(V23="10-시험완료","결과 보고서 전산 등록 독촉",IF(V23="12-조건부승인","조건부 승인 여부 판단 → 관련부서 협의","—"))))))))))))
A24: 20 | B24: AE_PE | C24: =IFERROR(VLOOKUP(D24,'Reference Data 기준데이터'!$A$30:$D$41,2,FALSE),"") | D24: 시트(뒤) | E24: =IFERROR(VLOOKUP(D24,'Reference Data 기준데이터'!$A$30:$D$41,3,FALSE),"") | F24: 시트 내구 시험 | G24: =IFERROR(VLOOKUP(F24,'Reference Data 기준데이터'!$A$9:$E$26,2,FALSE),"") | H24: =IFERROR(VLOOKUP(F24,'Reference Data 기준데이터'!$A$9:$E$26,5,FALSE),"") | I24: =IFERROR(VLOOKUP(B24,'Reference Data 기준데이터'!$A$3:$J$5,3,FALSE),"") | J24: =IFERROR(I24+VLOOKUP(B24,'Reference Data 기준데이터'!$A$3:$J$5,7,FALSE),"") | K24: 46047 | L24: Approved | M24: =IFERROR(I24+VLOOKUP(B24,'Reference Data 기준데이터'!$A$3:$J$5,8,FALSE),"") | N24: 46086 | O24: =IFERROR(IF(G24="차량장착",MAX(I24+VLOOKUP(B24,'Reference Data 기준데이터'!$A$3:$J$5,9,FALSE),VLOOKUP(B24,'Reference Data 기준데이터'!$A$3:$J$5,4,FALSE)),I24+VLOOKUP(B24,'Reference Data 기준데이터'!$A$3:$J$5,9,FALSE)),"") | P24: 46101 | Q24: =IFERROR(O24+VLOOKUP(F24,'Reference Data 기준데이터'!$A$9:$E$26,4,FALSE),"") | R24: 46128 | S24: =IFERROR(MIN(I24+VLOOKUP(B24,'Reference Data 기준데이터'!$A$3:$J$5,10,FALSE),VLOOKUP(B24,'Reference Data 기준데이터'!$A$3:$J$5,6,FALSE)),"") | T24: 46130 | V24: =IF(U24<>"",U24,IF(AND(T24<>"",R24<>""),"11-결과등록완료",IF(AND(R24<>"",T24=""),"10-시험완료",IF(AND(P24<>"",R24=""),"09-시험준비중",IF(AND(N24<>"",P24=""),"08-단품준비완료",IF(L24="Approved","05-계획서승인",IF(L24="Revision Needed","04-검토중_보완",IF(L24="Under Review","03-검토중",IF(AND(K24<>"",L24=""),"02-제출_미검토","01-미제출"))))))))) | W24: =IFS(V24="01-미제출",0,V24="02-제출_미검토",0.05,V24="03-검토중",0.1,V24="04-검토중_보완",0.05,V24="05-계획서승인",0.2,V24="06-BIW중단",0.15,V24="07-미인수",0.3,V24="08-단품준비완료",0.4,V24="09-시험준비중",0.55,V24="10-시험완료",0.85,V24="11-결과등록완료",1,V24="12-조건부승인",0.9,TRUE,0) | X24: =IF(T24<>"","-",IF(S24="","N/A",S24-TODAY())) | Y24: =IF(V24="11-결과등록완료","DONE",IF(U24="06-BIW중단","BLOCKED",IF(AND(K24="",J24<TODAY()),"CRITICAL",IF(AND(ISNUMBER(X24),X24<=0),"OVERDUE",IF(AND(ISNUMBER(X24),X24<=14),"WARNING",IF(U24<>"","ACTION","ON TRACK")))))) | Z24: =IF(OR(T24<>"",R24<>"",P24<>"",N24<>"",K24<>""),TODAY()-MAX(T24,R24,P24,N24,K24),"—") | AA24: =IF(V24="11-결과등록완료","— 완료",IF(V24="01-미제출",IF(J24<TODAY(),"계획서 제출 독촉 (OVERDUE)","계획서 제출 대기"),IF(V24="02-제출_미검토","설계자: 계획서 검토 착수",IF(V24="03-검토중","설계자: 승인 처리",IF(V24="04-검토중_보완","보완 요청 → 협력사 재제출 독촉",IF(V24="05-계획서승인","시험편 준비 현황 확인",IF(V24="06-BIW중단","BIW 생산팀 확인 → 일정 재수립",IF(V24="07-미인수","협력사 인수 독촉",IF(V24="08-단품준비완료","시험 일정 확인",IF(V24="09-시험준비중","시험 진행 모니터링",IF(V24="10-시험완료","결과 보고서 전산 등록 독촉",IF(V24="12-조건부승인","조건부 승인 여부 판단 → 관련부서 협의","—"))))))))))))
A25: 21 | B25: AE_PE | C25: =IFERROR(VLOOKUP(D25,'Reference Data 기준데이터'!$A$30:$D$41,2,FALSE),"") | D25: 시트(뒤) | E25: =IFERROR(VLOOKUP(D25,'Reference Data 기준데이터'!$A$30:$D$41,3,FALSE),"") | F25: 안전벨트 앵커리지 | G25: =IFERROR(VLOOKUP(F25,'Reference Data 기준데이터'!$A$9:$E$26,2,FALSE),"") | H25: =IFERROR(VLOOKUP(F25,'Reference Data 기준데이터'!$A$9:$E$26,5,FALSE),"") | I25: =IFERROR(VLOOKUP(B25,'Reference Data 기준데이터'!$A$3:$J$5,3,FALSE),"") | J25: =IFERROR(I25+VLOOKUP(B25,'Reference Data 기준데이터'!$A$3:$J$5,7,FALSE),"") | K25: 46048 | L25: Approved | M25: =IFERROR(I25+VLOOKUP(B25,'Reference Data 기준데이터'!$A$3:$J$5,8,FALSE),"") | N25: 46087 | O25: =IFERROR(IF(G25="차량장착",MAX(I25+VLOOKUP(B25,'Reference Data 기준데이터'!$A$3:$J$5,9,FALSE),VLOOKUP(B25,'Reference Data 기준데이터'!$A$3:$J$5,4,FALSE)),I25+VLOOKUP(B25,'Reference Data 기준데이터'!$A$3:$J$5,9,FALSE)),"") | P25: 46102 | Q25: =IFERROR(O25+VLOOKUP(F25,'Reference Data 기준데이터'!$A$9:$E$26,4,FALSE),"") | R25: 46122 | S25: =IFERROR(MIN(I25+VLOOKUP(B25,'Reference Data 기준데이터'!$A$3:$J$5,10,FALSE),VLOOKUP(B25,'Reference Data 기준데이터'!$A$3:$J$5,6,FALSE)),"") | V25: =IF(U25<>"",U25,IF(AND(T25<>"",R25<>""),"11-결과등록완료",IF(AND(R25<>"",T25=""),"10-시험완료",IF(AND(P25<>"",R25=""),"09-시험준비중",IF(AND(N25<>"",P25=""),"08-단품준비완료",IF(L25="Approved","05-계획서승인",IF(L25="Revision Needed","04-검토중_보완",IF(L25="Under Review","03-검토중",IF(AND(K25<>"",L25=""),"02-제출_미검토","01-미제출"))))))))) | W25: =IFS(V25="01-미제출",0,V25="02-제출_미검토",0.05,V25="03-검토중",0.1,V25="04-검토중_보완",0.05,V25="05-계획서승인",0.2,V25="06-BIW중단",0.15,V25="07-미인수",0.3,V25="08-단품준비완료",0.4,V25="09-시험준비중",0.55,V25="10-시험완료",0.85,V25="11-결과등록완료",1,V25="12-조건부승인",0.9,TRUE,0) | X25: =IF(T25<>"","-",IF(S25="","N/A",S25-TODAY())) | Y25: =IF(V25="11-결과등록완료","DONE",IF(U25="06-BIW중단","BLOCKED",IF(AND(K25="",J25<TODAY()),"CRITICAL",IF(AND(ISNUMBER(X25),X25<=0),"OVERDUE",IF(AND(ISNUMBER(X25),X25<=14),"WARNING",IF(U25<>"","ACTION","ON TRACK")))))) | Z25: =IF(OR(T25<>"",R25<>"",P25<>"",N25<>"",K25<>""),TODAY()-MAX(T25,R25,P25,N25,K25),"—") | AA25: =IF(V25="11-결과등록완료","— 완료",IF(V25="01-미제출",IF(J25<TODAY(),"계획서 제출 독촉 (OVERDUE)","계획서 제출 대기"),IF(V25="02-제출_미검토","설계자: 계획서 검토 착수",IF(V25="03-검토중","설계자: 승인 처리",IF(V25="04-검토중_보완","보완 요청 → 협력사 재제출 독촉",IF(V25="05-계획서승인","시험편 준비 현황 확인",IF(V25="06-BIW중단","BIW 생산팀 확인 → 일정 재수립",IF(V25="07-미인수","협력사 인수 독촉",IF(V25="08-단품준비완료","시험 일정 확인",IF(V25="09-시험준비중","시험 진행 모니터링",IF(V25="10-시험완료","결과 보고서 전산 등록 독촉",IF(V25="12-조건부승인","조건부 승인 여부 판단 → 관련부서 협의","—"))))))))))))
A26: 22 | B26: AE_PE | C26: =IFERROR(VLOOKUP(D26,'Reference Data 기준데이터'!$A$30:$D$41,2,FALSE),"") | D26: 시트(뒤) | E26: =IFERROR(VLOOKUP(D26,'Reference Data 기준데이터'!$A$30:$D$41,3,FALSE),"") | F26: ISOFIX 강도 시험 | G26: =IFERROR(VLOOKUP(F26,'Reference Data 기준데이터'!$A$9:$E$26,2,FALSE),"") | H26: =IFERROR(VLOOKUP(F26,'Reference Data 기준데이터'!$A$9:$E$26,5,FALSE),"") | I26: =IFERROR(VLOOKUP(B26,'Reference Data 기준데이터'!$A$3:$J$5,3,FALSE),"") | J26: =IFERROR(I26+VLOOKUP(B26,'Reference Data 기준데이터'!$A$3:$J$5,7,FALSE),"") | K26: 46049 | L26: Approved | M26: =IFERROR(I26+VLOOKUP(B26,'Reference Data 기준데이터'!$A$3:$J$5,8,FALSE),"") | N26: 46088 | O26: =IFERROR(IF(G26="차량장착",MAX(I26+VLOOKUP(B26,'Reference Data 기준데이터'!$A$3:$J$5,9,FALSE),VLOOKUP(B26,'Reference Data 기준데이터'!$A$3:$J$5,4,FALSE)),I26+VLOOKUP(B26,'Reference Data 기준데이터'!$A$3:$J$5,9,FALSE)),"") | P26: 46103 | Q26: =IFERROR(O26+VLOOKUP(F26,'Reference Data 기준데이터'!$A$9:$E$26,4,FALSE),"") | S26: =IFERROR(MIN(I26+VLOOKUP(B26,'Reference Data 기준데이터'!$A$3:$J$5,10,FALSE),VLOOKUP(B26,'Reference Data 기준데이터'!$A$3:$J$5,6,FALSE)),"") | V26: =IF(U26<>"",U26,IF(AND(T26<>"",R26<>""),"11-결과등록완료",IF(AND(R26<>"",T26=""),"10-시험완료",IF(AND(P26<>"",R26=""),"09-시험준비중",IF(AND(N26<>"",P26=""),"08-단품준비완료",IF(L26="Approved","05-계획서승인",IF(L26="Revision Needed","04-검토중_보완",IF(L26="Under Review","03-검토중",IF(AND(K26<>"",L26=""),"02-제출_미검토","01-미제출"))))))))) | W26: =IFS(V26="01-미제출",0,V26="02-제출_미검토",0.05,V26="03-검토중",0.1,V26="04-검토중_보완",0.05,V26="05-계획서승인",0.2,V26="06-BIW중단",0.15,V26="07-미인수",0.3,V26="08-단품준비완료",0.4,V26="09-시험준비중",0.55,V26="10-시험완료",0.85,V26="11-결과등록완료",1,V26="12-조건부승인",0.9,TRUE,0) | X26: =IF(T26<>"","-",IF(S26="","N/A",S26-TODAY())) | Y26: =IF(V26="11-결과등록완료","DONE",IF(U26="06-BIW중단","BLOCKED",IF(AND(K26="",J26<TODAY()),"CRITICAL",IF(AND(ISNUMBER(X26),X26<=0),"OVERDUE",IF(AND(ISNUMBER(X26),X26<=14),"WARNING",IF(U26<>"","ACTION","ON TRACK")))))) | Z26: =IF(OR(T26<>"",R26<>"",P26<>"",N26<>"",K26<>""),TODAY()-MAX(T26,R26,P26,N26,K26),"—") | AA26: =IF(V26="11-결과등록완료","— 완료",IF(V26="01-미제출",IF(J26<TODAY(),"계획서 제출 독촉 (OVERDUE)","계획서 제출 대기"),IF(V26="02-제출_미검토","설계자: 계획서 검토 착수",IF(V26="03-검토중","설계자: 승인 처리",IF(V26="04-검토중_보완","보완 요청 → 협력사 재제출 독촉",IF(V26="05-계획서승인","시험편 준비 현황 확인",IF(V26="06-BIW중단","BIW 생산팀 확인 → 일정 재수립",IF(V26="07-미인수","협력사 인수 독촉",IF(V26="08-단품준비완료","시험 일정 확인",IF(V26="09-시험준비중","시험 진행 모니터링",IF(V26="10-시험완료","결과 보고서 전산 등록 독촉",IF(V26="12-조건부승인","조건부 승인 여부 판단 → 관련부서 협의","—"))))))))))))
A27: 23 | B27: AE_PE | C27: =IFERROR(VLOOKUP(D27,'Reference Data 기준데이터'!$A$30:$D$41,2,FALSE),"") | D27: 시트(뒤) | E27: =IFERROR(VLOOKUP(D27,'Reference Data 기준데이터'!$A$30:$D$41,3,FALSE),"") | F27: 수하물 충격 시험 | G27: =IFERROR(VLOOKUP(F27,'Reference Data 기준데이터'!$A$9:$E$26,2,FALSE),"") | H27: =IFERROR(VLOOKUP(F27,'Reference Data 기준데이터'!$A$9:$E$26,5,FALSE),"") | I27: =IFERROR(VLOOKUP(B27,'Reference Data 기준데이터'!$A$3:$J$5,3,FALSE),"") | J27: =IFERROR(I27+VLOOKUP(B27,'Reference Data 기준데이터'!$A$3:$J$5,7,FALSE),"") | K27: 46050 | L27: Approved | M27: =IFERROR(I27+VLOOKUP(B27,'Reference Data 기준데이터'!$A$3:$J$5,8,FALSE),"") | N27: 46089 | O27: =IFERROR(IF(G27="차량장착",MAX(I27+VLOOKUP(B27,'Reference Data 기준데이터'!$A$3:$J$5,9,FALSE),VLOOKUP(B27,'Reference Data 기준데이터'!$A$3:$J$5,4,FALSE)),I27+VLOOKUP(B27,'Reference Data 기준데이터'!$A$3:$J$5,9,FALSE)),"") | P27: 46104 | Q27: =IFERROR(O27+VLOOKUP(F27,'Reference Data 기준데이터'!$A$9:$E$26,4,FALSE),"") | R27: 46124 | S27: =IFERROR(MIN(I27+VLOOKUP(B27,'Reference Data 기준데이터'!$A$3:$J$5,10,FALSE),VLOOKUP(B27,'Reference Data 기준데이터'!$A$3:$J$5,6,FALSE)),"") | T27: 46133 | V27: =IF(U27<>"",U27,IF(AND(T27<>"",R27<>""),"11-결과등록완료",IF(AND(R27<>"",T27=""),"10-시험완료",IF(AND(P27<>"",R27=""),"09-시험준비중",IF(AND(N27<>"",P27=""),"08-단품준비완료",IF(L27="Approved","05-계획서승인",IF(L27="Revision Needed","04-검토중_보완",IF(L27="Under Review","03-검토중",IF(AND(K27<>"",L27=""),"02-제출_미검토","01-미제출"))))))))) | W27: =IFS(V27="01-미제출",0,V27="02-제출_미검토",0.05,V27="03-검토중",0.1,V27="04-검토중_보완",0.05,V27="05-계획서승인",0.2,V27="06-BIW중단",0.15,V27="07-미인수",0.3,V27="08-단품준비완료",0.4,V27="09-시험준비중",0.55,V27="10-시험완료",0.85,V27="11-결과등록완료",1,V27="12-조건부승인",0.9,TRUE,0) | X27: =IF(T27<>"","-",IF(S27="","N/A",S27-TODAY())) | Y27: =IF(V27="11-결과등록완료","DONE",IF(U27="06-BIW중단","BLOCKED",IF(AND(K27="",J27<TODAY()),"CRITICAL",IF(AND(ISNUMBER(X27),X27<=0),"OVERDUE",IF(AND(ISNUMBER(X27),X27<=14),"WARNING",IF(U27<>"","ACTION","ON TRACK")))))) | Z27: =IF(OR(T27<>"",R27<>"",P27<>"",N27<>"",K27<>""),TODAY()-MAX(T27,R27,P27,N27,K27),"—") | AA27: =IF(V27="11-결과등록완료","— 완료",IF(V27="01-미제출",IF(J27<TODAY(),"계획서 제출 독촉 (OVERDUE)","계획서 제출 대기"),IF(V27="02-제출_미검토","설계자: 계획서 검토 착수",IF(V27="03-검토중","설계자: 승인 처리",IF(V27="04-검토중_보완","보완 요청 → 협력사 재제출 독촉",IF(V27="05-계획서승인","시험편 준비 현황 확인",IF(V27="06-BIW중단","BIW 생산팀 확인 → 일정 재수립",IF(V27="07-미인수","협력사 인수 독촉",IF(V27="08-단품준비완료","시험 일정 확인",IF(V27="09-시험준비중","시험 진행 모니터링",IF(V27="10-시험완료","결과 보고서 전산 등록 독촉",IF(V27="12-조건부승인","조건부 승인 여부 판단 → 관련부서 협의","—"))))))))))))
